Workbook
Name zsupermetrics_refreshAllSilent: #REF!
Name zsupermetrics_refreshAll: #REF!
Name zsupermetrics_forceRefresh: #REF!

Sheet Acompanhamento Geral
A1: DATA | B1: DIA | C1: AÇÃO DO DIA | D1: VALOR INVESTIDO | E1: FATURAMENTO | F1: ROAS | G1: CPS | H1: TAXA DE CONVERSÃO | I1: CPA | J1: PEDIDOS | K1: SESSÕES | L1: TICKET MÉDIO | M1: META INVESTIMENTO | N1: META FATURAMENTO | O1: META ROAS | P1: CPS META | Q1: META TAXA DE CONVERSÃO | R1: CPA META | S1: META SESSÕES | T1: META TICKET MÉDIO
A2: JANEIRO | B2: 31 | D2: =IFERROR(SUM(D3:D33),"") -> 1695.67 | E2: =iferror(SUM(E3:E33),"") -> 0 | F2: =iferror(E2/D2,"") -> 0 | G2: =iferror(D2/K2,"") -> 10.467099 | H2: =iferror(J2/K2,"") -> 0.012345679 | I2: =iferror(D2/J2,"") -> 847.835 | J2: =iferror(SUM(J3:J33),"") -> 2 | K2: =IFERROR(SUM(K3:K33),"") -> 162 | L2: =iferror(E2/J2,"") -> 0 | M2: =iferror(Planejador!$I$4,"") | N2: =iferror(Planejador!$I$13,"") | O2: =iferror(Planejador!$I$14,"") | P2: =iferror(Planejador!$I$5,"") | Q2: =Iferror(Planejador!$I$7,"") | R2: =iferror(Planejador!$I$11,"") | S2: =iferror(Planejador!$I$10,"") | T2: =iferror(Planejador!$I$6,"")
A3: 46023 | B3: =TEXT(A3,"dddd") -> quinta-feira | D3: =SUMIF('ADV - GG'!A:A,A3,'ADV - GG'!C:C)+SUMIF('ADV - FB'!A:A,$A3,'ADV - FB'!E:E) -> 13.26 | F3: =IFERROR(E3/D3,"") -> 0 | G3: =IFERROR(D3/K3,"") | H3: =iferror(J3/K3,"") | I3: =iferror(D3/J3,"") | J3: =SUMIF('ADV - GG'!A:A,A3,'ADV - GG'!H:H)+SUMIF('ADV - FB'!A:A,$A3,'ADV - FB'!I:I) -> 0 | K3: =SUMIF('ADV - GA4'!A:A,A3,'ADV - GA4'!C:C) -> 0 | L3: =IFERROR(E3/J3,"") | M3: =$M$2/$B$2 -> 0 | N3: =$N$2/$B$2 -> 0 | O3: =iferror(Planejador!$I$14,"") | P3: =Planejador!$I$5 | Q3: =Planejador!$I$7 | R3: =Planejador!$I$11 -> #DIV/0! | S3: =$S$2/$B$2 -> 0 | T3: =Planejador!$I$6
A4: 46024 | B4: =TEXT(A4,"dddd") -> sexta-feira | D4: =SUMIF('ADV - GG'!A:A,A4,'ADV - GG'!C:C)+SUMIF('ADV - FB'!A:A,$A4,'ADV - FB'!E:E) -> 35.08 | F4: =IFERROR(E4/D4,"") -> 0 | G4: =IFERROR(D4/K4,"") -> 35.08 | H4: =iferror(J4/K4,"") -> 0 | I4: =iferror(D4/J4,"") | J4: =SUMIF('ADV - GG'!A:A,A4,'ADV - GG'!H:H)+SUMIF('ADV - FB'!A:A,$A4,'ADV - FB'!I:I) -> 0 | K4: =SUMIF('ADV - GA4'!A:A,A4,'ADV - GA4'!C:C) -> 1 | L4: =IFERROR(E4/J4,"") | M4: =$M$2/$B$2 -> 0 | N4: =$N$2/$B$2 -> 0 | O4: =iferror(Planejador!$I$14,"") | P4: =Planejador!$I$5 | Q4: =Planejador!$I$7 | R4: =Planejador!$I$11 -> #DIV/0! | S4: =$S$2/$B$2 -> 0 | T4: =Planejador!$I$6
A5: 46025 | B5: =TEXT(A5,"dddd") -> sábado | D5: =SUMIF('ADV - GG'!A:A,A5,'ADV - GG'!C:C)+SUMIF('ADV - FB'!A:A,$A5,'ADV - FB'!E:E) -> 26.1 | F5: =IFERROR(E5/D5,"") -> 0 | G5: =IFERROR(D5/K5,"") -> 13.05 | H5: =iferror(J5/K5,"") -> 0 | I5: =iferror(D5/J5,"") | J5: =SUMIF('ADV - GG'!A:A,A5,'ADV - GG'!H:H)+SUMIF('ADV - FB'!A:A,$A5,'ADV - FB'!I:I) -> 0 | K5: =SUMIF('ADV - GA4'!A:A,A5,'ADV - GA4'!C:C) -> 2 | L5: =IFERROR(E5/J5,"") | M5: =$M$2/$B$2 -> 0 | N5: =$N$2/$B$2 -> 0 | O5: =iferror(Planejador!$I$14,"") | P5: =Planejador!$I$5 | Q5: =Planejador!$I$7 | R5: =Planejador!$I$11 -> #DIV/0! | S5: =$S$2/$B$2 -> 0 | T5: =Planejador!$I$6
A6: 46026 | B6: =TEXT(A6,"dddd") -> domingo | D6: =SUMIF('ADV - GG'!A:A,A6,'ADV - GG'!C:C)+SUMIF('ADV - FB'!A:A,$A6,'ADV - FB'!E:E) -> 43.39 | F6: =IFERROR(E6/D6,"") -> 0 | G6: =IFERROR(D6/K6,"") -> 14.463333 | H6: =iferror(J6/K6,"") -> 0 | I6: =iferror(D6/J6,"") | J6: =SUMIF('ADV - GG'!A:A,A6,'ADV - GG'!H:H)+SUMIF('ADV - FB'!A:A,$A6,'ADV - FB'!I:I) -> 0 | K6: =SUMIF('ADV - GA4'!A:A,A6,'ADV - GA4'!C:C) -> 3 | L6: =IFERROR(E6/J6,"") | M6: =$M$2/$B$2 -> 0 | N6: =$N$2/$B$2 -> 0 | O6: =iferror(Planejador!$I$14,"") | P6: =Planejador!$I$5 | Q6: =Planejador!$I$7 | R6: =Planejador!$I$11 -> #DIV/0! | S6: =$S$2/$B$2 -> 0 | T6: =Planejador!$I$6
A7: 46027 | B7: =TEXT(A7,"dddd") -> segunda-feira | D7: =SUMIF('ADV - GG'!A:A,A7,'ADV - GG'!C:C)+SUMIF('ADV - FB'!A:A,$A7,'ADV - FB'!E:E) -> 27.17 | F7: =IFERROR(E7/D7,"") -> 0 | G7: =IFERROR(D7/K7,"") -> 3.39625 | H7: =iferror(J7/K7,"") -> 0.25 | I7: =iferror(D7/J7,"") -> 13.585 | J7: =SUMIF('ADV - GG'!A:A,A7,'ADV - GG'!H:H)+SUMIF('ADV - FB'!A:A,$A7,'ADV - FB'!I:I) -> 2 | K7: =SUMIF('ADV - GA4'!A:A,A7,'ADV - GA4'!C:C) -> 8 | L7: =IFERROR(E7/J7,"") -> 0 | M7: =$M$2/$B$2 -> 0 | N7: =$N$2/$B$2 -> 0 | O7: =iferror(Planejador!$I$14,"") | P7: =Planejador!$I$5 | Q7: =Planejador!$I$7 | R7: =Planejador!$I$11 -> #DIV/0! | S7: =$S$2/$B$2 -> 0 | T7: =Planejador!$I$6
A8: 46028 | B8: =TEXT(A8,"dddd") -> terça-feira | D8: =SUMIF('ADV - GG'!A:A,A8,'ADV - GG'!C:C)+SUMIF('ADV - FB'!A:A,$A8,'ADV - FB'!E:E) -> 18.77 | F8: =IFERROR(E8/D8,"") -> 0 | G8: =IFERROR(D8/K8,"") -> 3.754 | H8: =iferror(J8/K8,"") -> 0 | I8: =iferror(D8/J8,"") | J8: =SUMIF('ADV - GG'!A:A,A8,'ADV - GG'!H:H)+SUMIF('ADV - FB'!A:A,$A8,'ADV - FB'!I:I) -> 0 | K8: =SUMIF('ADV - GA4'!A:A,A8,'ADV - GA4'!C:C) -> 5 | L8: =IFERROR(E8/J8,"") | M8: =$M$2/$B$2 -> 0 | N8: =$N$2/$B$2 -> 0 | O8: =iferror(Planejador!$I$14,"") | P8: =Planejador!$I$5 | Q8: =Planejador!$I$7 | R8: =Planejador!$I$11 -> #DIV/0! | S8: =$S$2/$B$2 -> 0 | T8: =Planejador!$I$6
A9: 46029 | B9: =TEXT(A9,"dddd") -> quarta-feira | D9: =SUMIF('ADV - GG'!A:A,A9,'ADV - GG'!C:C)+SUMIF('ADV - FB'!A:A,$A9,'ADV - FB'!E:E) -> 16.91 | F9: =IFERROR(E9/D9,"") -> 0 | G9: =IFERROR(D9/K9,"") -> 3.382 | H9: =iferror(J9/K9,"") -> 0 | I9: =iferror(D9/J9,"") | J9: =SUMIF('ADV - GG'!A:A,A9,'ADV - GG'!H:H)+SUMIF('ADV - FB'!A:A,$A9,'ADV - FB'!I:I) -> 0 | K9: =SUMIF('ADV - GA4'!A:A,A9,'ADV - GA4'!C:C) -> 5 | L9: =IFERROR(E9/J9,"") | M9: =$M$2/$B$2 -> 0 | N9: =$N$2/$B$2 -> 0 | O9: =iferror(Planejador!$I$14,"") | P9: =Planejador!$I$5 | Q9: =Planejador!$I$7 | R9: =Planejador!$I$11 -> #DIV/0! | S9: =$S$2/$B$2 -> 0 | T9: =Planejador!$I$6
A10: 46030 | B10: =TEXT(A10,"dddd") -> quinta-feira | D10: =SUMIF('ADV - GG'!A:A,A10,'ADV - GG'!C:C)+SUMIF('ADV - FB'!A:A,$A10,'ADV - FB'!E:E) -> 24.63 | F10: =IFERROR(E10/D10,"") -> 0 | G10: =IFERROR(D10/K10,"") -> 24.63 | H10: =iferror(J10/K10,"") -> 0 | I10: =iferror(D10/J10,"") | J10: =SUMIF('ADV - GG'!A:A,A10,'ADV - GG'!H:H)+SUMIF('ADV - FB'!A:A,$A10,'ADV - FB'!I:I) -> 0 | K10: =SUMIF('ADV - GA4'!A:A,A10,'ADV - GA4'!C:C) -> 1 | L10: =IFERROR(E10/J10,"") | M10: =$M$2/$B$2 -> 0 | N10: =$N$2/$B$2 -> 0 | O10: =iferror(Planejador!$I$14,"") | P10: =Planejador!$I$5 | Q10: =Planejador!$I$7 | R10: =Planejador!$I$11 -> #DIV/0! | S10: =$S$2/$B$2 -> 0 | T10: =Planejador!$I$6
A11: 46031 | B11: =TEXT(A11,"dddd") -> sexta-feira | D11: =SUMIF('ADV - GG'!A:A,A11,'ADV - GG'!C:C)+SUMIF('ADV - FB'!A:A,$A11,'ADV - FB'!E:E) -> 20.05 | F11: =IFERROR(E11/D11,"") -> 0 | G11: =IFERROR(D11/K11,"") -> 2.8642857 | H11: =iferror(J11/K11,"") -> 0 | I11: =iferror(D11/J11,"") | J11: =SUMIF('ADV - GG'!A:A,A11,'ADV - GG'!H:H)+SUMIF('ADV - FB'!A:A,$A11,'ADV - FB'!I:I) -> 0 | K11: =SUMIF('ADV - GA4'!A:A,A11,'ADV - GA4'!C:C) -> 7 | L11: =IFERROR(E11/J11,"") | M11: =$M$2/$B$2 -> 0 | N11: =$N$2/$B$2 -> 0 | O11: =iferror(Planejador!$I$14,"") | P11: =Planejador!$I$5 | Q11: =Planejador!$I$7 | R11: =Planejador!$I$11 -> #DIV/0! | S11: =$S$2/$B$2 -> 0 | T11: =Planejador!$I$6
A12: 46032 | B12: =TEXT(A12,"dddd") -> sábado | D12: =SUMIF('ADV - GG'!A:A,A12,'ADV - GG'!C:C)+SUMIF('ADV - FB'!A:A,$A12,'ADV - FB'!E:E) -> 29.7 | F12: =IFERROR(E12/D12,"") -> 0 | G12: =IFERROR(D12/K12,"") -> 29.7 | H12: =iferror(J12/K12,"") -> 0 | I12: =iferror(D12/J12,"") | J12: =SUMIF('ADV - GG'!A:A,A12,'ADV - GG'!H:H)+SUMIF('ADV - FB'!A:A,$A12,'ADV - FB'!I:I) -> 0 | K12: =SUMIF('ADV - GA4'!A:A,A12,'ADV - GA4'!C:C) -> 1 | L12: =IFERROR(E12/J12,"") | M12: =$M$2/$B$2 -> 0 | N12: =$N$2/$B$2 -> 0 | O12: =iferror(Planejador!$I$14,"") | P12: =Planejador!$I$5 | Q12: =Planejador!$I$7 | R12: =Planejador!$I$11 -> #DIV/0! | S12: =$S$2/$B$2 -> 0 | T12: =Planejador!$I$6
A13: 46033 | B13: =TEXT(A13,"dddd") -> domingo | D13: =SUMIF('ADV - GG'!A:A,A13,'ADV - GG'!C:C)+SUMIF('ADV - FB'!A:A,$A13,'ADV - FB'!E:E) -> 39.73 | F13: =IFERROR(E13/D13,"") -> 0 | G13: =IFERROR(D13/K13,"") -> 5.6757143 | H13: =iferror(J13/K13,"") -> 0 | I13: =iferror(D13/J13,"") | J13: =SUMIF('ADV - GG'!A:A,A13,'ADV - GG'!H:H)+SUMIF('ADV - FB'!A:A,$A13,'ADV - FB'!I:I) -> 0 | K13: =SUMIF('ADV - GA4'!A:A,A13,'ADV - GA4'!C:C) -> 7 | L13: =IFERROR(E13/J13,"") | M13: =$M$2/$B$2 -> 0 | N13: =$N$2/$B$2 -> 0 | O13: =iferror(Planejador!$I$14,"") | P13: =Planejador!$I$5 | Q13: =Planejador!$I$7 | R13: =Planejador!$I$11 -> #DIV/0! | S13: =$S$2/$B$2 -> 0 | T13: =Planejador!$I$6
A14: 46034 | B14: =TEXT(A14,"dddd") -> segunda-feira | D14: =SUMIF('ADV - GG'!A:A,A14,'ADV - GG'!C:C)+SUMIF('ADV - FB'!A:A,$A14,'ADV - FB'!E:E) -> 53.64 | F14: =IFERROR(E14/D14,"") -> 0 | G14: =IFERROR(D14/K14,"") -> 4.8763636 | H14: =iferror(J14/K14,"") -> 0 | I14: =iferror(D14/J14,"") | J14: =SUMIF('ADV - GG'!A:A,A14,'ADV - GG'!H:H)+SUMIF('ADV - FB'!A:A,$A14,'ADV - FB'!I:I) -> 0 | K14: =SUMIF('ADV - GA4'!A:A,A14,'ADV - GA4'!C:C) -> 11 | L14: =IFERROR(E14/J14,"") | M14: =$M$2/$B$2 -> 0 | N14: =$N$2/$B$2 -> 0 | O14: =iferror(Planejador!$I$14,"") | P14: =Planejador!$I$5 | Q14: =Planejador!$I$7 | R14: =Planejador!$I$11 -> #DIV/0! | S14: =$S$2/$B$2 -> 0 | T14: =Planejador!$I$6
... A33: 46053 | B33: =TEXT(A33,"dddd") -> sábado | D33: =SUMIF('ADV - GG'!A:A,A33,'ADV - GG'!C:C)+SUMIF('ADV - FB'!A:A,$A33,'ADV - FB'!E:E) -> 71.29 | F33: =IFERROR(E33/D33,"") -> 0 | G33: =IFERROR(D33/K33,"") -> 71.29 | H33: =iferror(J33/K33,"") -> 0 | I33: =iferror(D33/J33,"") | J33: =SUMIF('ADV - GG'!A:A,A33,'ADV - GG'!H:H)+SUMIF('ADV - FB'!A:A,$A33,'ADV - FB'!I:I) -> 0 | K33: =SUMIF('ADV - GA4'!A:A,A33,'ADV - GA4'!C:C) -> 1 | L33: =IFERROR(E33/J33,"") | M33: =$M$2/$B$2 -> 0 | N33: =$N$2/$B$2 -> 0 | O33: =iferror(Planejador!$I$14,"") | P33: =Planejador!$I$5 | Q33: =Planejador!$I$7 | R33: =Planejador!$I$11 -> #DIV/0! | S33: =$S$2/$B$2 -> 0 | T33: =Planejador!$I$6
A34: FEVEREIRO | B34: =COUNTA(A35:A63) -> 29 | D34: =IFERROR(SUM(D35:D63),"") -> 1640.2 | E34: =iferror(SUM(E35:E63),"") -> 0 | F34: =iferror(E34/D34,"") -> 0 | G34: =iferror(D34/K34,"") -> 5.1741325 | H34: =iferror(J34/K34,"") -> 0.14511041 | I34: =iferror(D34/J34,"") -> 35.656522 | J34: =iferror(SUM(J35:J63),"") -> 46 | K34: =IFERROR(SUM(K35:K63),"") -> 317 | L34: =iferror(E34/J34,"") -> 0 | M34: =Planejador!$I$27 | N34: =IFERROR(Planejador!$I$36,"") | O34: =IFERROR(Planejador!$I$37,"") | P34: =Planejador!$I$28 | Q34: =Planejador!$I$30 | R34: =iferror(Planejador!$I$34,"") | S34: =iferror(Planejador!$I$33,"") | T34: =iferror(Planejador!$I$29,"")
A35: 46054 | B35: =TEXT(A35,"dddd") -> domingo | D35: =SUMIF('ADV - GG'!A:A,A35,'ADV - GG'!C:C)+SUMIF('ADV - FB'!A:A,$A35,'ADV - FB'!E:E) -> 89.37 | F35: =IFERROR(E35/D35,"") -> 0 | G35: =IFERROR(D35/K33,"") -> 89.37 | H35: =iferror(J35/K35,"") -> 0 | I35: =iferror(D35/J35,"") | J35: =SUMIF('ADV - GG'!A:A,A35,'ADV - GG'!H:H)+SUMIF('ADV - FB'!A:A,$A35,'ADV - FB'!I:I) -> 0 | K35: =SUMIF('ADV - GA4'!A:A,A35,'ADV - GA4'!C:C) -> 129 | L35: =IFERROR(E35/J35,"") | M35: =$M$34/$B$34 -> 0 | N35: =$N$34/$B$34 -> 0 | O35: =IFERROR(Planejador!$I$37,"") | P35: =Planejador!$I$28 | Q35: =Planejador!$I$30 | R35: =iferror(Planejador!$I$34,"") | S35: =$S$34/$B$34 -> 0 | T35: =iferror(Planejador!$I$29,"")
A36: 46055 | B36: =TEXT(A36,"dddd") -> segunda-feira | D36: =SUMIF('ADV - GG'!A:A,A36,'ADV - GG'!C:C)+SUMIF('ADV - FB'!A:A,$A36,'ADV - FB'!E:E) -> 39.12 | F36: =IFERROR(E36/D36,"") -> 0 | G36: =IFERROR(D36/K34,"") -> 0.12340694 | H36: =iferror(J36/K36,"") -> 0 | I36: =iferror(D36/J36,"") | J36: =SUMIF('ADV - GG'!A:A,A36,'ADV - GG'!H:H)+SUMIF('ADV - FB'!A:A,$A36,'ADV - FB'!I:I) -> 0 | K36: =SUMIF('ADV - GA4'!A:A,A36,'ADV - GA4'!C:C) -> 47 | L36: =IFERROR(E36/J36,"") | M36: =$M$34/$B$34 -> 0 | N36: =$N$34/$B$34 -> 0 | O36: =IFERROR(Planejador!$I$37,"") | P36: =Planejador!$I$28 | Q36: =Planejador!$I$30 | R36: =iferror(Planejador!$I$34,"") | S36: =$S$34/$B$34 -> 0 | T36: =iferror(Planejador!$I$29,"")
A37: 46056 | B37: =TEXT(A37,"dddd") -> terça-feira | D37: =SUMIF('ADV - GG'!A:A,A37,'ADV - GG'!C:C)+SUMIF('ADV - FB'!A:A,$A37,'ADV - FB'!E:E) -> 122.42 | F37: =IFERROR(E37/D37,"") -> 0 | G37: =IFERROR(D37/K35,"") -> 0.94899225 | H37: =iferror(J37/K37,"") -> 0 | I37: =iferror(D37/J37,"") | J37: =SUMIF('ADV - GG'!A:A,A37,'ADV - GG'!H:H)+SUMIF('ADV - FB'!A:A,$A37,'ADV - FB'!I:I) -> 0 | K37: =SUMIF('ADV - GA4'!A:A,A37,'ADV - GA4'!C:C) -> 19 | L37: =IFERROR(E37/J37,"") | M37: =$M$34/$B$34 -> 0 | N37: =$N$34/$B$34 -> 0 | O37: =IFERROR(Planejador!$I$37,"") | P37: =Planejador!$I$28 | Q37: =Planejador!$I$30 | R37: =iferror(Planejador!$I$34,"") | S37: =$S$34/$B$34 -> 0 | T37: =iferror(Planejador!$I$29,"")
A38: 46057 | B38: =TEXT(A38,"dddd") -> quarta-feira | D38: =SUMIF('ADV - GG'!A:A,A38,'ADV - GG'!C:C)+SUMIF('ADV - FB'!A:A,$A38,'ADV - FB'!E:E) -> 80.8 | F38: =IFERROR(E38/D38,"") -> 0 | G38: =IFERROR(D38/K36,"") -> 1.7191489 | H38: =iferror(J38/K38,"") -> 0 | I38: =iferror(D38/J38,"") | J38: =SUMIF('ADV - GG'!A:A,A38,'ADV - GG'!H:H)+SUMIF('ADV - FB'!A:A,$A38,'ADV - FB'!I:I) -> 0 | K38: =SUMIF('ADV - GA4'!A:A,A38,'ADV - GA4'!C:C) -> 25 | L38: =IFERROR(E38/J38,"") | M38: =$M$34/$B$34 -> 0 | N38: =$N$34/$B$34 -> 0 | O38: =IFERROR(Planejador!$I$37,"") | P38: =Planejador!$I$28 | Q38: =Planejador!$I$30 | R38: =iferror(Planejador!$I$34,"") | S38: =$S$34/$B$34 -> 0 | T38: =iferror(Planejador!$I$29,"")
A39: 46058 | B39: =TEXT(A39,"dddd") -> quinta-feira | D39: =SUMIF('ADV - GG'!A:A,A39,'ADV - GG'!C:C)+SUMIF('ADV - FB'!A:A,$A39,'ADV - FB'!E:E) -> 78.11 | F39: =IFERROR(E39/D39,"") -> 0 | G39: =IFERROR(D39/K37,"") -> 4.1110526 | H39: =iferror(J39/K39,"") -> 0.08 | I39: =iferror(D39/J39,"") -> 39.055 | J39: =SUMIF('ADV - GG'!A:A,A39,'ADV - GG'!H:H)+SUMIF('ADV - FB'!A:A,$A39,'ADV - FB'!I:I) -> 2 | K39: =SUMIF('ADV - GA4'!A:A,A39,'ADV - GA4'!C:C) -> 25 | L39: =IFERROR(E39/J39,"") -> 0 | M39: =$M$34/$B$34 -> 0 | N39: =$N$34/$B$34 -> 0 | O39: =IFERROR(Planejador!$I$37,"") | P39: =Planejador!$I$28 | Q39: =Planejador!$I$30 | R39: =iferror(Planejador!$I$34,"") | S39: =$S$34/$B$34 -> 0 | T39: =iferror(Planejador!$I$29,"")
A40: 46059 | B40: =TEXT(A40,"dddd") -> sexta-feira | D40: =SUMIF('ADV - GG'!A:A,A40,'ADV - GG'!C:C)+SUMIF('ADV - FB'!A:A,$A40,'ADV - FB'!E:E) -> 101.89 | F40: =IFERROR(E40/D40,"") -> 0 | G40: =IFERROR(D40/K38,"") -> 4.0756 | H40: =iferror(J40/K40,"") -> 0.5 | I40: =iferror(D40/J40,"") -> 101.89 | J40: =SUMIF('ADV - GG'!A:A,A40,'ADV - GG'!H:H)+SUMIF('ADV - FB'!A:A,$A40,'ADV - FB'!I:I) -> 1 | K40: =SUMIF('ADV - GA4'!A:A,A40,'ADV - GA4'!C:C) -> 2 | L40: =IFERROR(E40/J40,"") -> 0 | M40: =$M$34/$B$34 -> 0 | N40: =$N$34/$B$34 -> 0 | O40: =IFERROR(Planejador!$I$37,"") | P40: =Planejador!$I$28 | Q40: =Planejador!$I$30 | R40: =iferror(Planejador!$I$34,"") | S40: =$S$34/$B$34 -> 0 | T40: =iferror(Planejador!$I$29,"")
A41: 46060 | B41: =TEXT(A41,"dddd") -> sábado | D41: =SUMIF('ADV - GG'!A:A,A41,'ADV - GG'!C:C)+SUMIF('ADV - FB'!A:A,$A41,'ADV - FB'!E:E) -> 12.11 | F41: =IFERROR(E41/D41,"") -> 0 | G41: =IFERROR(D41/K39,"") -> 0.4844 | H41: =iferror(J41/K41,"") -> 0 | I41: =iferror(D41/J41,"") | J41: =SUMIF('ADV - GG'!A:A,A41,'ADV - GG'!H:H)+SUMIF('ADV - FB'!A:A,$A41,'ADV - FB'!I:I) -> 0 | K41: =SUMIF('ADV - GA4'!A:A,A41,'ADV - GA4'!C:C) -> 8 | L41: =IFERROR(E41/J41,"") | M41: =$M$34/$B$34 -> 0 | N41: =$N$34/$B$34 -> 0 | O41: =IFERROR(Planejador!$I$37,"") | P41: =Planejador!$I$28 | Q41: =Planejador!$I$30 | R41: =iferror(Planejador!$I$34,"") | S41: =$S$34/$B$34 -> 0 | T41: =iferror(Planejador!$I$29,"")
A42: 46061 | B42: =TEXT(A42,"dddd") -> domingo | D42: =SUMIF('ADV - GG'!A:A,A42,'ADV - GG'!C:C)+SUMIF('ADV - FB'!A:A,$A42,'ADV - FB'!E:E) -> 0 | F42: =IFERROR(E42/D42,"") | G42: =IFERROR(D42/K40,"") -> 0 | H42: =iferror(J42/K42,"") -> 0 | I42: =iferror(D42/J42,"") | J42: =SUMIF('ADV - GG'!A:A,A42,'ADV - GG'!H:H)+SUMIF('ADV - FB'!A:A,$A42,'ADV - FB'!I:I) -> 0 | K42: =SUMIF('ADV - GA4'!A:A,A42,'ADV - GA4'!C:C) -> 4 | L42: =IFERROR(E42/J42,"") | M42: =$M$34/$B$34 -> 0 | N42: =$N$34/$B$34 -> 0 | O42: =IFERROR(Planejador!$I$37,"") | P42: =Planejador!$I$28 | Q42: =Planejador!$I$30 | R42: =iferror(Planejador!$I$34,"") | S42: =$S$34/$B$34 -> 0 | T42: =iferror(Planejador!$I$29,"")
A43: 46062 | B43: =TEXT(A43,"dddd") -> segunda-feira | D43: =SUMIF('ADV - GG'!A:A,A43,'ADV - GG'!C:C)+SUMIF('ADV - FB'!A:A,$A43,'ADV - FB'!E:E) -> 125.59 | F43: =IFERROR(E43/D43,"") -> 0 | G43: =IFERROR(D43/K41,"") -> 15.69875 | H43: =iferror(J43/K43,"") -> 2 | I43: =iferror(D43/J43,"") -> 31.3975 | J43: =SUMIF('ADV - GG'!A:A,A43,'ADV - GG'!H:H)+SUMIF('ADV - FB'!A:A,$A43,'ADV - FB'!I:I) -> 4 | K43: =SUMIF('ADV - GA4'!A:A,A43,'ADV - GA4'!C:C) -> 2 | L43: =IFERROR(E43/J43,"") -> 0 | M43: =$M$34/$B$34 -> 0 | N43: =$N$34/$B$34 -> 0 | O43: =IFERROR(Planejador!$I$37,"") | P43: =Planejador!$I$28 | Q43: =Planejador!$I$30 | R43: =iferror(Planejador!$I$34,"") | S43: =$S$34/$B$34 -> 0 | T43: =iferror(Planejador!$I$29,"")
A44: 46063 | B44: =TEXT(A44,"dddd") -> terça-feira | D44: =SUMIF('ADV - GG'!A:A,A44,'ADV - GG'!C:C)+SUMIF('ADV - FB'!A:A,$A44,'ADV - FB'!E:E) -> 108.07 | F44: =IFERROR(E44/D44,"") -> 0 | G44: =IFERROR(D44/K42,"") -> 27.0175 | H44: =iferror(J44/K44,"") -> 0.5 | I44: =iferror(D44/J44,"") -> 54.035 | J44: =SUMIF('ADV - GG'!A:A,A44,'ADV - GG'!H:H)+SUMIF('ADV - FB'!A:A,$A44,'ADV - FB'!I:I) -> 2 | K44: =SUMIF('ADV - GA4'!A:A,A44,'ADV - GA4'!C:C) -> 4 | L44: =IFERROR(E44/J44,"") -> 0 | M44: =$M$34/$B$34 -> 0 | N44: =$N$34/$B$34 -> 0 | O44: =IFERROR(Planejador!$I$37,"") | P44: =Planejador!$I$28 | Q44: =Planejador!$I$30 | R44: =iferror(Planejador!$I$34,"") | S44: =$S$34/$B$34 -> 0 | T44: =iferror(Planejador!$I$29,"")
A45: 46064 | B45: =TEXT(A45,"dddd") -> quarta-feira | D45: =SUMIF('ADV - GG'!A:A,A45,'ADV - GG'!C:C)+SUMIF('ADV - FB'!A:A,$A45,'ADV - FB'!E:E) -> 105.34 | F45: =IFERROR(E45/D45,"") -> 0 | G45: =IFERROR(D45/K43,"") -> 52.67 | H45: =iferror(J45/K45,"") -> 1.4 | I45: =iferror(D45/J45,"") -> 15.048571 | J45: =SUMIF('ADV - GG'!A:A,A45,'ADV - GG'!H:H)+SUMIF('ADV - FB'!A:A,$A45,'ADV - FB'!I:I) -> 7 | K45: =SUMIF('ADV - GA4'!A:A,A45,'ADV - GA4'!C:C) -> 5 | L45: =IFERROR(E45/J45,"") -> 0 | M45: =$M$34/$B$34 -> 0 | N45: =$N$34/$B$34 -> 0 | O45: =IFERROR(Planejador!$I$37,"") | P45: =Planejador!$I$28 | Q45: =Planejador!$I$30 | R45: =iferror(Planejador!$I$34,"") | S45: =$S$34/$B$34 -> 0 | T45: =iferror(Planejador!$I$29,"")
A46: 46065 | B46: =TEXT(A46,"dddd") -> quinta-feira | D46: =SUMIF('ADV - GG'!A:A,A46,'ADV - GG'!C:C)+SUMIF('ADV - FB'!A:A,$A46,'ADV - FB'!E:E) -> 56.33 | F46: =IFERROR(E46/D46,"") -> 0 | G46: =IFERROR(D46/K44,"") -> 14.0825 | H46: =iferror(J46/K46,"") -> 0.5 | I46: =iferror(D46/J46,"") -> 56.33 | J46: =SUMIF('ADV - GG'!A:A,A46,'ADV - GG'!H:H)+SUMIF('ADV - FB'!A:A,$A46,'ADV - FB'!I:I) -> 1 | K46: =SUMIF('ADV - GA4'!A:A,A46,'ADV - GA4'!C:C) -> 2 | L46: =IFERROR(E46/J46,"") -> 0 | M46: =$M$34/$B$34 -> 0 | N46: =$N$34/$B$34 -> 0 | O46: =IFERROR(Planejador!$I$37,"") | P46: =Planejador!$I$28 | Q46: =Planejador!$I$30 | R46: =iferror(Planejador!$I$34,"") | S46: =$S$34/$B$34 -> 0 | T46: =iferror(Planejador!$I$29,"")
... A62: 46081 | B62: =TEXT(A62,"dddd") -> sábado | D62: =SUMIF('ADV - GG'!A:A,A62,'ADV - GG'!C:C)+SUMIF('ADV - FB'!A:A,$A62,'ADV - FB'!E:E) -> 35.17 | F62: =IFERROR(E62/D62,"") -> 0 | G62: =IFERROR(D62/K60,"") -> 3.9077778 | H62: =iferror(J62/K62,"") -> 1 | I62: =iferror(D62/J62,"") -> 17.585 | J62: =SUMIF('ADV - GG'!A:A,A62,'ADV - GG'!H:H)+SUMIF('ADV - FB'!A:A,$A62,'ADV - FB'!I:I) -> 2 | K62: =SUMIF('ADV - GA4'!A:A,A62,'ADV - GA4'!C:C) -> 2 | L62: =IFERROR(E62/J62,"") -> 0 | M62: =$M$34/$B$34 -> 0 | N62: =$N$34/$B$34 -> 0 | O62: =IFERROR(Planejador!$I$37,"") | P62: =Planejador!$I$28 | Q62: =Planejador!$I$30 | R62: =iferror(Planejador!$I$34,"") | S62: =$S$34/$B$34 -> 0 | T62: =iferror(Planejador!$I$29,"")
A63: 29/02/2026 | B63: =TEXT(A63,"dddd") -> 29/02/2026 | D63: =SUMIF('ADV - GG'!A:A,A63,'ADV - GG'!C:C)+SUMIF('ADV - FB'!A:A,$A63,'ADV - FB'!E:E) -> 0 | F63: =IFERROR(E63/D63,"") | G63: =IFERROR(D63/K61,"") -> 0 | H63: =iferror(J63/K63,"") | I63: =iferror(D63/J63,"") | J63: =SUMIF('ADV - GG'!A:A,A63,'ADV - GG'!H:H)+SUMIF('ADV - FB'!A:A,$A63,'ADV - FB'!I:I) -> 0 | K63: =SUMIF('ADV - GA4'!A:A,A63,'ADV - GA4'!C:C) -> 0 | L63: =IFERROR(E63/J63,"") | M63: =$M$34/$B$34 -> 0 | N63: =$N$34/$B$34 -> 0 | O63: =IFERROR(Planejador!$I$37,"") | P63: =Planejador!$I$28 | Q63: =Planejador!$I$30 | R63: =iferror(Planejador!$I$34,"") | S63: =$S$34/$B$34 -> 0 | T63: =iferror(Planejador!$I$29,"")
A64: MARÇO | B64: 31 | D64: =IFERROR(SUM(D65:D95),"") -> 1935.08 | E64: =iferror(SUM(E65:E95),"") -> 0 | F64: =iferror(E64/D64,"") -> 0 | G64: =iferror(D64/K64,"") -> 15.117812 | H64: =iferror(J64/K64,"") -> 0.4921875 | I64: =iferror(D64/J64,"") -> 30.715556 | J64: =iferror(SUM(J65:J95),"") -> 63 | K64: =IFERROR(SUM(K65:K95),"") -> 128 | L64: =iferror(E64/J64,"") -> 0 | M64: =Planejador!$I$50 | N64: =IFERROR(Planejador!$I$59,"") | O64: =IFERROR(Planejador!$I$60,"") | P64: =Planejador!$I$51 | Q64: =Planejador!$I$53 | R64: =iferror(Planejador!$I$57,"") | S64: =iferror(Planejador!$I$56,"") | T64: =iferror(Planejador!$I$52,"")
A65: 46082 | B65: =TEXT(A65,"dddd") -> domingo | D65: =SUMIF('ADV - GG'!A:A,A65,'ADV - GG'!C:C)+SUMIF('ADV - FB'!A:A,$A65,'ADV - FB'!E:E) -> 51.15 | F65: =IFERROR(E65/D65,"") -> 0 | G65: =IFERROR(D65/K65,"") -> 51.15 | H65: =iferror(J65/K65,"") -> 3 | I65: =iferror(D65/J65,"") -> 17.05 | J65: =SUMIF('ADV - GG'!A:A,A65,'ADV - GG'!H:H)+SUMIF('ADV - FB'!A:A,$A65,'ADV - FB'!I:I) -> 3 | K65: =SUMIF('ADV - GA4'!A:A,A65,'ADV - GA4'!C:C) -> 1 | L65: =IFERROR(E65/J65,"") -> 0 | M65: =$M$64/$B$64 -> 0 | N65: =$N$64/$B$64 -> 0 | O65: =IFERROR(Planejador!$I$60,"") | P65: =Planejador!$I$51 | Q65: =Planejador!$I$53 | R65: =iferror(Planejador!$I$57,"") | S65: =$S$64/$B$64 -> 0 | T65: =Planejador!$I$52
A66: 46083 | B66: =TEXT(A66,"dddd") -> segunda-feira | D66: =SUMIF('ADV - GG'!A:A,A66,'ADV - GG'!C:C)+SUMIF('ADV - FB'!A:A,$A66,'ADV - FB'!E:E) -> 66.59 | F66: =IFERROR(E66/D66,"") -> 0 | G66: =IFERROR(D66/K66,"") -> 16.6475 | H66: =iferror(J66/K66,"") -> 0.5 | I66: =iferror(D66/J66,"") -> 33.295 | J66: =SUMIF('ADV - GG'!A:A,A66,'ADV - GG'!H:H)+SUMIF('ADV - FB'!A:A,$A66,'ADV - FB'!I:I) -> 2 | K66: =SUMIF('ADV - GA4'!A:A,A66,'ADV - GA4'!C:C) -> 4 | L66: =IFERROR(E66/J66,"") -> 0 | M66: =$M$64/$B$64 -> 0 | N66: =$N$64/$B$64 -> 0 | O66: =IFERROR(Planejador!$I$60,"") | P66: =Planejador!$I$51 | Q66: =Planejador!$I$53 | R66: =iferror(Planejador!$I$57,"") | S66: =$S$64/$B$64 -> 0 | T66: =Planejador!$I$52
A67: 46084 | B67: =TEXT(A67,"dddd") -> terça-feira | D67: =SUMIF('ADV - GG'!A:A,A67,'ADV - GG'!C:C)+SUMIF('ADV - FB'!A:A,$A67,'ADV - FB'!E:E) -> 61.98 | F67: =IFERROR(E67/D67,"") -> 0 | G67: =IFERROR(D67/K67,"") -> 30.99 | H67: =iferror(J67/K67,"") -> 1 | I67: =iferror(D67/J67,"") -> 30.99 | J67: =SUMIF('ADV - GG'!A:A,A67,'ADV - GG'!H:H)+SUMIF('ADV - FB'!A:A,$A67,'ADV - FB'!I:I) -> 2 | K67: =SUMIF('ADV - GA4'!A:A,A67,'ADV - GA4'!C:C) -> 2 | L67: =IFERROR(E67/J67,"") -> 0 | M67: =$M$64/$B$64 -> 0 | N67: =$N$64/$B$64 -> 0 | O67: =IFERROR(Planejador!$I$60,"") | P67: =Planejador!$I$51 | Q67: =Planejador!$I$53 | R67: =iferror(Planejador!$I$57,"") | S67: =$S$64/$B$64 -> 0 | T67: =Planejador!$I$52
A68: 46085 | B68: =TEXT(A68,"dddd") -> quarta-feira | D68: =SUMIF('ADV - GG'!A:A,A68,'ADV - GG'!C:C)+SUMIF('ADV - FB'!A:A,$A68,'ADV - FB'!E:E) -> 55.45 | F68: =IFERROR(E68/D68,"") -> 0 | G68: =IFERROR(D68/K68,"") -> 13.8625 | H68: =iferror(J68/K68,"") -> 0.25 | I68: =iferror(D68/J68,"") -> 55.45 | J68: =SUMIF('ADV - GG'!A:A,A68,'ADV - GG'!H:H)+SUMIF('ADV - FB'!A:A,$A68,'ADV - FB'!I:I) -> 1 | K68: =SUMIF('ADV - GA4'!A:A,A68,'ADV - GA4'!C:C) -> 4 | L68: =IFERROR(E68/J68,"") -> 0 | M68: =$M$64/$B$64 -> 0 | N68: =$N$64/$B$64 -> 0 | O68: =IFERROR(Planejador!$I$60,"") | P68: =Planejador!$I$51 | Q68: =Planejador!$I$53 | R68: =iferror(Planejador!$I$57,"") | S68: =$S$64/$B$64 -> 0 | T68: =Planejador!$I$52
A69: 46086 | B69: =TEXT(A69,"dddd") -> quinta-feira | D69: =SUMIF('ADV - GG'!A:A,A69,'ADV - GG'!C:C)+SUMIF('ADV - FB'!A:A,$A69,'ADV - FB'!E:E) -> 69.46 | F69: =IFERROR(E69/D69,"") -> 0 | G69: =IFERROR(D69/K69,"") -> 23.153333 | H69: =iferror(J69/K69,"") -> 1 | I69: =iferror(D69/J69,"") -> 23.153333 | J69: =SUMIF('ADV - GG'!A:A,A69,'ADV - GG'!H:H)+SUMIF('ADV - FB'!A:A,$A69,'ADV - FB'!I:I) -> 3 | K69: =SUMIF('ADV - GA4'!A:A,A69,'ADV - GA4'!C:C) -> 3 | L69: =IFERROR(E69/J69,"") -> 0 | M69: =$M$64/$B$64 -> 0 | N69: =$N$64/$B$64 -> 0 | O69: =IFERROR(Planejador!$I$60,"") | P69: =Planejador!$I$51 | Q69: =Planejador!$I$53 | R69: =iferror(Planejador!$I$57,"") | S69: =$S$64/$B$64 -> 0 | T69: =Planejador!$I$52
A70: 46087 | B70: =TEXT(A70,"dddd") -> sexta-feira | D70: =SUMIF('ADV - GG'!A:A,A70,'ADV - GG'!C:C)+SUMIF('ADV - FB'!A:A,$A70,'ADV - FB'!E:E) -> 70.74 | F70: =IFERROR(E70/D70,"") -> 0 | G70: =IFERROR(D70/K70,"") -> 14.148 | H70: =iferror(J70/K70,"") -> 1 | I70: =iferror(D70/J70,"") -> 14.148 | J70: =SUMIF('ADV - GG'!A:A,A70,'ADV - GG'!H:H)+SUMIF('ADV - FB'!A:A,$A70,'ADV - FB'!I:I) -> 5 | K70: =SUMIF('ADV - GA4'!A:A,A70,'ADV - GA4'!C:C) -> 5 | L70: =IFERROR(E70/J70,"") -> 0 | M70: =$M$64/$B$64 -> 0 | N70: =$N$64/$B$64 -> 0 | O70: =IFERROR(Planejador!$I$60,"") | P70: =Planejador!$I$51 | Q70: =Planejador!$I$53 | R70: =iferror(Planejador!$I$57,"") | S70: =$S$64/$B$64 -> 0 | T70: =Planejador!$I$52
A71: 46088 | B71: =TEXT(A71,"dddd") -> sábado | D71: =SUMIF('ADV - GG'!A:A,A71,'ADV - GG'!C:C)+SUMIF('ADV - FB'!A:A,$A71,'ADV - FB'!E:E) -> 66.94 | F71: =IFERROR(E71/D71,"") -> 0 | G71: =IFERROR(D71/K71,"") -> 66.94 | H71: =iferror(J71/K71,"") -> 1 | I71: =iferror(D71/J71,"") -> 66.94 | J71: =SUMIF('ADV - GG'!A:A,A71,'ADV - GG'!H:H)+SUMIF('ADV - FB'!A:A,$A71,'ADV - FB'!I:I) -> 1 | K71: =SUMIF('ADV - GA4'!A:A,A71,'ADV - GA4'!C:C) -> 1 | L71: =IFERROR(E71/J71,"") -> 0 | M71: =$M$64/$B$64 -> 0 | N71: =$N$64/$B$64 -> 0 | O71: =IFERROR(Planejador!$I$60,"") | P71: =Planejador!$I$51 | Q71: =Planejador!$I$53 | R71: =iferror(Planejador!$I$57,"") | S71: =$S$64/$B$64 -> 0 | T71: =Planejador!$I$52
A72: 46089 | B72: =TEXT(A72,"dddd") -> domingo | D72: =SUMIF('ADV - GG'!A:A,A72,'ADV - GG'!C:C)+SUMIF('ADV - FB'!A:A,$A72,'ADV - FB'!E:E) -> 81.19 | F72: =IFERROR(E72/D72,"") -> 0 | G72: =IFERROR(D72/K72,"") -> 27.063333 | H72: =iferror(J72/K72,"") -> 0.33333333 | I72: =iferror(D72/J72,"") -> 81.19 | J72: =SUMIF('ADV - GG'!A:A,A72,'ADV - GG'!H:H)+SUMIF('ADV - FB'!A:A,$A72,'ADV - FB'!I:I) -> 1 | K72: =SUMIF('ADV - GA4'!A:A,A72,'ADV - GA4'!C:C) -> 3 | L72: =IFERROR(E72/J72,"") -> 0 | M72: =$M$64/$B$64 -> 0 | N72: =$N$64/$B$64 -> 0 | O72: =IFERROR(Planejador!$I$60,"") | P72: =Planejador!$I$51 | Q72: =Planejador!$I$53 | R72: =iferror(Planejador!$I$57,"") | S72: =$S$64/$B$64 -> 0 | T72: =Planejador!$I$52
A73: 46090 | B73: =TEXT(A73,"dddd") -> segunda-feira | D73: =SUMIF('ADV - GG'!A:A,A73,'ADV - GG'!C:C)+SUMIF('ADV - FB'!A:A,$A73,'ADV - FB'!E:E) -> 81.01 | F73: =IFERROR(E73/D73,"") -> 0 | G73: =IFERROR(D73/K73,"") -> 20.2525 | H73: =iferror(J73/K73,"") -> 0 | I73: =iferror(D73/J73,"") | J73: =SUMIF('ADV - GG'!A:A,A73,'ADV - GG'!H:H)+SUMIF('ADV - FB'!A:A,$A73,'ADV - FB'!I:I) -> 0 | K73: =SUMIF('ADV - GA4'!A:A,A73,'ADV - GA4'!C:C) -> 4 | L73: =IFERROR(E73/J73,"") | M73: =$M$64/$B$64 -> 0 | N73: =$N$64/$B$64 -> 0 | O73: =IFERROR(Planejador!$I$60,"") | P73: =Planejador!$I$51 | Q73: =Planejador!$I$53 | R73: =iferror(Planejador!$I$57,"") | S73: =$S$64/$B$64 -> 0 | T73: =Planejador!$I$52
...

Sheet Dados Históricos
A1: CRESCIMENTO MoM | C1: =(C3-B3)/B3*1 -> #DIV/0! | D1: =(D3-C3)/C3*1 -> #DIV/0! | E1: =(E3-D3)/D3*1 -> #DIV/0! | F1: =(F3-E3)/E3*1 -> #DIV/0! | G1: =(G3-F3)/F3*1 -> #DIV/0! | H1: =(H3-G3)/G3*1 -> #DIV/0! | I1: =(I3-H3)/H3*1 -> #DIV/0! | J1: =(J3-I3)/I3*1 -> #DIV/0! | ... M1: =(M3-L3)/L3*1 -> #DIV/0! | O1: MÉTRICAS MÉDIAS
A2: MÉTRICAS / MÊS | B2: JAN | C2: FEV | D2: MAR | E2: ABR | F2: MAI | G2: JUN | H2: JUL | I2: AGO | J2: SET | K2: OUT | L2: NOV | M2: DEZ | O2: Crescimento Médio | P2: =AVERAGE(C1:K1) -> #DIV/0!
A3: Receita Captada | O3: Receita Captada | P3: =AVERAGE(B3:M3) -> #DIV/0!
A4: Receita Faturada | O4: Receita Faturada | P4: =AVERAGE(B4:M4) -> #DIV/0!
A5: % de Aprovação | B5: =IFERROR(B4/B3,"") | C5: =IFERROR(C4/C3,"") | D5: =IFERROR(D4/D3,"") | E5: =IFERROR(E4/E3,"") | F5: =IFERROR(F4/F3,"") | G5: =IFERROR(G4/G3,"") | H5: =IFERROR(H4/H3,"") | I5: =IFERROR(I4/I3,"") | ... M5: =IFERROR(M4/M3,"") | O5: % Aprovação | P5: =AVERAGE(B5:M5) -> #DIV/0!
A6: Receita Captada Midia Paga | O6: Receita Mídia | P6: =AVERAGE(B6:M6) -> #DIV/0!
A7: % Mídia Paga | B7: =IFERROR((B6/B3)*1,"") | C7: =IFERROR((C6/C3)*1,"") | D7: =IFERROR((D6/D3)*1,"") | E7: =IFERROR((E6/E3)*1,"") | F7: =IFERROR((F6/F3)*1,"") | G7: =IFERROR((G6/G3)*1,"") | H7: =IFERROR((H6/H3)*1,"") | I7: =IFERROR((I6/I3)*1,"") | ... M7: =IFERROR((M6/M3)*1,"") | O7: % Mídia Paga | P7: =AVERAGE(B7:J7) -> #DIV/0!
A8: Receita Captada Outros Canais | B8: =IFERROR(B3-B6,"") -> 0 | C8: =IFERROR(C3-C6,"") -> 0 | D8: =IFERROR(D3-D6,"") -> 0 | E8: =IFERROR(E3-E6,"") -> 0 | F8: =IFERROR(F3-F6,"") -> 0 | G8: =IFERROR(G3-G6,"") -> 0 | H8: =IFERROR(H3-H6,"") -> 0 | I8: =IFERROR(I3-I6,"") -> 0 | ... M8: =IFERROR(M3-M6,"") -> 0 | O8: Receita Canais | P8: =AVERAGE(B8:M8) -> 0
A9: % Outros Canais | B9: =IFERROR((B8/B3)*1,"") | C9: =IFERROR((C8/C3)*1,"") | D9: =IFERROR((D8/D3)*1,"") | E9: =IFERROR((E8/E3)*1,"") | F9: =IFERROR((F8/F3)*1,"") | G9: =IFERROR((G8/G3)*1,"") | H9: =IFERROR((H8/H3)*1,"") | I9: =IFERROR((I8/I3)*1,"") | ... M9: =IFERROR((M8/M3)*1,"") | O9: % Outros Canais | P9: =AVERAGE(B9:M9) -> #DIV/0!
A10: Investimento Ads | O10: Investimento | P10: =AVERAGE(B10:M10) -> #DIV/0!
A11: % Aumento / Redução ADS | C11: =(C10-B10)/B10*1 -> #DIV/0! | D11: =(D10-C10)/C10*1 -> #DIV/0! | E11: =(E10-D10)/D10*1 -> #DIV/0! | F11: =(F10-E10)/E10*1 -> #DIV/0! | G11: =(G10-F10)/F10*1 -> #DIV/0! | H11: =(H10-G10)/G10*1 -> #DIV/0! | I11: =(I10-H10)/H10*1 -> #DIV/0! | J11: =(J10-I10)/I10*1 -> #DIV/0! | O11: % Aumento / Redução ADS | P11: =AVERAGE(B11:M11) -> #DIV/0!
A12: Sessões Totais | O12: Sessões Geral | P12: =AVERAGE(B12:M12) -> #DIV/0!
A13: Sessões Midia | O13: Sessões Mídia | P13: =AVERAGE(B13:M13) -> #DIV/0!
A14: CPS Geral | B14: =IFERROR(B10/B12,"") | C14: =IFERROR(C10/C12,"") | D14: =IFERROR(D10/D12,"") | E14: =IFERROR(E10/E12,"") | F14: =IFERROR(F10/F12,"") | G14: =IFERROR(G10/G12,"") | H14: =IFERROR(H10/H12,"") | I14: =IFERROR(I10/I12,"") | ... M14: =IFERROR(M10/M12,"") | O14: CPS Geral | P14: =AVERAGE(B14:M14) -> #DIV/0!
A15: CPS Midia | B15: =IFERROR(B10/B13,"") | C15: =IFERROR(C10/C13,"") | D15: =IFERROR(D10/D13,"") | E15: =IFERROR(E10/E13,"") | F15: =IFERROR(F10/F13,"") | G15: =IFERROR(G10/G13,"") | H15: =IFERROR(H10/H13,"") | I15: =IFERROR(I10/I13,"") | ... M15: =IFERROR(M10/M13,"") | O15: CPS Mídia | P15: =AVERAGE(B15:M15) -> #DIV/0!
A16: Transações Captadas | O16: Pedidos | P16: =AVERAGE(B16:M16) -> #DIV/0!
A17: Ticket Médio | B17: =IFERROR(B3/B16,"") | C17: =IFERROR(C3/C16,"") | D17: =IFERROR(D3/D16,"") | E17: =IFERROR(E3/E16,"") | F17: =IFERROR(F3/F16,"") | G17: =IFERROR(G3/G16,"") | H17: =IFERROR(H3/H16,"") | I17: =IFERROR(I3/I16,"") | ... M17: =IFERROR(M3/M16,"") | O17: Ticket Médio | P17: =AVERAGE(B17:M17) -> #DIV/0!
A18: Taxa de Conversão | B18: =IFERROR(B16/B12,"") | C18: =IFERROR(C16/C12,"") | D18: =IFERROR(D16/D12,"") | E18: =IFERROR(E16/E12,"") | F18: =IFERROR(F16/F12,"") | G18: =IFERROR(G16/G12,"") | H18: =IFERROR(H16/H12,"") | I18: =IFERROR(I16/I12,"") | ... M18: =IFERROR(M16/M12,"") | O18: Taxa de Conversão | P18: =AVERAGE(B18:M18) -> #DIV/0!
A19: ROAS Captado | B19: =IFERROR(B3/B10,"") | C19: =IFERROR(C3/C10,"") | D19: =IFERROR(D3/D10,"") | E19: =IFERROR(E3/E10,"") | F19: =IFERROR(F3/F10,"") | G19: =IFERROR(G3/G10,"") | H19: =IFERROR(H3/H10,"") | I19: =IFERROR(I3/I10,"") | ... M19: =IFERROR(M3/M10,"") | O19: ROAS Captado | P19: =AVERAGE(B19:M19) -> #DIV/0!
A20: % + - ROAS Geral | C20: =(C19/B19)-1 -> #DIV/0! | D20: =(D19/C19)-1 -> #DIV/0! | E20: =(E19/D19)-1 -> #DIV/0! | F20: =(F19/E19)-1 -> #DIV/0! | G20: =(G19/F19)-1 -> #DIV/0! | H20: =(H19/G19)-1 -> #DIV/0! | I20: =(I19/H19)-1 -> #DIV/0! | J20: =(J19/I19)-1 -> #DIV/0! | O20: % + - ROAS Geral | P20: =AVERAGE(B20:M20) -> #DIV/0!
A21: ROAS Faturado | B21: =IFERROR(B4/B10,"") | C21: =IFERROR(C4/C10,"") | D21: =IFERROR(D4/D10,"") | E21: =IFERROR(E4/E10,"") | F21: =IFERROR(F4/F10,"") | G21: =IFERROR(G4/G10,"") | H21: =IFERROR(H4/H10,"") | I21: =IFERROR(I4/I10,"") | ... M21: =IFERROR(M4/M10,"") | O21: ROAS Faturado | P21: =AVERAGE(B21:M21) -> #DIV/0!
A22: ROAS Midia Paga | B22: =IFERROR(B6/B10,"") | C22: =IFERROR(C6/C10,"") | D22: =IFERROR(D6/D10,"") | E22: =IFERROR(E6/E10,"") | F22: =IFERROR(F6/F10,"") | G22: =IFERROR(G6/G10,"") | H22: =IFERROR(H6/H10,"") | I22: =IFERROR(I6/I10,"") | ... M22: =IFERROR(M6/M10,"") | O22: ROAS Mídia | P22: =AVERAGE(B22:M22) -> #DIV/0!
A23: % + - ROAS Midia | C23: =IFERROR((C22/B22)-1,"") | D23: =(D22/C22)-1 -> #DIV/0! | E23: =(E22/D22)-1 -> #DIV/0! | F23: =(F22/E22)-1 -> #DIV/0! | G23: =(G22/F22)-1 -> #DIV/0! | H23: =(H22/G22)-1 -> #DIV/0! | I23: =(I22/H22)-1 -> #DIV/0! | J23: =(J22/I22)-1 -> #DIV/0! | O23: % + - ROAS Midia | P23: =AVERAGE(B23:M23) -> #DIV/0!
A27: CANAIS | B27: JAN | C27: FEV | D27: MAR | E27: ABR | F27: MAI | G27: JUN | H27: JUL | I27: AGO | J27: SET | K27: OUT | L27: NOV | M27: DEZ | O27: TOTAL
A28: (Other) | O28: =SUM(B28:M28) -> 0 | P28: =O28/$O$42 -> #DIV/0!
A29: Direto / none | O29: =SUM(B29:M29) -> 0 | P29: =O29/$O$42 -> #DIV/0!
A30: Facebook cpc | O30: =SUM(B30:M30) -> 0 | P30: =O30/$O$42 -> #DIV/0!
A31: Google cpc | O31: =SUM(B31:M31) -> 0 | P31: =O31/$O$42 -> #DIV/0!
A32: Orgânico | O32: =SUM(B32:M32) -> 0 | P32: =O32/$O$42 -> #DIV/0!
A33: Instagram Perfil | O33: =SUM(B33:M33) -> 0 | P33: =O33/$O$42 -> #DIV/0!
A34: E-mail | O34: =SUM(B34:M34) -> 0 | P34: =O34/$O$42 -> #DIV/0!
A35: IG Shopping | O35: =SUM(B35:M35) -> 0 | P35: =O35/$O$42 -> #DIV/0!
A36: Instagram / FB Referral | O36: =SUM(B36:M36) -> 0 | P36: =O36/$O$42 -> #DIV/0!
A37: Blog | O37: =SUM(B37:M37) -> 0 | P37: =O37/$O$42 -> #DIV/0!
A38: Pinterest / Referral | O38: =SUM(B38:M38) -> 0 | P38: =O38/$O$42 -> #DIV/0!
A39: TikTok | O39: =SUM(B39:M39) -> 0 | P39: =O39/$O$42 -> #DIV/0!
... A41: Youtube referral | O41: =SUM(B41:M41) -> 0 | P41: =O41/$O$42 -> #DIV/0!
A42: Total de receita | B42: =IFERROR(SUM(B28:B41),"") -> 0 | C42: =IFERROR(SUM(C28:C41),"") -> 0 | D42: =IFERROR(SUM(D28:D41),"") -> 0 | E42: =IFERROR(SUM(E28:E41),"") -> 0 | F42: =IFERROR(SUM(F28:F41),"") -> 0 | G42: =IFERROR(SUM(G28:G41),"") -> 0 | H42: =IFERROR(SUM(H28:H41),"") -> 0 | I42: =IFERROR(SUM(I28:I41),"") -> 0 | ... M42: =IFERROR(SUM(M28:M41),"") -> 0 | O42: =SUM(B42:M42) -> 0
A43: Share dos meses | B43: =IFERROR(B42/$O$42,"") | C43: =IFERROR(C42/$O$42,"") | D43: =IFERROR(D42/$O$42,"") | E43: =IFERROR(E42/$O$42,"") | F43: =IFERROR(F42/$O$42,"") | G43: =IFERROR(G42/$O$42,"") | H43: =IFERROR(H42/$O$42,"") | I43: =IFERROR(I42/$O$42,"") | ... M43: =IFERROR(M42/$O$42,"")

Sheet Planejador
B1: JANEIRO
B3: CENÁRIO ATUAL (ÚLTIMO MÊS) | E3: CENÁRIO DESEJADO | H3: CENÁRIO IDEAL | J3: MÉDIA / ANUAL | K3: % ATUAL | L3: % MÁX
B4: Valor Investimento | E4: Faturamento Desejado | H4: Verba Mensal | K4: =(I4-J4)/J4*1 -> #DIV/0! | L4: 0.4
B5: CPS Geral | E5: CPS Atual | F5: =C5 | H5: CPS Ideal | K5: =(I5-J5)/J5*1 -> #DIV/0! | L5: -0.1
B6: Ticket Médio | E6: Ticket Médio | F6: =C6 | H6: Ticket Médio Ideal | K6: =(I6-J6)/J6*1 -> #DIV/0! | L6: 0.1
B7: TX Conversão | E7: Taxa de Conversão Atual | F7: =C7 | H7: Taxa Conversão Ideal | K7: =(I7-J7)/J7*1 -> #DIV/0! | L7: 0.1
B8: % De Aprovação | E8: % De Pagamento Atual | F8: =C8 | H8: Aprovação Pagamento | K8: =(I8-J8)/J8*1 -> #DIV/0! | L8: 0.03
B10: Sessões | C10: =C4/C5 -> #DIV/0! | E10: Visitas Ideais | F10: =F12/F7 -> #DIV/0! | H10: Visitas Ideais | I10: =I4/I5 -> #DIV/0! | K10: CANAL DE VENDA | L10: % | M10: FATURAMENTO | N10: PEDIDOS POR CANAL | Q10: 80/20 PRODUTOS | R10: PRODUTO | S10: % | T10: PEDIDOS POR PRODUTO | U10: TICKET MÉDIO | V10: FATURAMENTO ESPERADO
B11: CPA | C11: =C4/C12 -> #DIV/0! | E11: CPA Ideal | F11: =F15/F12 -> #DIV/0! | H11: CPA Ideal | I11: =I4/I12 -> #DIV/0! | K11: Meta Ads | L11: 0.2 | M11: =I15/100*L11*100 -> #DIV/0! | N11: =M11/I6 -> #DIV/0! | Q11: 80% DAS VENDAS | R11: Produto 1 | S11: 0.25 | T11: =I12*S11 -> #DIV/0! | U11: 100 | V11: =T11*U11 -> #DIV/0!
B12: Pedidos | C12: =C10*C7 -> #DIV/0! | E12: Pedidos Mês Ideal | F12: =F13/F6 -> #DIV/0! | H12: Pedidos Mês Ideal | I12: =I10*I7 -> #DIV/0! | K12: Google Ads | L12: 0.2 | M12: =I15/100*L12*100 -> #DIV/0! | N12: =M12/I6 -> #DIV/0! | R12: Produto 2 | S12: 0.2 | T12: =I12*S12 -> #DIV/0! | U12: 100 | V12: =T12*U12 -> #DIV/0!
B13: Faturamento Captado | C13: =(C10*C7)*C6 -> #DIV/0! | E13: Faturamento Captado | F13: =F4/F8 -> #DIV/0! | H13: Faturamento Bruto | I13: =I10*I7*I6 -> #DIV/0! | K13: Social | L13: 0.3 | M13: =I15/100*L13*100 -> #DIV/0! | N13: =M13/I6 -> #DIV/0! | R13: Produto 3 | S13: 0.2 | T13: =I12*S13 -> #DIV/0! | U13: 100 | V13: =T13*U13 -> #DIV/0!
B14: ROAS Bruto | C14: =C13/C4 -> #DIV/0! | E14: ROAS Bruto | F14: =F13/F15 -> #DIV/0! | H14: ROAS Bruto | I14: =I13/I4 -> #DIV/0! | K14: Organico | L14: 0.15 | M14: =I15/100*L14*100 -> #DIV/0! | N14: =M14/I6 -> #DIV/0! | R14: Produto 4 | S14: 0.15 | T14: =I12*S14 -> #DIV/0! | U14: 100 | V14: =T14*U14 -> #DIV/0!
B15: Faturamento Real | C15: =C13*C8 -> #DIV/0! | E15: Investimento Necessário | F15: =F10*F5 -> #DIV/0! | H15: Faturamento Desejado | I15: =I13*I8 -> #DIV/0! | K15: E-mail | L15: 0.15 | M15: =I15/100*L15*100 -> #DIV/0! | N15: =M15/I6 -> #DIV/0! | Q15: 20% DAS VENDAS | R15: Produto 5 | S15: 0.05 | T15: =I12*S15 -> #DIV/0! | U15: 100 | V15: =T15*U15 -> #DIV/0!
B16: ROAS Real | C16: =C15/C4 -> #DIV/0! | E16: ROAS Desejado | F16: =F4/F15 -> #DIV/0! | H16: ROAS Real | I16: =I15/I4 -> #DIV/0! | L16: =SUM(L11:L15) -> 1 | N16: =SUM(N11:N15) -> #DIV/0! | R16: Produto 6 | S16: 0.05 | T16: =I12*S16 -> #DIV/0! | U16: 100 | V16: =T16*U16 -> #DIV/0!
R17: Produto 7 | S17: 0.05 | T17: =I12*S17 -> #DIV/0! | U17: 100 | V17: =T17*U17 -> #DIV/0!
B18: CENÁRIO DIÁRIO ATUAL | E18: CENÁRIO DIÁRIO DESEJADO | H18: CENÁRIO DIÁRIO IDEAL | K18: Canal | L18: Facebook | M18: Google | N18: Outros | O18: Total | R18: Produto 8 | S18: 0.05 | T18: =I12*S18 -> #DIV/0! | U18: 100 | V18: =T18*U18 -> #DIV/0!
B19: Investimento Diário | C19: =C4/30 -> 0 | E19: Investimento Diário | F19: =F4/30 -> 0 | H19: Investimento Diário | I19: =I4/'Acompanhamento Geral'!B2 -> 0 | K19: % | L19: 0.7 | M19: 0.3 | N19: 0 | O19: =sum(L19:N19) -> 1 | S19: =SUM(S11:S18) -> 1 | T19: =SUM(T11:T18) -> #DIV/0! | V19: =SUM(V11:V18) -> #DIV/0!
B20: Sessões Diárias | C20: =C10/30 -> #DIV/0! | E20: Sessões Diárias | F20: =F10/30 -> #DIV/0! | H20: Sessões Diárias | I20: =I10/'Acompanhamento Geral'!B2 -> #DIV/0! | K20: Verba Mês | L20: =I4*L19 -> 0 | M20: =I4*M19 -> 0 | N20: =I4*N19 -> 0 | O20: =sum(L20:N20) -> 0
B21: Pedidos Diários | C21: =C12/30 -> #DIV/0! | E21: Pedidos Diários | F21: =F12/30 -> #DIV/0! | H21: Pedidos Diários | I21: =I12/'Acompanhamento Geral'!B2 -> #DIV/0! | K21: Verba Dia | L21: =L20/'Acompanhamento Geral'!B2 -> 0 | M21: =M20/'Acompanhamento Geral'!B2 -> 0 | N21: =iferror(N20/'Acompanhamento Geral'!B2,"") -> 0 | O21: =SUM(L21:N21) -> 0
B22: Faturamento Diário | C22: =C13/30 -> #DIV/0! | E22: Faturamento Diário | F22: =F13/30 -> #DIV/0! | H22: Faturamento Diário | I22: =I13/'Acompanhamento Geral'!B2 -> #DIV/0!
B24: FEVEREIRO
B26: CENÁRIO ATUAL (ÚLTIMO MÊS) | E26: CENÁRIO DESEJADO | H26: CENÁRIO IDEAL | J26: MÉDIA / ANUAL | K26: % ATUAL | L26: % MÁX
B27: Valor Investimento | E27: Faturamento Desejado | H27: Verba Mensal | K27: =(I27-J27)/J27*1 -> #DIV/0! | L27: 0.4
B28: CPS Geral | E28: CPS Atual | F28: =C28 | H28: CPS Ideal | K28: =(I28-J28)/J28*1 -> #DIV/0! | L28: -0.1
B29: Ticket Médio | E29: Ticket Médio | F29: =C29 | H29: Ticket Médio Ideal | K29: =(I29-J29)/J29*1 -> #DIV/0! | L29: 0.1
B30: TX Conversão | E30: Taxa de Conversão Atual | F30: =C30 | H30: Taxa Conversão Ideal | K30: =(I30-J30)/J30*1 -> #DIV/0! | L30: 0.1
B31: % De Aprovação | E31: % De Pagamento Atual | F31: =C31 | H31: Aprovação Pagamento | K31: =(I31-J31)/J31*1 -> #DIV/0! | L31: 0.03
B33: Sessões | C33: =C27/C28 -> #DIV/0! | E33: Visitas Ideais | F33: =F35/F30 -> #DIV/0! | H33: Visitas Ideais | I33: =I27/I28 -> #DIV/0! | K33: CANAL DE VENDA | L33: % | M33: FATURAMENTO | N33: PEDIDOS POR CANAL
B34: CPA | C34: =C27/C35 -> #DIV/0! | E34: CPA Ideal | F34: =F38/F35 -> #DIV/0! | H34: CPA Ideal | I34: =I27/I35 -> #DIV/0! | K34: Meta Ads | L34: 0.2 | M34: =I38/100*L34*100 -> #DIV/0! | N34: =M34/I29 -> #DIV/0!
B35: Pedidos | C35: =C33*C30 -> #DIV/0! | E35: Pedidos Mês Ideal | F35: =F36/F29 -> #DIV/0! | H35: Pedidos Mês Ideal | I35: =I33*I30 -> #DIV/0! | K35: Google Ads | L35: 0.2 | M35: =I38/100*L35*100 -> #DIV/0! | N35: =M35/I29 -> #DIV/0!
B36: Faturamento Captado | C36: =(C33*C30)*C29 -> #DIV/0! | E36: Faturamento Captado | F36: =F27/F31 -> #DIV/0! | H36: Faturamento Bruto | I36: =I33*I30*I29 -> #DIV/0! | K36: Social | L36: 0.3 | M36: =I38/100*L36*100 -> #DIV/0! | N36: =M36/I29 -> #DIV/0!
B37: ROAS Bruto | C37: =C36/C27 -> #DIV/0! | E37: ROAS Bruto | F37: =F36/F38 -> #DIV/0! | H37: ROAS Bruto | I37: =I36/I27 -> #DIV/0! | K37: Organico | L37: 0.15 | M37: =I38/100*L37*100 -> #DIV/0! | N37: =M37/I29 -> #DIV/0!
B38: Faturamento Real | C38: =C36*C31 -> #DIV/0! | E38: Investimento Necessário | F38: =F33*F28 -> #DIV/0! | H38: Faturamento Desejado | I38: =I36*I31 -> #DIV/0! | K38: E-mail | L38: 0.15 | M38: =I38/100*L38*100 -> #DIV/0! | N38: =M38/I29 -> #DIV/0!
B39: ROAS Real | C39: =C38/C27 -> #DIV/0! | E39: ROAS Desejado | F39: =F27/F38 -> #DIV/0! | H39: ROAS Real | I39: =I38/I27 -> #DIV/0! | L39: =SUM(L34:L38) -> 1 | N39: =SUM(N34:N38) -> #DIV/0!
B41: CENÁRIO DIÁRIO ATUAL | E41: CENÁRIO DIÁRIO DESEJADO | H41: CENÁRIO DIÁRIO IDEAL | K41: Canal | L41: Facebook | M41: Google | N41: Outros | O41: Total
B42: Investimento Diário | C42: =C27/30 -> 0 | E42: Investimento Diário | F42: =F27/30 -> 0 | H42: Investimento Diário | I42: =I27/'Acompanhamento Geral'!B34 -> 0 | K42: % | L42: 0.7 | M42: 0.3 | N42: 0 | O42: =sum(L42:N42) -> 1
B43: Sessões Diárias | C43: =C33/30 -> #DIV/0! | E43: Sessões Diárias | F43: =F33/30 -> #DIV/0! | H43: Sessões Diárias | I43: =I33/'Acompanhamento Geral'!B34 -> #DIV/0! | K43: Verba Mês | L43: =I27*L42 -> 0 | M43: =I27*M42 -> 0 | N43: =I27*N42 -> 0 | O43: =sum(L43:N43) -> 0
B44: Pedidos Diários | C44: =C35/30 -> #DIV/0! | E44: Pedidos Diários | F44: =F35/30 -> #DIV/0! | H44: Pedidos Diários | I44: =I35/'Acompanhamento Geral'!B34 -> #DIV/0! | K44: Verba Dia | L44: =L43/'Acompanhamento Geral'!B34 -> 0 | M44: =M43/'Acompanhamento Geral'!B34 -> 0 | N44: =iferror(N43/'Acompanhamento Geral'!B34,"") -> 0 | O44: =SUM(L44:N44) -> 0
B45: Faturamento Diário | C45: =C36/30 -> #DIV/0! | E45: Faturamento Diário | F45: =F36/30 -> #DIV/0! | H45: Faturamento Diário | I45: =I36/'Acompanhamento Geral'!B34 -> #DIV/0!
B47: MARÇO
...

Sheet Projeção Rápida
D1: PROJEÇÃO RÁPIDA
B3: Investimento | D3: CPS | F3: Canal | G3: Facebook | H3: Google | I3: Outros
B4: 10000 | D4: 0.3 | F4: % | G4: 0.7 | H4: 0.4 | I4: 0
F5: Verba Mês | G5: =G4*$B$4 -> 7000 | H5: =H4*$B$4 -> 4000 | I5: =I4*$B$4 -> 0
B6: Ticket Médio | D6: Taxa de Conversão | F6: Verba Dia | G6: =ROUNDUP((B4*G4)/30,0) -> 234 | H6: =ROUNDUP((B4*H4)/30,0) -> 134 | I6: =ROUNDUP((B4*I4)/30,0) -> 0 | J6: =SUM(G6:I6) -> 368
B7: 150 | D7: 0.015
B9: MER | D9: VISITAS
B10: =B16/B4 -> 7.5 | D10: =B4/D4 -> 33333.333
B12: CPA | D12: N. PEDIDOS / MÊS
B13: =B4/D13 -> 20 | D13: =D10*D7 -> 500
B15: FATURAMENTO
B16: =D13*B7 -> 75000
B18: ANTES DE ENTRAR NO SITE | D18: DEPOIS DE ENTRAR NO SITE
B19: MELHORIAS PARA CPC | D19: MELHORIAS PARA TX
B20: CRIATIVO | D20: NAVEGABILIDADE
B21: COPY | D21: CONTEÚDO
B22: PÚBLICO | D22: OFERTA
B23: OFERTA | D23: FRETE
B24: CAMPANHAS DE CPC BAIXO | D24: CHECKOUT
B25: PRODUTO | D25: CREDIBILIDADE E PROVA SOCIAL
B26: QUALIDADE DA PÁGINA
B28: BENCHMARK MERCADO | D28: BENCHMARK MERCADO
B29: CPS | D29: TAXA DE CONVERSÃO
B30: 0.35 | D30: 0.005
B31: 0.6 | D31: 0.01
B32: 0.9 | D32: 0.015

Sheet DRE Performance
B3: Preencer dados (Atual) | E3: Não Preencer dados | I3: Não Preencer dados
B4: Preencher | E4: DRE | H4: 0.25 | I4: ROAS/Budget | J4: =C12 -> 5000 | K4: =J4*(1+$H$4) -> 6250 | L4: =K4*(1+$H$4) -> 7812.5 | M4: =L4*(1+$H$4) -> 9765.625 | N4: =M4*(1+$H$4) -> 12207.031 | O4: =N4*(1+$H$4) -> 15258.789 | P4: =O4*(1+$H$4) -> 19073.486 | Q4: =P4*(1+$H$4) -> 23841.858 | R4: =Q4*(1+$H$4) -> 29802.322 | S4: =R4*(1+$H$4) -> 37252.903
B5: Receita Mensal (R$) | C5: 10000 | E5: Ticket Médio | F5: =C5/C6 -> 100 | I5: 1 | J5: =($J$4*I5)-(($J$4*I5)*(SUM($G$6:$G$10)))-$J$4 -> -3500 | K5: =($K$4*I5)-(($K$4*I5)*(SUM($G$6:$G$10)))-$K$4 -> -4375 | L5: =($L$4*I5)-(($L$4*I5)*(SUM($G$6:$G$10)))-$L$4 -> -5468.75 | M5: =($M$4*I5)-(($M$4*I5)*(SUM($G$6:$G$10)))-$M$4 -> -6835.9375 | N5: =($N$4*I5)-(($N$4*I5)*(SUM($G$6:$G$10)))-$N$4 -> -8544.9219 | O5: =($O$4*I5)-(($O$4*I5)*(SUM($G$6:$G$10)))-$O$4 -> -10681.152 | P5: =($P$4*I5)-(($P$4*I5)*(SUM($G$6:$G$10)))-$P$4 -> -13351.44 | Q5: =($Q$4*I5)-(($Q$4*I5)*(SUM($G$6:$G$10)))-$Q$4 -> -16689.301 | R5: =($R$4*I5)-(($R$4*I5)*(SUM($G$6:$G$10)))-$R$4 -> -20861.626 | S5: =($S$4*I5)-(($S$4*I5)*(SUM($G$6:$G$10)))-$S$4 -> -26077.032
B6: Número de pedidos | C6: 100 | E6: (-) Gateway de pagamento | F6: =C8*F5 -> 7 | G6: =F6/$F$5 -> 0.07 | I6: 1.5 | J6: =($J$4*I6)-(($J$4*I6)*(SUM($G$6:$G$10)))-$J$4 -> -2750 | K6: =($K$4*I6)-(($K$4*I6)*(SUM($G$6:$G$10)))-$K$4 -> -3437.5 | L6: =($L$4*I6)-(($L$4*I6)*(SUM($G$6:$G$10)))-$L$4 -> -4296.875 | M6: =($M$4*I6)-(($M$4*I6)*(SUM($G$6:$G$10)))-$M$4 -> -5371.0938 | N6: =($N$4*I6)-(($N$4*I6)*(SUM($G$6:$G$10)))-$N$4 -> -6713.8672 | O6: =($O$4*I6)-(($O$4*I6)*(SUM($G$6:$G$10)))-$O$4 -> -8392.334 | P6: =($P$4*I6)-(($P$4*I6)*(SUM($G$6:$G$10)))-$P$4 -> -10490.417 | Q6: =($Q$4*I6)-(($Q$4*I6)*(SUM($G$6:$G$10)))-$Q$4 -> -13113.022 | R6: =($R$4*I6)-(($R$4*I6)*(SUM($G$6:$G$10)))-$R$4 -> -16391.277 | S6: =($S$4*I6)-(($S$4*I6)*(SUM($G$6:$G$10)))-$S$4 -> -20489.097
B7: Número de devoluções | C7: 0 | E7: (-) Devoluções | F7: =(C7/C6)*F5 -> 0 | G7: =F7/$F$5 -> 0 | I7: 2 | J7: =($J$4*I7)-(($J$4*I7)*(SUM($G$6:$G$10)))-$J$4 -> -2000 | K7: =($K$4*I7)-(($K$4*I7)*(SUM($G$6:$G$10)))-$K$4 -> -2500 | L7: =($L$4*I7)-(($L$4*I7)*(SUM($G$6:$G$10)))-$L$4 -> -3125 | M7: =($M$4*I7)-(($M$4*I7)*(SUM($G$6:$G$10)))-$M$4 -> -3906.25 | N7: =($N$4*I7)-(($N$4*I7)*(SUM($G$6:$G$10)))-$N$4 -> -4882.8125 | O7: =($O$4*I7)-(($O$4*I7)*(SUM($G$6:$G$10)))-$O$4 -> -6103.5156 | P7: =($P$4*I7)-(($P$4*I7)*(SUM($G$6:$G$10)))-$P$4 -> -7629.3945 | Q7: =($Q$4*I7)-(($Q$4*I7)*(SUM($G$6:$G$10)))-$Q$4 -> -9536.7432 | R7: =($R$4*I7)-(($R$4*I7)*(SUM($G$6:$G$10)))-$R$4 -> -11920.929 | S7: =($S$4*I7)-(($S$4*I7)*(SUM($G$6:$G$10)))-$S$4 -> -14901.161
B8: Taxa Gateway & Checkout (%) | C8: 0.07 | E8: (-) Impostos sob receita | F8: =F5*C9 -> 8 | G8: =F8/$F$5 -> 0.08 | I8: 2.5 | J8: =($J$4*I8)-(($J$4*I8)*(SUM($G$6:$G$10)))-$J$4 -> -1250 | K8: =($K$4*I8)-(($K$4*I8)*(SUM($G$6:$G$10)))-$K$4 -> -1562.5 | L8: =($L$4*I8)-(($L$4*I8)*(SUM($G$6:$G$10)))-$L$4 -> -1953.125 | M8: =($M$4*I8)-(($M$4*I8)*(SUM($G$6:$G$10)))-$M$4 -> -2441.4062 | N8: =($N$4*I8)-(($N$4*I8)*(SUM($G$6:$G$10)))-$N$4 -> -3051.7578 | O8: =($O$4*I8)-(($O$4*I8)*(SUM($G$6:$G$10)))-$O$4 -> -3814.6973 | P8: =($P$4*I8)-(($P$4*I8)*(SUM($G$6:$G$10)))-$P$4 -> -4768.3716 | Q8: =($Q$4*I8)-(($Q$4*I8)*(SUM($G$6:$G$10)))-$Q$4 -> -5960.4645 | R8: =($R$4*I8)-(($R$4*I8)*(SUM($G$6:$G$10)))-$R$4 -> -7450.5806 | S8: =($S$4*I8)-(($S$4*I8)*(SUM($G$6:$G$10)))-$S$4 -> -9313.2257
B9: Impostos sob receita (%) | C9: 0.08 | E9: (-) CMV | F9: =(1/C11)*F5 -> 40 | G9: =F9/$F$5 -> 0.4 | I9: 3 | J9: =($J$4*I9)-(($J$4*I9)*(SUM($G$6:$G$10)))-$J$4 -> -500 | K9: =($K$4*I9)-(($K$4*I9)*(SUM($G$6:$G$10)))-$K$4 -> -625 | L9: =($L$4*I9)-(($L$4*I9)*(SUM($G$6:$G$10)))-$L$4 -> -781.25 | M9: =($M$4*I9)-(($M$4*I9)*(SUM($G$6:$G$10)))-$M$4 -> -976.5625 | N9: =($N$4*I9)-(($N$4*I9)*(SUM($G$6:$G$10)))-$N$4 -> -1220.7031 | O9: =($O$4*I9)-(($O$4*I9)*(SUM($G$6:$G$10)))-$O$4 -> -1525.8789 | P9: =($P$4*I9)-(($P$4*I9)*(SUM($G$6:$G$10)))-$P$4 -> -1907.3486 | Q9: =($Q$4*I9)-(($Q$4*I9)*(SUM($G$6:$G$10)))-$Q$4 -> -2384.1858 | R9: =($R$4*I9)-(($R$4*I9)*(SUM($G$6:$G$10)))-$R$4 -> -2980.2322 | S9: =($S$4*I9)-(($S$4*I9)*(SUM($G$6:$G$10)))-$S$4 -> -3725.2903
B10: Valor gasto Frete mensal (R$) | C10: 1500 | E10: (-) Frete | F10: =C10/C6 -> 15 | G10: =F10/$F$5 -> 0.15 | I10: 3.5 | J10: =($J$4*I10)-(($J$4*I10)*(SUM($G$6:$G$10)))-$J$4 -> 250 | K10: =($K$4*I10)-(($K$4*I10)*(SUM($G$6:$G$10)))-$K$4 -> 312.5 | L10: =($L$4*I10)-(($L$4*I10)*(SUM($G$6:$G$10)))-$L$4 -> 390.625 | M10: =($M$4*I10)-(($M$4*I10)*(SUM($G$6:$G$10)))-$M$4 -> 488.28125 | N10: =($N$4*I10)-(($N$4*I10)*(SUM($G$6:$G$10)))-$N$4 -> 610.35156 | O10: =($O$4*I10)-(($O$4*I10)*(SUM($G$6:$G$10)))-$O$4 -> 762.93945 | P10: =($P$4*I10)-(($P$4*I10)*(SUM($G$6:$G$10)))-$P$4 -> 953.67432 | Q10: =($Q$4*I10)-(($Q$4*I10)*(SUM($G$6:$G$10)))-$Q$4 -> 1192.0929 | R10: =($R$4*I10)-(($R$4*I10)*(SUM($G$6:$G$10)))-$R$4 -> 1490.1161 | S10: =($S$4*I10)-(($S$4*I10)*(SUM($G$6:$G$10)))-$S$4 -> 1862.6451
B11: Markup | C11: 2.5 | E11: (=) Margem bruta | F11: =F5-F6-F7-F8-F9-F10 -> 30 | G11: =F11/$F$5 -> 0.3 | I11: 4 | J11: =($J$4*I11)-(($J$4*I11)*(SUM($G$6:$G$10)))-$J$4 -> 1000 | K11: =($K$4*I11)-(($K$4*I11)*(SUM($G$6:$G$10)))-$K$4 -> 1250 | L11: =($L$4*I11)-(($L$4*I11)*(SUM($G$6:$G$10)))-$L$4 -> 1562.5 | M11: =($M$4*I11)-(($M$4*I11)*(SUM($G$6:$G$10)))-$M$4 -> 1953.125 | N11: =($N$4*I11)-(($N$4*I11)*(SUM($G$6:$G$10)))-$N$4 -> 2441.4062 | O11: =($O$4*I11)-(($O$4*I11)*(SUM($G$6:$G$10)))-$O$4 -> 3051.7578 | P11: =($P$4*I11)-(($P$4*I11)*(SUM($G$6:$G$10)))-$P$4 -> 3814.6973 | Q11: =($Q$4*I11)-(($Q$4*I11)*(SUM($G$6:$G$10)))-$Q$4 -> 4768.3716 | R11: =($R$4*I11)-(($R$4*I11)*(SUM($G$6:$G$10)))-$R$4 -> 5960.4645 | S11: =($S$4*I11)-(($S$4*I11)*(SUM($G$6:$G$10)))-$S$4 -> 7450.5806
B12: Budget Anúncios (R$) | C12: 5000 | E12: (-) CPA | F12: =(C12/C6) -> 50 | G12: =F12/F5 -> 0.5 | I12: 4.5 | J12: =($J$4*I12)-(($J$4*I12)*(SUM($G$6:$G$10)))-$J$4 -> 1750 | K12: =($K$4*I12)-(($K$4*I12)*(SUM($G$6:$G$10)))-$K$4 -> 2187.5 | L12: =($L$4*I12)-(($L$4*I12)*(SUM($G$6:$G$10)))-$L$4 -> 2734.375 | M12: =($M$4*I12)-(($M$4*I12)*(SUM($G$6:$G$10)))-$M$4 -> 3417.9688 | N12: =($N$4*I12)-(($N$4*I12)*(SUM($G$6:$G$10)))-$N$4 -> 4272.4609 | O12: =($O$4*I12)-(($O$4*I12)*(SUM($G$6:$G$10)))-$O$4 -> 5340.5762 | P12: =($P$4*I12)-(($P$4*I12)*(SUM($G$6:$G$10)))-$P$4 -> 6675.7202 | Q12: =($Q$4*I12)-(($Q$4*I12)*(SUM($G$6:$G$10)))-$Q$4 -> 8344.6503 | R12: =($R$4*I12)-(($R$4*I12)*(SUM($G$6:$G$10)))-$R$4 -> 10430.813 | S12: =($S$4*I12)-(($S$4*I12)*(SUM($G$6:$G$10)))-$S$4 -> 13038.516
E13: (=) Margem de Contribuição | F13: =F11-F12 -> -20 | G13: =F13/F5 -> -0.2 | I13: 5 | J13: =($J$4*I13)-(($J$4*I13)*(SUM($G$6:$G$10)))-$J$4 -> 2500 | K13: =($K$4*I13)-(($K$4*I13)*(SUM($G$6:$G$10)))-$K$4 -> 3125 | L13: =($L$4*I13)-(($L$4*I13)*(SUM($G$6:$G$10)))-$L$4 -> 3906.25 | M13: =($M$4*I13)-(($M$4*I13)*(SUM($G$6:$G$10)))-$M$4 -> 4882.8125 | N13: =($N$4*I13)-(($N$4*I13)*(SUM($G$6:$G$10)))-$N$4 -> 6103.5156 | O13: =($O$4*I13)-(($O$4*I13)*(SUM($G$6:$G$10)))-$O$4 -> 7629.3945 | P13: =($P$4*I13)-(($P$4*I13)*(SUM($G$6:$G$10)))-$P$4 -> 9536.7432 | Q13: =($Q$4*I13)-(($Q$4*I13)*(SUM($G$6:$G$10)))-$Q$4 -> 11920.929 | R13: =($R$4*I13)-(($R$4*I13)*(SUM($G$6:$G$10)))-$R$4 -> 14901.161 | S13: =($S$4*I13)-(($S$4*I13)*(SUM($G$6:$G$10)))-$S$4 -> 18626.451
I14: 5.5 | J14: =($J$4*I14)-(($J$4*I14)*(SUM($G$6:$G$10)))-$J$4 -> 3250 | K14: =($K$4*I14)-(($K$4*I14)*(SUM($G$6:$G$10)))-$K$4 -> 4062.5 | L14: =($L$4*I14)-(($L$4*I14)*(SUM($G$6:$G$10)))-$L$4 -> 5078.125 | M14: =($M$4*I14)-(($M$4*I14)*(SUM($G$6:$G$10)))-$M$4 -> 6347.6562 | N14: =($N$4*I14)-(($N$4*I14)*(SUM($G$6:$G$10)))-$N$4 -> 7934.5703 | O14: =($O$4*I14)-(($O$4*I14)*(SUM($G$6:$G$10)))-$O$4 -> 9918.2129 | P14: =($P$4*I14)-(($P$4*I14)*(SUM($G$6:$G$10)))-$P$4 -> 12397.766 | Q14: =($Q$4*I14)-(($Q$4*I14)*(SUM($G$6:$G$10)))-$Q$4 -> 15497.208 | R14: =($R$4*I14)-(($R$4*I14)*(SUM($G$6:$G$10)))-$R$4 -> 19371.51 | S14: =($S$4*I14)-(($S$4*I14)*(SUM($G$6:$G$10)))-$S$4 -> 24214.387
B15: Preencer dados (Planejamento) | E15: (=) Margem Contribuição | F15: =F13/F5 -> -0.2 | I15: 6 | J15: =($J$4*I15)-(($J$4*I15)*(SUM($G$6:$G$10)))-$J$4 -> 4000 | K15: =($K$4*I15)-(($K$4*I15)*(SUM($G$6:$G$10)))-$K$4 -> 5000 | L15: =($L$4*I15)-(($L$4*I15)*(SUM($G$6:$G$10)))-$L$4 -> 6250 | M15: =($M$4*I15)-(($M$4*I15)*(SUM($G$6:$G$10)))-$M$4 -> 7812.5 | N15: =($N$4*I15)-(($N$4*I15)*(SUM($G$6:$G$10)))-$N$4 -> 9765.625 | O15: =($O$4*I15)-(($O$4*I15)*(SUM($G$6:$G$10)))-$O$4 -> 12207.031 | P15: =($P$4*I15)-(($P$4*I15)*(SUM($G$6:$G$10)))-$P$4 -> 15258.789 | Q15: =($Q$4*I15)-(($Q$4*I15)*(SUM($G$6:$G$10)))-$Q$4 -> 19073.486 | R15: =($R$4*I15)-(($R$4*I15)*(SUM($G$6:$G$10)))-$R$4 -> 23841.858 | S15: =($S$4*I15)-(($S$4*I15)*(SUM($G$6:$G$10)))-$S$4 -> 29802.322
B16: Preencher | E16: (=) ROAs Realizado | F16: =C5/C12 -> 2 | I16: 6.5 | J16: =($J$4*I16)-(($J$4*I16)*(SUM($G$6:$G$10)))-$J$4 -> 4750 | K16: =($K$4*I16)-(($K$4*I16)*(SUM($G$6:$G$10)))-$K$4 -> 5937.5 | L16: =($L$4*I16)-(($L$4*I16)*(SUM($G$6:$G$10)))-$L$4 -> 7421.875 | M16: =($M$4*I16)-(($M$4*I16)*(SUM($G$6:$G$10)))-$M$4 -> 9277.3438 | N16: =($N$4*I16)-(($N$4*I16)*(SUM($G$6:$G$10)))-$N$4 -> 11596.68 | O16: =($O$4*I16)-(($O$4*I16)*(SUM($G$6:$G$10)))-$O$4 -> 14495.85 | P16: =($P$4*I16)-(($P$4*I16)*(SUM($G$6:$G$10)))-$P$4 -> 18119.812 | Q16: =($Q$4*I16)-(($Q$4*I16)*(SUM($G$6:$G$10)))-$Q$4 -> 22649.765 | R16: =($R$4*I16)-(($R$4*I16)*(SUM($G$6:$G$10)))-$R$4 -> 28312.206 | S16: =($S$4*I16)-(($S$4*I16)*(SUM($G$6:$G$10)))-$S$4 -> 35390.258
B17: Receita Mensal (R$) | E17: (=) Lucro Bruto | F17: =C5*F15 -> -2000 | I17: 7 | J17: =($J$4*I17)-(($J$4*I17)*(SUM($G$6:$G$10)))-$J$4 -> 5500 | K17: =($K$4*I17)-(($K$4*I17)*(SUM($G$6:$G$10)))-$K$4 -> 6875 | L17: =($L$4*I17)-(($L$4*I17)*(SUM($G$6:$G$10)))-$L$4 -> 8593.75 | M17: =($M$4*I17)-(($M$4*I17)*(SUM($G$6:$G$10)))-$M$4 -> 10742.188 | N17: =($N$4*I17)-(($N$4*I17)*(SUM($G$6:$G$10)))-$N$4 -> 13427.734 | O17: =($O$4*I17)-(($O$4*I17)*(SUM($G$6:$G$10)))-$O$4 -> 16784.668 | P17: =($P$4*I17)-(($P$4*I17)*(SUM($G$6:$G$10)))-$P$4 -> 20980.835 | Q17: =($Q$4*I17)-(($Q$4*I17)*(SUM($G$6:$G$10)))-$Q$4 -> 26226.044 | R17: =($R$4*I17)-(($R$4*I17)*(SUM($G$6:$G$10)))-$R$4 -> 32782.555 | S17: =($S$4*I17)-(($S$4*I17)*(SUM($G$6:$G$10)))-$S$4 -> 40978.193
B18: Número de pedidos | E18: Breakeven Roas | F18: =1/G11 -> 3.3333333 | I18: 7.5 | J18: =($J$4*I18)-(($J$4*I18)*(SUM($G$6:$G$10)))-$J$4 -> 6250 | K18: =($K$4*I18)-(($K$4*I18)*(SUM($G$6:$G$10)))-$K$4 -> 7812.5 | L18: =($L$4*I18)-(($L$4*I18)*(SUM($G$6:$G$10)))-$L$4 -> 9765.625 | M18: =($M$4*I18)-(($M$4*I18)*(SUM($G$6:$G$10)))-$M$4 -> 12207.031 | N18: =($N$4*I18)-(($N$4*I18)*(SUM($G$6:$G$10)))-$N$4 -> 15258.789 | O18: =($O$4*I18)-(($O$4*I18)*(SUM($G$6:$G$10)))-$O$4 -> 19073.486 | P18: =($P$4*I18)-(($P$4*I18)*(SUM($G$6:$G$10)))-$P$4 -> 23841.858 | Q18: =($Q$4*I18)-(($Q$4*I18)*(SUM($G$6:$G$10)))-$Q$4 -> 29802.322 | R18: =($R$4*I18)-(($R$4*I18)*(SUM($G$6:$G$10)))-$R$4 -> 37252.903 | S18: =($S$4*I18)-(($S$4*I18)*(SUM($G$6:$G$10)))-$S$4 -> 46566.129
B19: Número de devoluções | I19: 8 | J19: =($J$4*I19)-(($J$4*I19)*(SUM($G$6:$G$10)))-$J$4 -> 7000 | K19: =($K$4*I19)-(($K$4*I19)*(SUM($G$6:$G$10)))-$K$4 -> 8750 | L19: =($L$4*I19)-(($L$4*I19)*(SUM($G$6:$G$10)))-$L$4 -> 10937.5 | M19: =($M$4*I19)-(($M$4*I19)*(SUM($G$6:$G$10)))-$M$4 -> 13671.875 | N19: =($N$4*I19)-(($N$4*I19)*(SUM($G$6:$G$10)))-$N$4 -> 17089.844 | O19: =($O$4*I19)-(($O$4*I19)*(SUM($G$6:$G$10)))-$O$4 -> 21362.305 | P19: =($P$4*I19)-(($P$4*I19)*(SUM($G$6:$G$10)))-$P$4 -> 26702.881 | Q19: =($Q$4*I19)-(($Q$4*I19)*(SUM($G$6:$G$10)))-$Q$4 -> 33378.601 | R19: =($R$4*I19)-(($R$4*I19)*(SUM($G$6:$G$10)))-$R$4 -> 41723.251 | S19: =($S$4*I19)-(($S$4*I19)*(SUM($G$6:$G$10)))-$S$4 -> 52154.064
B20: Taxa Gateway & Checkout (%) | E20: ROAS | F20: Margem Contrib. | I20: 8.5 | J20: =($J$4*I20)-(($J$4*I20)*(SUM($G$6:$G$10)))-$J$4 -> 7750 | K20: =($K$4*I20)-(($K$4*I20)*(SUM($G$6:$G$10)))-$K$4 -> 9687.5 | L20: =($L$4*I20)-(($L$4*I20)*(SUM($G$6:$G$10)))-$L$4 -> 12109.375 | M20: =($M$4*I20)-(($M$4*I20)*(SUM($G$6:$G$10)))-$M$4 -> 15136.719 | N20: =($N$4*I20)-(($N$4*I20)*(SUM($G$6:$G$10)))-$N$4 -> 18920.898 | O20: =($O$4*I20)-(($O$4*I20)*(SUM($G$6:$G$10)))-$O$4 -> 23651.123 | P20: =($P$4*I20)-(($P$4*I20)*(SUM($G$6:$G$10)))-$P$4 -> 29563.904 | Q20: =($Q$4*I20)-(($Q$4*I20)*(SUM($G$6:$G$10)))-$Q$4 -> 36954.88 | R20: =($R$4*I20)-(($R$4*I20)*(SUM($G$6:$G$10)))-$R$4 -> 46193.6 | S20: =($S$4*I20)-(($S$4*I20)*(SUM($G$6:$G$10)))-$S$4 -> 57742
B21: Impostos sob receita (%) | E21: 1 | F21: =($F$5-$F$6-$F$7-$F$8-$F$9-$F$10-($F$5/E21))/$F$5 -> -0.7 | I21: 9 | J21: =($J$4*I21)-(($J$4*I21)*(SUM($G$6:$G$10)))-$J$4 -> 8500 | K21: =($K$4*I21)-(($K$4*I21)*(SUM($G$6:$G$10)))-$K$4 -> 10625 | L21: =($L$4*I21)-(($L$4*I21)*(SUM($G$6:$G$10)))-$L$4 -> 13281.25 | M21: =($M$4*I21)-(($M$4*I21)*(SUM($G$6:$G$10)))-$M$4 -> 16601.562 | N21: =($N$4*I21)-(($N$4*I21)*(SUM($G$6:$G$10)))-$N$4 -> 20751.953 | O21: =($O$4*I21)-(($O$4*I21)*(SUM($G$6:$G$10)))-$O$4 -> 25939.941 | P21: =($P$4*I21)-(($P$4*I21)*(SUM($G$6:$G$10)))-$P$4 -> 32424.927 | Q21: =($Q$4*I21)-(($Q$4*I21)*(SUM($G$6:$G$10)))-$Q$4 -> 40531.158 | R21: =($R$4*I21)-(($R$4*I21)*(SUM($G$6:$G$10)))-$R$4 -> 50663.948 | S21: =($S$4*I21)-(($S$4*I21)*(SUM($G$6:$G$10)))-$S$4 -> 63329.935
B22: Valor gasto Frete mensal (R$) | E22: 2 | F22: =($F$5-$F$6-$F$7-$F$8-$F$9-$F$10-($F$5/E22))/$F$5 -> -0.2 | I22: 9.5 | J22: =($J$4*I22)-(($J$4*I22)*(SUM($G$6:$G$10)))-$J$4 -> 9250 | K22: =($K$4*I22)-(($K$4*I22)*(SUM($G$6:$G$10)))-$K$4 -> 11562.5 | L22: =($L$4*I22)-(($L$4*I22)*(SUM($G$6:$G$10)))-$L$4 -> 14453.125 | M22: =($M$4*I22)-(($M$4*I22)*(SUM($G$6:$G$10)))-$M$4 -> 18066.406 | N22: =($N$4*I22)-(($N$4*I22)*(SUM($G$6:$G$10)))-$N$4 -> 22583.008 | O22: =($O$4*I22)-(($O$4*I22)*(SUM($G$6:$G$10)))-$O$4 -> 28228.76 | P22: =($P$4*I22)-(($P$4*I22)*(SUM($G$6:$G$10)))-$P$4 -> 35285.95 | Q22: =($Q$4*I22)-(($Q$4*I22)*(SUM($G$6:$G$10)))-$Q$4 -> 44107.437 | R22: =($R$4*I22)-(($R$4*I22)*(SUM($G$6:$G$10)))-$R$4 -> 55134.296 | S22: =($S$4*I22)-(($S$4*I22)*(SUM($G$6:$G$10)))-$S$4 -> 68917.871
B23: Markup | E23: 3 | F23: =($F$5-$F$6-$F$7-$F$8-$F$9-$F$10-($F$5/E23))/$F$5 -> -0.033333333 | I23: 10 | J23: =($J$4*I23)-(($J$4*I23)*(SUM($G$6:$G$10)))-$J$4 -> 10000 | K23: =($K$4*I23)-(($K$4*I23)*(SUM($G$6:$G$10)))-$K$4 -> 12500 | L23: =($L$4*I23)-(($L$4*I23)*(SUM($G$6:$G$10)))-$L$4 -> 15625 | M23: =($M$4*I23)-(($M$4*I23)*(SUM($G$6:$G$10)))-$M$4 -> 19531.25 | N23: =($N$4*I23)-(($N$4*I23)*(SUM($G$6:$G$10)))-$N$4 -> 24414.062 | O23: =($O$4*I23)-(($O$4*I23)*(SUM($G$6:$G$10)))-$O$4 -> 30517.578 | P23: =($P$4*I23)-(($P$4*I23)*(SUM($G$6:$G$10)))-$P$4 -> 38146.973 | Q23: =($Q$4*I23)-(($Q$4*I23)*(SUM($G$6:$G$10)))-$Q$4 -> 47683.716 | R23: =($R$4*I23)-(($R$4*I23)*(SUM($G$6:$G$10)))-$R$4 -> 59604.645 | S23: =($S$4*I23)-(($S$4*I23)*(SUM($G$6:$G$10)))-$S$4 -> 74505.806
B24: Budget Anúncios (R$) | E24: 4 | F24: =($F$5-$F$6-$F$7-$F$8-$F$9-$F$10-($F$5/E24))/$F$5 -> 0.05 | I24: 10.5 | J24: =($J$4*I24)-(($J$4*I24)*(SUM($G$6:$G$10)))-$J$4 -> 10750 | K24: =($K$4*I24)-(($K$4*I24)*(SUM($G$6:$G$10)))-$K$4 -> 13437.5 | L24: =($L$4*I24)-(($L$4*I24)*(SUM($G$6:$G$10)))-$L$4 -> 16796.875 | M24: =($M$4*I24)-(($M$4*I24)*(SUM($G$6:$G$10)))-$M$4 -> 20996.094 | N24: =($N$4*I24)-(($N$4*I24)*(SUM($G$6:$G$10)))-$N$4 -> 26245.117 | O24: =($O$4*I24)-(($O$4*I24)*(SUM($G$6:$G$10)))-$O$4 -> 32806.396 | P24: =($P$4*I24)-(($P$4*I24)*(SUM($G$6:$G$10)))-$P$4 -> 41007.996 | Q24: =($Q$4*I24)-(($Q$4*I24)*(SUM($G$6:$G$10)))-$Q$4 -> 51259.995 | R24: =($R$4*I24)-(($R$4*I24)*(SUM($G$6:$G$10)))-$R$4 -> 64074.993 | S24: =($S$4*I24)-(($S$4*I24)*(SUM($G$6:$G$10)))-$S$4 -> 80093.741
