Workbook
Name zsupermetrics_forceRefresh: #REF!
Name zsupermetrics_refreshAllSilent: #REF!
Name zsupermetrics_refreshAll: #REF!

Sheet Acompanhamento Geral
A1: DATA | B1: DIA | C1: AÇÃO DO DIA | D1: VALOR INVESTIDO | E1: LEADS | F1: CPL | G1: LEADS QUALIFICADOS | H1: VENDAS | I1: VALOR DE VENDA | J1: SESSÕES | K1: CPS | L1: TAXA DE CONVERSÃO P/ LEAD | M1: META INVESTIMENTO | N1: META LEADS | O1: CPL META | P1: CPS META | Q1: META SESSÕES | R1: META TAXA DE CONVERSÃO P/LEAD
A2: JANEIRO | B2: 31 | D2: =IFERROR(SUM(D3:D33),"") -> 2003.14 | E2: =iferror(SUM(E3:E33),"") -> 382 | F2: =IFERROR(D2/E2,"") -> 5.243822 | G2: =iferror(SUM(G3:G33),"") -> 0 | H2: =iferror(SUM(H3:H33),"") -> 0 | I2: =iferror(SUM(I3:I33),"") -> 0 | J2: =IFERROR(SUM(J3:J33),"") -> 0 | K2: =iferror(D2/J2,"") | L2: =iferror(E2/J2,"") | M2: =iferror(Planejador!$I$4,"") | N2: =iferror(Planejador!$I$11,"") | O2: =iferror(Planejador!$I$13,"") | P2: =iferror(Planejador!$I$5,"") | Q2: =iferror(Planejador!$I$10,"") | R2: =Iferror(Planejador!$I$7,"")
A3: 46023 | B3: quinta-feira | D3: =SUMIF('ADV - GG'!A:A,A3,'ADV - GG'!C:C)+SUMIF('ADV - FB'!A:A,$A3,'ADV - FB'!E:E) -> 82.16 | E3: =SUMIF('ADV - GG'!A:A,A3,'ADV - GG'!H:H)+SUMIF('ADV - FB'!A:A,$A3,'ADV - FB'!I:I)+SUMIF('ADV - FB'!A:A,$A3,'ADV - FB'!J:J)+SUMIF('ADV - FB'!A:A,$A3,'ADV - FB'!K:K) -> 14 | F3: =IFERROR(D3/E3,"") -> 5.8685714 | J3: =SUMIF('ADV - GA4'!A:A,A3,'ADV - GA4'!C:C) -> 0 | K3: =IFERROR(D3/J3,"") | L3: =iferror(E3/J3,"") | M3: =iferror($M$2/$B$2,"") -> 0 | N3: =iferror($N$2/$B$2,"") -> 0 | O3: =iferror(Planejador!$I$13,"") | P3: =Planejador!$I$5 | Q3: =iferror($Q$2/$B$2,"") -> 0 | R3: =Planejador!$I$7
A4: 46024 | B4: sexta-feira | D4: =SUMIF('ADV - GG'!A:A,A4,'ADV - GG'!C:C)+SUMIF('ADV - FB'!A:A,$A4,'ADV - FB'!E:E) -> 83.78 | E4: =SUMIF('ADV - GG'!A:A,A4,'ADV - GG'!H:H)+SUMIF('ADV - FB'!A:A,$A4,'ADV - FB'!I:I)+SUMIF('ADV - FB'!A:A,$A4,'ADV - FB'!J:J)+SUMIF('ADV - FB'!A:A,$A4,'ADV - FB'!K:K) -> 20 | F4: =IFERROR(D4/E4,"") -> 4.189 | J4: =SUMIF('ADV - GA4'!A:A,A4,'ADV - GA4'!C:C) -> 0 | K4: =IFERROR(D4/J4,"") | L4: =iferror(E4/J4,"") | M4: =iferror($M$2/$B$2,"") -> 0 | N4: =iferror($N$2/$B$2,"") -> 0 | O4: =iferror(Planejador!$I$13,"") | P4: =Planejador!$I$5 | Q4: =iferror($Q$2/$B$2,"") -> 0 | R4: =Planejador!$I$7
A5: 46025 | B5: sábado | D5: =SUMIF('ADV - GG'!A:A,A5,'ADV - GG'!C:C)+SUMIF('ADV - FB'!A:A,$A5,'ADV - FB'!E:E) -> 78.33 | E5: =SUMIF('ADV - GG'!A:A,A5,'ADV - GG'!H:H)+SUMIF('ADV - FB'!A:A,$A5,'ADV - FB'!I:I)+SUMIF('ADV - FB'!A:A,$A5,'ADV - FB'!J:J)+SUMIF('ADV - FB'!A:A,$A5,'ADV - FB'!K:K) -> 20 | F5: =IFERROR(D5/E5,"") -> 3.9165 | J5: =SUMIF('ADV - GA4'!A:A,A5,'ADV - GA4'!C:C) -> 0 | K5: =IFERROR(D5/J5,"") | L5: =iferror(E5/J5,"") | M5: =iferror($M$2/$B$2,"") -> 0 | N5: =iferror($N$2/$B$2,"") -> 0 | O5: =iferror(Planejador!$I$13,"") | P5: =Planejador!$I$5 | Q5: =iferror($Q$2/$B$2,"") -> 0 | R5: =Planejador!$I$7
A6: 46026 | B6: domingo | D6: =SUMIF('ADV - GG'!A:A,A6,'ADV - GG'!C:C)+SUMIF('ADV - FB'!A:A,$A6,'ADV - FB'!E:E) -> 85.09 | E6: =SUMIF('ADV - GG'!A:A,A6,'ADV - GG'!H:H)+SUMIF('ADV - FB'!A:A,$A6,'ADV - FB'!I:I)+SUMIF('ADV - FB'!A:A,$A6,'ADV - FB'!J:J)+SUMIF('ADV - FB'!A:A,$A6,'ADV - FB'!K:K) -> 19 | F6: =IFERROR(D6/E6,"") -> 4.4784211 | J6: =SUMIF('ADV - GA4'!A:A,A6,'ADV - GA4'!C:C) -> 0 | K6: =IFERROR(D6/J6,"") | L6: =iferror(E6/J6,"") | M6: =iferror($M$2/$B$2,"") -> 0 | N6: =iferror($N$2/$B$2,"") -> 0 | O6: =iferror(Planejador!$I$13,"") | P6: =Planejador!$I$5 | Q6: =iferror($Q$2/$B$2,"") -> 0 | R6: =Planejador!$I$7
A7: 46027 | B7: segunda-feira | D7: =SUMIF('ADV - GG'!A:A,A7,'ADV - GG'!C:C)+SUMIF('ADV - FB'!A:A,$A7,'ADV - FB'!E:E) -> 76.3 | E7: =SUMIF('ADV - GG'!A:A,A7,'ADV - GG'!H:H)+SUMIF('ADV - FB'!A:A,$A7,'ADV - FB'!I:I)+SUMIF('ADV - FB'!A:A,$A7,'ADV - FB'!J:J)+SUMIF('ADV - FB'!A:A,$A7,'ADV - FB'!K:K) -> 11 | F7: =IFERROR(D7/E7,"") -> 6.9363636 | J7: =SUMIF('ADV - GA4'!A:A,A7,'ADV - GA4'!C:C) -> 0 | K7: =IFERROR(D7/J7,"") | L7: =iferror(E7/J7,"") | M7: =iferror($M$2/$B$2,"") -> 0 | N7: =iferror($N$2/$B$2,"") -> 0 | O7: =iferror(Planejador!$I$13,"") | P7: =Planejador!$I$5 | Q7: =iferror($Q$2/$B$2,"") -> 0 | R7: =Planejador!$I$7
A8: 46028 | B8: terça-feira | D8: =SUMIF('ADV - GG'!A:A,A8,'ADV - GG'!C:C)+SUMIF('ADV - FB'!A:A,$A8,'ADV - FB'!E:E) -> 81.59 | E8: =SUMIF('ADV - GG'!A:A,A8,'ADV - GG'!H:H)+SUMIF('ADV - FB'!A:A,$A8,'ADV - FB'!I:I)+SUMIF('ADV - FB'!A:A,$A8,'ADV - FB'!J:J)+SUMIF('ADV - FB'!A:A,$A8,'ADV - FB'!K:K) -> 19 | F8: =IFERROR(D8/E8,"") -> 4.2942105 | J8: =SUMIF('ADV - GA4'!A:A,A8,'ADV - GA4'!C:C) -> 0 | K8: =IFERROR(D8/J8,"") | L8: =iferror(E8/J8,"") | M8: =iferror($M$2/$B$2,"") -> 0 | N8: =iferror($N$2/$B$2,"") -> 0 | O8: =iferror(Planejador!$I$13,"") | P8: =Planejador!$I$5 | Q8: =iferror($Q$2/$B$2,"") -> 0 | R8: =Planejador!$I$7
A9: 46029 | B9: quarta-feira | D9: =SUMIF('ADV - GG'!A:A,A9,'ADV - GG'!C:C)+SUMIF('ADV - FB'!A:A,$A9,'ADV - FB'!E:E) -> 79.41 | E9: =SUMIF('ADV - GG'!A:A,A9,'ADV - GG'!H:H)+SUMIF('ADV - FB'!A:A,$A9,'ADV - FB'!I:I)+SUMIF('ADV - FB'!A:A,$A9,'ADV - FB'!J:J)+SUMIF('ADV - FB'!A:A,$A9,'ADV - FB'!K:K) -> 13 | F9: =IFERROR(D9/E9,"") -> 6.1084615 | J9: =SUMIF('ADV - GA4'!A:A,A9,'ADV - GA4'!C:C) -> 0 | K9: =IFERROR(D9/J9,"") | L9: =iferror(E9/J9,"") | M9: =iferror($M$2/$B$2,"") -> 0 | N9: =iferror($N$2/$B$2,"") -> 0 | O9: =iferror(Planejador!$I$13,"") | P9: =Planejador!$I$5 | Q9: =iferror($Q$2/$B$2,"") -> 0 | R9: =Planejador!$I$7
A10: 46030 | B10: quinta-feira | D10: =SUMIF('ADV - GG'!A:A,A10,'ADV - GG'!C:C)+SUMIF('ADV - FB'!A:A,$A10,'ADV - FB'!E:E) -> 83.06 | E10: =SUMIF('ADV - GG'!A:A,A10,'ADV - GG'!H:H)+SUMIF('ADV - FB'!A:A,$A10,'ADV - FB'!I:I)+SUMIF('ADV - FB'!A:A,$A10,'ADV - FB'!J:J)+SUMIF('ADV - FB'!A:A,$A10,'ADV - FB'!K:K) -> 8 | F10: =IFERROR(D10/E10,"") -> 10.3825 | J10: =SUMIF('ADV - GA4'!A:A,A10,'ADV - GA4'!C:C) -> 0 | K10: =IFERROR(D10/J10,"") | L10: =iferror(E10/J10,"") | M10: =iferror($M$2/$B$2,"") -> 0 | N10: =iferror($N$2/$B$2,"") -> 0 | O10: =iferror(Planejador!$I$13,"") | P10: =Planejador!$I$5 | Q10: =iferror($Q$2/$B$2,"") -> 0 | R10: =Planejador!$I$7
A11: 46031 | B11: sexta-feira | D11: =SUMIF('ADV - GG'!A:A,A11,'ADV - GG'!C:C)+SUMIF('ADV - FB'!A:A,$A11,'ADV - FB'!E:E) -> 77.34 | E11: =SUMIF('ADV - GG'!A:A,A11,'ADV - GG'!H:H)+SUMIF('ADV - FB'!A:A,$A11,'ADV - FB'!I:I)+SUMIF('ADV - FB'!A:A,$A11,'ADV - FB'!J:J)+SUMIF('ADV - FB'!A:A,$A11,'ADV - FB'!K:K) -> 14 | F11: =IFERROR(D11/E11,"") -> 5.5242857 | J11: =SUMIF('ADV - GA4'!A:A,A11,'ADV - GA4'!C:C) -> 0 | K11: =IFERROR(D11/J11,"") | L11: =iferror(E11/J11,"") | M11: =iferror($M$2/$B$2,"") -> 0 | N11: =iferror($N$2/$B$2,"") -> 0 | O11: =iferror(Planejador!$I$13,"") | P11: =Planejador!$I$5 | Q11: =iferror($Q$2/$B$2,"") -> 0 | R11: =Planejador!$I$7
A12: 46032 | B12: sábado | D12: =SUMIF('ADV - GG'!A:A,A12,'ADV - GG'!C:C)+SUMIF('ADV - FB'!A:A,$A12,'ADV - FB'!E:E) -> 75.27 | E12: =SUMIF('ADV - GG'!A:A,A12,'ADV - GG'!H:H)+SUMIF('ADV - FB'!A:A,$A12,'ADV - FB'!I:I)+SUMIF('ADV - FB'!A:A,$A12,'ADV - FB'!J:J)+SUMIF('ADV - FB'!A:A,$A12,'ADV - FB'!K:K) -> 11 | F12: =IFERROR(D12/E12,"") -> 6.8427273 | J12: =SUMIF('ADV - GA4'!A:A,A12,'ADV - GA4'!C:C) -> 0 | K12: =IFERROR(D12/J12,"") | L12: =iferror(E12/J12,"") | M12: =iferror($M$2/$B$2,"") -> 0 | N12: =iferror($N$2/$B$2,"") -> 0 | O12: =iferror(Planejador!$I$13,"") | P12: =Planejador!$I$5 | Q12: =iferror($Q$2/$B$2,"") -> 0 | R12: =Planejador!$I$7
A13: 46033 | B13: domingo | D13: =SUMIF('ADV - GG'!A:A,A13,'ADV - GG'!C:C)+SUMIF('ADV - FB'!A:A,$A13,'ADV - FB'!E:E) -> 78.85 | E13: =SUMIF('ADV - GG'!A:A,A13,'ADV - GG'!H:H)+SUMIF('ADV - FB'!A:A,$A13,'ADV - FB'!I:I)+SUMIF('ADV - FB'!A:A,$A13,'ADV - FB'!J:J)+SUMIF('ADV - FB'!A:A,$A13,'ADV - FB'!K:K) -> 19 | F13: =IFERROR(D13/E13,"") -> 4.15 | J13: =SUMIF('ADV - GA4'!A:A,A13,'ADV - GA4'!C:C) -> 0 | K13: =IFERROR(D13/J13,"") | L13: =iferror(E13/J13,"") | M13: =iferror($M$2/$B$2,"") -> 0 | N13: =iferror($N$2/$B$2,"") -> 0 | O13: =iferror(Planejador!$I$13,"") | P13: =Planejador!$I$5 | Q13: =iferror($Q$2/$B$2,"") -> 0 | R13: =Planejador!$I$7
A14: 46034 | B14: segunda-feira | D14: =SUMIF('ADV - GG'!A:A,A14,'ADV - GG'!C:C)+SUMIF('ADV - FB'!A:A,$A14,'ADV - FB'!E:E) -> 72.4 | E14: =SUMIF('ADV - GG'!A:A,A14,'ADV - GG'!H:H)+SUMIF('ADV - FB'!A:A,$A14,'ADV - FB'!I:I)+SUMIF('ADV - FB'!A:A,$A14,'ADV - FB'!J:J)+SUMIF('ADV - FB'!A:A,$A14,'ADV - FB'!K:K) -> 9 | F14: =IFERROR(D14/E14,"") -> 8.0444444 | J14: =SUMIF('ADV - GA4'!A:A,A14,'ADV - GA4'!C:C) -> 0 | K14: =IFERROR(D14/J14,"") | L14: =iferror(E14/J14,"") | M14: =iferror($M$2/$B$2,"") -> 0 | N14: =iferror($N$2/$B$2,"") -> 0 | O14: =iferror(Planejador!$I$13,"") | P14: =Planejador!$I$5 | Q14: =iferror($Q$2/$B$2,"") -> 0 | R14: =Planejador!$I$7
... A33: 46053 | B33: sábado | D33: =SUMIF('ADV - GG'!A:A,A33,'ADV - GG'!C:C)+SUMIF('ADV - FB'!A:A,$A33,'ADV - FB'!E:E) -> 53.55 | E33: =SUMIF('ADV - GG'!A:A,A33,'ADV - GG'!H:H)+SUMIF('ADV - FB'!A:A,$A33,'ADV - FB'!I:I)+SUMIF('ADV - FB'!A:A,$A33,'ADV - FB'!J:J)+SUMIF('ADV - FB'!A:A,$A33,'ADV - FB'!K:K) -> 3 | F33: =IFERROR(D33/E33,"") -> 17.85 | J33: =SUMIF('ADV - GA4'!A:A,A33,'ADV - GA4'!C:C) -> 0 | K33: =IFERROR(D33/J33,"") | L33: =iferror(E33/J33,"") | M33: =iferror($M$2/$B$2,"") -> 0 | N33: =iferror($N$2/$B$2,"") -> 0 | O33: =iferror(Planejador!$I$13,"") | P33: =Planejador!$I$5 | Q33: =iferror($Q$2/$B$2,"") -> 0 | R33: =Planejador!$I$7
A34: FEVEREIRO | B34: =COUNTA(A35:A62) -> 28 | D34: =IFERROR(SUM(D35:D62),"") -> 1840.12 | E34: =iferror(SUM(E35:E62),"") -> 250 | F34: =IFERROR(D34/E34,"") -> 7.36048 | G34: =iferror(SUM(G35:G62),"") -> 0 | H34: =iferror(SUM(H35:H62),"") -> 0 | I34: =iferror(SUM(I35:I62),"") -> 0 | J34: =IFERROR(SUM(J35:J62),"") -> 0 | K34: =iferror(D34/J34,"") | L34: =iferror(E34/J34,"") | M34: =iferror(Planejador!$I$27,"") | N34: =iferror(Planejador!$I$34,"") | O34: =iferror(Planejador!$I$36,"") | P34: =iferror(Planejador!$I$28,"") | Q34: =iferror(Planejador!$I$33,"") | R34: =Iferror(Planejador!$I$30,"")
A35: 46054 | B35: =TEXT(A35,"dddd") -> domingo | D35: =SUMIF('ADV - GG'!A:A,A35,'ADV - GG'!C:C)+SUMIF('ADV - FB'!A:A,$A35,'ADV - FB'!E:E) -> 60.4 | E35: =SUMIF('ADV - GG'!A:A,A35,'ADV - GG'!H:H)+SUMIF('ADV - FB'!A:A,$A35,'ADV - FB'!I:I)+SUMIF('ADV - FB'!A:A,$A35,'ADV - FB'!J:J)+SUMIF('ADV - FB'!A:A,$A35,'ADV - FB'!K:K) -> 6 | F35: =IFERROR(D35/E35,"") -> 10.066667 | J35: =SUMIF('ADV - GA4'!A:A,A35,'ADV - GA4'!C:C) -> 0 | K35: =IFERROR(D35/J35,"") | L35: =iferror(E35/J35,"") | M35: =$M$34/$B$34 -> 0 | N35: =iferror($N$34/$B$34,"") -> 0 | O35: =iferror(Planejador!$I$36,"") | P35: =Planejador!$I$28 | Q35: =iferror($Q$34/$B$34,"") -> 0 | R35: =Planejador!$I$30
A36: 46055 | B36: =TEXT(A36,"dddd") -> segunda-feira | D36: =SUMIF('ADV - GG'!A:A,A36,'ADV - GG'!C:C)+SUMIF('ADV - FB'!A:A,$A36,'ADV - FB'!E:E) -> 58.38 | E36: =SUMIF('ADV - GG'!A:A,A36,'ADV - GG'!H:H)+SUMIF('ADV - FB'!A:A,$A36,'ADV - FB'!I:I)+SUMIF('ADV - FB'!A:A,$A36,'ADV - FB'!J:J)+SUMIF('ADV - FB'!A:A,$A36,'ADV - FB'!K:K) -> 9 | F36: =IFERROR(D36/E36,"") -> 6.4866667 | J36: =SUMIF('ADV - GA4'!A:A,A36,'ADV - GA4'!C:C) -> 0 | K36: =IFERROR(D36/J36,"") | L36: =iferror(E36/J36,"") | M36: =$M$34/$B$34 -> 0 | N36: =iferror($N$34/$B$34,"") -> 0 | O36: =iferror(Planejador!$I$36,"") | P36: =Planejador!$I$28 | Q36: =iferror($Q$34/$B$34,"") -> 0 | R36: =Planejador!$I$30
A37: 46056 | B37: =TEXT(A37,"dddd") -> terça-feira | D37: =SUMIF('ADV - GG'!A:A,A37,'ADV - GG'!C:C)+SUMIF('ADV - FB'!A:A,$A37,'ADV - FB'!E:E) -> 59.4 | E37: =SUMIF('ADV - GG'!A:A,A37,'ADV - GG'!H:H)+SUMIF('ADV - FB'!A:A,$A37,'ADV - FB'!I:I)+SUMIF('ADV - FB'!A:A,$A37,'ADV - FB'!J:J)+SUMIF('ADV - FB'!A:A,$A37,'ADV - FB'!K:K) -> 13 | F37: =IFERROR(D37/E37,"") -> 4.5692308 | J37: =SUMIF('ADV - GA4'!A:A,A37,'ADV - GA4'!C:C) -> 0 | K37: =IFERROR(D37/J37,"") | L37: =iferror(E37/J37,"") | M37: =$M$34/$B$34 -> 0 | N37: =iferror($N$34/$B$34,"") -> 0 | O37: =iferror(Planejador!$I$36,"") | P37: =Planejador!$I$28 | Q37: =iferror($Q$34/$B$34,"") -> 0 | R37: =Planejador!$I$30
A38: 46057 | B38: =TEXT(A38,"dddd") -> quarta-feira | D38: =SUMIF('ADV - GG'!A:A,A38,'ADV - GG'!C:C)+SUMIF('ADV - FB'!A:A,$A38,'ADV - FB'!E:E) -> 50.03 | E38: =SUMIF('ADV - GG'!A:A,A38,'ADV - GG'!H:H)+SUMIF('ADV - FB'!A:A,$A38,'ADV - FB'!I:I)+SUMIF('ADV - FB'!A:A,$A38,'ADV - FB'!J:J)+SUMIF('ADV - FB'!A:A,$A38,'ADV - FB'!K:K) -> 6 | F38: =IFERROR(D38/E38,"") -> 8.3383333 | J38: =SUMIF('ADV - GA4'!A:A,A38,'ADV - GA4'!C:C) -> 0 | K38: =IFERROR(D38/J38,"") | L38: =iferror(E38/J38,"") | M38: =$M$34/$B$34 -> 0 | N38: =iferror($N$34/$B$34,"") -> 0 | O38: =iferror(Planejador!$I$36,"") | P38: =Planejador!$I$28 | Q38: =iferror($Q$34/$B$34,"") -> 0 | R38: =Planejador!$I$30
A39: 46058 | B39: =TEXT(A39,"dddd") -> quinta-feira | D39: =SUMIF('ADV - GG'!A:A,A39,'ADV - GG'!C:C)+SUMIF('ADV - FB'!A:A,$A39,'ADV - FB'!E:E) -> 49.87 | E39: =SUMIF('ADV - GG'!A:A,A39,'ADV - GG'!H:H)+SUMIF('ADV - FB'!A:A,$A39,'ADV - FB'!I:I)+SUMIF('ADV - FB'!A:A,$A39,'ADV - FB'!J:J)+SUMIF('ADV - FB'!A:A,$A39,'ADV - FB'!K:K) -> 6 | F39: =IFERROR(D39/E39,"") -> 8.3116667 | J39: =SUMIF('ADV - GA4'!A:A,A39,'ADV - GA4'!C:C) -> 0 | K39: =IFERROR(D39/J39,"") | L39: =iferror(E39/J39,"") | M39: =$M$34/$B$34 -> 0 | N39: =iferror($N$34/$B$34,"") -> 0 | O39: =iferror(Planejador!$I$36,"") | P39: =Planejador!$I$28 | Q39: =iferror($Q$34/$B$34,"") -> 0 | R39: =Planejador!$I$30
A40: 46059 | B40: =TEXT(A40,"dddd") -> sexta-feira | D40: =SUMIF('ADV - GG'!A:A,A40,'ADV - GG'!C:C)+SUMIF('ADV - FB'!A:A,$A40,'ADV - FB'!E:E) -> 48.67 | E40: =SUMIF('ADV - GG'!A:A,A40,'ADV - GG'!H:H)+SUMIF('ADV - FB'!A:A,$A40,'ADV - FB'!I:I)+SUMIF('ADV - FB'!A:A,$A40,'ADV - FB'!J:J)+SUMIF('ADV - FB'!A:A,$A40,'ADV - FB'!K:K) -> 5 | F40: =IFERROR(D40/E40,"") -> 9.734 | J40: =SUMIF('ADV - GA4'!A:A,A40,'ADV - GA4'!C:C) -> 0 | K40: =IFERROR(D40/J40,"") | L40: =iferror(E40/J40,"") | M40: =$M$34/$B$34 -> 0 | N40: =iferror($N$34/$B$34,"") -> 0 | O40: =iferror(Planejador!$I$36,"") | P40: =Planejador!$I$28 | Q40: =iferror($Q$34/$B$34,"") -> 0 | R40: =Planejador!$I$30
A41: 46060 | B41: =TEXT(A41,"dddd") -> sábado | D41: =SUMIF('ADV - GG'!A:A,A41,'ADV - GG'!C:C)+SUMIF('ADV - FB'!A:A,$A41,'ADV - FB'!E:E) -> 49.12 | E41: =SUMIF('ADV - GG'!A:A,A41,'ADV - GG'!H:H)+SUMIF('ADV - FB'!A:A,$A41,'ADV - FB'!I:I)+SUMIF('ADV - FB'!A:A,$A41,'ADV - FB'!J:J)+SUMIF('ADV - FB'!A:A,$A41,'ADV - FB'!K:K) -> 6 | F41: =IFERROR(D41/E41,"") -> 8.1866667 | J41: =SUMIF('ADV - GA4'!A:A,A41,'ADV - GA4'!C:C) -> 0 | K41: =IFERROR(D41/J41,"") | L41: =iferror(E41/J41,"") | M41: =$M$34/$B$34 -> 0 | N41: =iferror($N$34/$B$34,"") -> 0 | O41: =iferror(Planejador!$I$36,"") | P41: =Planejador!$I$28 | Q41: =iferror($Q$34/$B$34,"") -> 0 | R41: =Planejador!$I$30
A42: 46061 | B42: =TEXT(A42,"dddd") -> domingo | D42: =SUMIF('ADV - GG'!A:A,A42,'ADV - GG'!C:C)+SUMIF('ADV - FB'!A:A,$A42,'ADV - FB'!E:E) -> 51.47 | E42: =SUMIF('ADV - GG'!A:A,A42,'ADV - GG'!H:H)+SUMIF('ADV - FB'!A:A,$A42,'ADV - FB'!I:I)+SUMIF('ADV - FB'!A:A,$A42,'ADV - FB'!J:J)+SUMIF('ADV - FB'!A:A,$A42,'ADV - FB'!K:K) -> 7 | F42: =IFERROR(D42/E42,"") -> 7.3528571 | J42: =SUMIF('ADV - GA4'!A:A,A42,'ADV - GA4'!C:C) -> 0 | K42: =IFERROR(D42/J42,"") | L42: =iferror(E42/J42,"") | M42: =$M$34/$B$34 -> 0 | N42: =iferror($N$34/$B$34,"") -> 0 | O42: =iferror(Planejador!$I$36,"") | P42: =Planejador!$I$28 | Q42: =iferror($Q$34/$B$34,"") -> 0 | R42: =Planejador!$I$30
A43: 46062 | B43: =TEXT(A43,"dddd") -> segunda-feira | D43: =SUMIF('ADV - GG'!A:A,A43,'ADV - GG'!C:C)+SUMIF('ADV - FB'!A:A,$A43,'ADV - FB'!E:E) -> 60.67 | E43: =SUMIF('ADV - GG'!A:A,A43,'ADV - GG'!H:H)+SUMIF('ADV - FB'!A:A,$A43,'ADV - FB'!I:I)+SUMIF('ADV - FB'!A:A,$A43,'ADV - FB'!J:J)+SUMIF('ADV - FB'!A:A,$A43,'ADV - FB'!K:K) -> 8 | F43: =IFERROR(D43/E43,"") -> 7.58375 | J43: =SUMIF('ADV - GA4'!A:A,A43,'ADV - GA4'!C:C) -> 0 | K43: =IFERROR(D43/J43,"") | L43: =iferror(E43/J43,"") | M43: =$M$34/$B$34 -> 0 | N43: =iferror($N$34/$B$34,"") -> 0 | O43: =iferror(Planejador!$I$36,"") | P43: =Planejador!$I$28 | Q43: =iferror($Q$34/$B$34,"") -> 0 | R43: =Planejador!$I$30
A44: 46063 | B44: =TEXT(A44,"dddd") -> terça-feira | D44: =SUMIF('ADV - GG'!A:A,A44,'ADV - GG'!C:C)+SUMIF('ADV - FB'!A:A,$A44,'ADV - FB'!E:E) -> 59.41 | E44: =SUMIF('ADV - GG'!A:A,A44,'ADV - GG'!H:H)+SUMIF('ADV - FB'!A:A,$A44,'ADV - FB'!I:I)+SUMIF('ADV - FB'!A:A,$A44,'ADV - FB'!J:J)+SUMIF('ADV - FB'!A:A,$A44,'ADV - FB'!K:K) -> 7 | F44: =IFERROR(D44/E44,"") -> 8.4871429 | J44: =SUMIF('ADV - GA4'!A:A,A44,'ADV - GA4'!C:C) -> 0 | K44: =IFERROR(D44/J44,"") | L44: =iferror(E44/J44,"") | M44: =$M$34/$B$34 -> 0 | N44: =iferror($N$34/$B$34,"") -> 0 | O44: =iferror(Planejador!$I$36,"") | P44: =Planejador!$I$28 | Q44: =iferror($Q$34/$B$34,"") -> 0 | R44: =Planejador!$I$30
A45: 46064 | B45: =TEXT(A45,"dddd") -> quarta-feira | D45: =SUMIF('ADV - GG'!A:A,A45,'ADV - GG'!C:C)+SUMIF('ADV - FB'!A:A,$A45,'ADV - FB'!E:E) -> 56.86 | E45: =SUMIF('ADV - GG'!A:A,A45,'ADV - GG'!H:H)+SUMIF('ADV - FB'!A:A,$A45,'ADV - FB'!I:I)+SUMIF('ADV - FB'!A:A,$A45,'ADV - FB'!J:J)+SUMIF('ADV - FB'!A:A,$A45,'ADV - FB'!K:K) -> 9 | F45: =IFERROR(D45/E45,"") -> 6.3177778 | J45: =SUMIF('ADV - GA4'!A:A,A45,'ADV - GA4'!C:C) -> 0 | K45: =IFERROR(D45/J45,"") | L45: =iferror(E45/J45,"") | M45: =$M$34/$B$34 -> 0 | N45: =iferror($N$34/$B$34,"") -> 0 | O45: =iferror(Planejador!$I$36,"") | P45: =Planejador!$I$28 | Q45: =iferror($Q$34/$B$34,"") -> 0 | R45: =Planejador!$I$30
A46: 46065 | B46: =TEXT(A46,"dddd") -> quinta-feira | D46: =SUMIF('ADV - GG'!A:A,A46,'ADV - GG'!C:C)+SUMIF('ADV - FB'!A:A,$A46,'ADV - FB'!E:E) -> 57.92 | E46: =SUMIF('ADV - GG'!A:A,A46,'ADV - GG'!H:H)+SUMIF('ADV - FB'!A:A,$A46,'ADV - FB'!I:I)+SUMIF('ADV - FB'!A:A,$A46,'ADV - FB'!J:J)+SUMIF('ADV - FB'!A:A,$A46,'ADV - FB'!K:K) -> 7 | F46: =IFERROR(D46/E46,"") -> 8.2742857 | J46: =SUMIF('ADV - GA4'!A:A,A46,'ADV - GA4'!C:C) -> 0 | K46: =IFERROR(D46/J46,"") | L46: =iferror(E46/J46,"") | M46: =$M$34/$B$34 -> 0 | N46: =iferror($N$34/$B$34,"") -> 0 | O46: =iferror(Planejador!$I$36,"") | P46: =Planejador!$I$28 | Q46: =iferror($Q$34/$B$34,"") -> 0 | R46: =Planejador!$I$30
... A62: 46081 | B62: =TEXT(A62,"dddd") -> sábado | D62: =SUMIF('ADV - GG'!A:A,A62,'ADV - GG'!C:C)+SUMIF('ADV - FB'!A:A,$A62,'ADV - FB'!E:E) -> 71.89 | E62: =SUMIF('ADV - GG'!A:A,A62,'ADV - GG'!H:H)+SUMIF('ADV - FB'!A:A,$A62,'ADV - FB'!I:I)+SUMIF('ADV - FB'!A:A,$A62,'ADV - FB'!J:J)+SUMIF('ADV - FB'!A:A,$A62,'ADV - FB'!K:K) -> 10 | F62: =IFERROR(D62/E62,"") -> 7.189 | J62: =SUMIF('ADV - GA4'!A:A,A62,'ADV - GA4'!C:C) -> 0 | K62: =IFERROR(D62/J62,"") | L62: =iferror(E62/J62,"") | M62: =$M$34/$B$34 -> 0 | N62: =iferror($N$34/$B$34,"") -> 0 | O62: =iferror(Planejador!$I$36,"") | P62: =Planejador!$I$28 | Q62: =iferror($Q$34/$B$34,"") -> 0 | R62: =Planejador!$I$30
A63: MARÇO | B63: 31 | D63: =IFERROR(SUM(D64:D94),"") -> 2070.09 | E63: =iferror(SUM(E64:E94),"") -> 214 | F63: =IFERROR(D63/E63,"") -> 9.6733178 | G63: =iferror(SUM(G64:G94),"") -> 0 | H63: =iferror(SUM(H64:H94),"") -> 0 | I63: =iferror(SUM(I64:I94),"") -> 0 | J63: =IFERROR(SUM(J64:J94),"") -> 0 | K63: =iferror(D63/J63,"") | L63: =iferror(E63/J63,"") | M63: =Planejador!$I$50 | N63: =iferror(Planejador!$I$57,"") | O63: =iferror(Planejador!$I$59,"") | P63: =iferror(Planejador!$I$51,"") | Q63: =iferror(Planejador!$I$56,"") | R63: =Iferror(Planejador!$I$53,"")
A64: 46082 | B64: =TEXT(A64,"dddd") -> domingo | D64: =SUMIF('ADV - GG'!A:A,A64,'ADV - GG'!C:C)+SUMIF('ADV - FB'!A:A,$A64,'ADV - FB'!E:E) -> 81.72 | E64: =SUMIF('ADV - GG'!A:A,A64,'ADV - GG'!H:H)+SUMIF('ADV - FB'!A:A,$A64,'ADV - FB'!I:I)+SUMIF('ADV - FB'!A:A,$A64,'ADV - FB'!J:J)+SUMIF('ADV - FB'!A:A,$A64,'ADV - FB'!K:K) -> 16 | F64: =IFERROR(D64/E64,"") -> 5.1075 | J64: =SUMIF('ADV - GA4'!A:A,A64,'ADV - GA4'!C:C) -> 0 | K64: =IFERROR(D64/J64,"") | L64: =iferror(E64/J64,"") | M64: =$M$63/$B$63 -> 0 | N64: =iferror($N$63/$B$63,"") -> 0 | O64: =iferror(Planejador!$I$59,"") | P64: =Planejador!$I$51 | Q64: =$Q$63/$B$63 -> 0 | R64: =Planejador!$I$53
A65: 46083 | B65: =TEXT(A65,"dddd") -> segunda-feira | D65: =SUMIF('ADV - GG'!A:A,A65,'ADV - GG'!C:C)+SUMIF('ADV - FB'!A:A,$A65,'ADV - FB'!E:E) -> 78.19 | E65: =SUMIF('ADV - GG'!A:A,A65,'ADV - GG'!H:H)+SUMIF('ADV - FB'!A:A,$A65,'ADV - FB'!I:I)+SUMIF('ADV - FB'!A:A,$A65,'ADV - FB'!J:J)+SUMIF('ADV - FB'!A:A,$A65,'ADV - FB'!K:K) -> 10 | F65: =IFERROR(D65/E65,"") -> 7.819 | J65: =SUMIF('ADV - GA4'!A:A,A65,'ADV - GA4'!C:C) -> 0 | K65: =IFERROR(D65/J65,"") | L65: =iferror(E65/J65,"") | M65: =$M$63/$B$63 -> 0 | N65: =iferror($N$63/$B$63,"") -> 0 | O65: =iferror(Planejador!$I$59,"") | P65: =Planejador!$I$51 | Q65: =$Q$63/$B$63 -> 0 | R65: =Planejador!$I$53
A66: 46084 | B66: =TEXT(A66,"dddd") -> terça-feira | D66: =SUMIF('ADV - GG'!A:A,A66,'ADV - GG'!C:C)+SUMIF('ADV - FB'!A:A,$A66,'ADV - FB'!E:E) -> 81.84 | E66: =SUMIF('ADV - GG'!A:A,A66,'ADV - GG'!H:H)+SUMIF('ADV - FB'!A:A,$A66,'ADV - FB'!I:I)+SUMIF('ADV - FB'!A:A,$A66,'ADV - FB'!J:J)+SUMIF('ADV - FB'!A:A,$A66,'ADV - FB'!K:K) -> 11 | F66: =IFERROR(D66/E66,"") -> 7.44 | J66: =SUMIF('ADV - GA4'!A:A,A66,'ADV - GA4'!C:C) -> 0 | K66: =IFERROR(D66/J66,"") | L66: =iferror(E66/J66,"") | M66: =$M$63/$B$63 -> 0 | N66: =iferror($N$63/$B$63,"") -> 0 | O66: =iferror(Planejador!$I$59,"") | P66: =Planejador!$I$51 | Q66: =$Q$63/$B$63 -> 0 | R66: =Planejador!$I$53
A67: 46085 | B67: =TEXT(A67,"dddd") -> quarta-feira | D67: =SUMIF('ADV - GG'!A:A,A67,'ADV - GG'!C:C)+SUMIF('ADV - FB'!A:A,$A67,'ADV - FB'!E:E) -> 72.64 | E67: =SUMIF('ADV - GG'!A:A,A67,'ADV - GG'!H:H)+SUMIF('ADV - FB'!A:A,$A67,'ADV - FB'!I:I)+SUMIF('ADV - FB'!A:A,$A67,'ADV - FB'!J:J)+SUMIF('ADV - FB'!A:A,$A67,'ADV - FB'!K:K) -> 5 | F67: =IFERROR(D67/E67,"") -> 14.528 | J67: =SUMIF('ADV - GA4'!A:A,A67,'ADV - GA4'!C:C) -> 0 | K67: =IFERROR(D67/J67,"") | L67: =iferror(E67/J67,"") | M67: =$M$63/$B$63 -> 0 | N67: =iferror($N$63/$B$63,"") -> 0 | O67: =iferror(Planejador!$I$59,"") | P67: =Planejador!$I$51 | Q67: =$Q$63/$B$63 -> 0 | R67: =Planejador!$I$53
A68: 46086 | B68: =TEXT(A68,"dddd") -> quinta-feira | D68: =SUMIF('ADV - GG'!A:A,A68,'ADV - GG'!C:C)+SUMIF('ADV - FB'!A:A,$A68,'ADV - FB'!E:E) -> 64.31 | E68: =SUMIF('ADV - GG'!A:A,A68,'ADV - GG'!H:H)+SUMIF('ADV - FB'!A:A,$A68,'ADV - FB'!I:I)+SUMIF('ADV - FB'!A:A,$A68,'ADV - FB'!J:J)+SUMIF('ADV - FB'!A:A,$A68,'ADV - FB'!K:K) -> 6 | F68: =IFERROR(D68/E68,"") -> 10.718333 | J68: =SUMIF('ADV - GA4'!A:A,A68,'ADV - GA4'!C:C) -> 0 | K68: =IFERROR(D68/J68,"") | L68: =iferror(E68/J68,"") | M68: =$M$63/$B$63 -> 0 | N68: =iferror($N$63/$B$63,"") -> 0 | O68: =iferror(Planejador!$I$59,"") | P68: =Planejador!$I$51 | Q68: =$Q$63/$B$63 -> 0 | R68: =Planejador!$I$53
A69: 46087 | B69: =TEXT(A69,"dddd") -> sexta-feira | D69: =SUMIF('ADV - GG'!A:A,A69,'ADV - GG'!C:C)+SUMIF('ADV - FB'!A:A,$A69,'ADV - FB'!E:E) -> 66.75 | E69: =SUMIF('ADV - GG'!A:A,A69,'ADV - GG'!H:H)+SUMIF('ADV - FB'!A:A,$A69,'ADV - FB'!I:I)+SUMIF('ADV - FB'!A:A,$A69,'ADV - FB'!J:J)+SUMIF('ADV - FB'!A:A,$A69,'ADV - FB'!K:K) -> 5 | F69: =IFERROR(D69/E69,"") -> 13.35 | J69: =SUMIF('ADV - GA4'!A:A,A69,'ADV - GA4'!C:C) -> 0 | K69: =IFERROR(D69/J69,"") | L69: =iferror(E69/J69,"") | M69: =$M$63/$B$63 -> 0 | N69: =iferror($N$63/$B$63,"") -> 0 | O69: =iferror(Planejador!$I$59,"") | P69: =Planejador!$I$51 | Q69: =$Q$63/$B$63 -> 0 | R69: =Planejador!$I$53
A70: 46088 | B70: =TEXT(A70,"dddd") -> sábado | D70: =SUMIF('ADV - GG'!A:A,A70,'ADV - GG'!C:C)+SUMIF('ADV - FB'!A:A,$A70,'ADV - FB'!E:E) -> 58.69 | E70: =SUMIF('ADV - GG'!A:A,A70,'ADV - GG'!H:H)+SUMIF('ADV - FB'!A:A,$A70,'ADV - FB'!I:I)+SUMIF('ADV - FB'!A:A,$A70,'ADV - FB'!J:J)+SUMIF('ADV - FB'!A:A,$A70,'ADV - FB'!K:K) -> 10 | F70: =IFERROR(D70/E70,"") -> 5.869 | J70: =SUMIF('ADV - GA4'!A:A,A70,'ADV - GA4'!C:C) -> 0 | K70: =IFERROR(D70/J70,"") | L70: =iferror(E70/J70,"") | M70: =$M$63/$B$63 -> 0 | N70: =iferror($N$63/$B$63,"") -> 0 | O70: =iferror(Planejador!$I$59,"") | P70: =Planejador!$I$51 | Q70: =$Q$63/$B$63 -> 0 | R70: =Planejador!$I$53
A71: 46089 | B71: =TEXT(A71,"dddd") -> domingo | D71: =SUMIF('ADV - GG'!A:A,A71,'ADV - GG'!C:C)+SUMIF('ADV - FB'!A:A,$A71,'ADV - FB'!E:E) -> 68.48 | E71: =SUMIF('ADV - GG'!A:A,A71,'ADV - GG'!H:H)+SUMIF('ADV - FB'!A:A,$A71,'ADV - FB'!I:I)+SUMIF('ADV - FB'!A:A,$A71,'ADV - FB'!J:J)+SUMIF('ADV - FB'!A:A,$A71,'ADV - FB'!K:K) -> 8 | F71: =IFERROR(D71/E71,"") -> 8.56 | J71: =SUMIF('ADV - GA4'!A:A,A71,'ADV - GA4'!C:C) -> 0 | K71: =IFERROR(D71/J71,"") | L71: =iferror(E71/J71,"") | M71: =$M$63/$B$63 -> 0 | N71: =iferror($N$63/$B$63,"") -> 0 | O71: =iferror(Planejador!$I$59,"") | P71: =Planejador!$I$51 | Q71: =$Q$63/$B$63 -> 0 | R71: =Planejador!$I$53
A72: 46090 | B72: =TEXT(A72,"dddd") -> segunda-feira | D72: =SUMIF('ADV - GG'!A:A,A72,'ADV - GG'!C:C)+SUMIF('ADV - FB'!A:A,$A72,'ADV - FB'!E:E) -> 69.44 | E72: =SUMIF('ADV - GG'!A:A,A72,'ADV - GG'!H:H)+SUMIF('ADV - FB'!A:A,$A72,'ADV - FB'!I:I)+SUMIF('ADV - FB'!A:A,$A72,'ADV - FB'!J:J)+SUMIF('ADV - FB'!A:A,$A72,'ADV - FB'!K:K) -> 8 | F72: =IFERROR(D72/E72,"") -> 8.68 | J72: =SUMIF('ADV - GA4'!A:A,A72,'ADV - GA4'!C:C) -> 0 | K72: =IFERROR(D72/J72,"") | L72: =iferror(E72/J72,"") | M72: =$M$63/$B$63 -> 0 | N72: =iferror($N$63/$B$63,"") -> 0 | O72: =iferror(Planejador!$I$59,"") | P72: =Planejador!$I$51 | Q72: =$Q$63/$B$63 -> 0 | R72: =Planejador!$I$53
A73: 46091 | B73: =TEXT(A73,"dddd") -> terça-feira | D73: =SUMIF('ADV - GG'!A:A,A73,'ADV - GG'!C:C)+SUMIF('ADV - FB'!A:A,$A73,'ADV - FB'!E:E) -> 68.2 | E73: =SUMIF('ADV - GG'!A:A,A73,'ADV - GG'!H:H)+SUMIF('ADV - FB'!A:A,$A73,'ADV - FB'!I:I)+SUMIF('ADV - FB'!A:A,$A73,'ADV - FB'!J:J)+SUMIF('ADV - FB'!A:A,$A73,'ADV - FB'!K:K) -> 9 | F73: =IFERROR(D73/E73,"") -> 7.5777778 | J73: =SUMIF('ADV - GA4'!A:A,A73,'ADV - GA4'!C:C) -> 0 | K73: =IFERROR(D73/J73,"") | L73: =iferror(E73/J73,"") | M73: =$M$63/$B$63 -> 0 | N73: =iferror($N$63/$B$63,"") -> 0 | O73: =iferror(Planejador!$I$59,"") | P73: =Planejador!$I$51 | Q73: =$Q$63/$B$63 -> 0 | R73: =Planejador!$I$53
...

Sheet Calculadora de Leads
I1: Calculadora de Leads
B2: Preencha os campos abaixo e descubra qual a quantidade de Leads necessarios para atingir seus objetivos comerciais.
M4: Etapa do funil | V4: Quantidade Necessária | Y4: Quantidade Atual | AB4: Taxa
B5: Selecione o seu segmento:
M6: Visitantes Únicos | V6: =IF(AB8=0,0,ROUNDDOWN(V9/AB8,0)) -> 2719 | Y6: =IF(B31="",0,ROUNDDOWN(B31,0)) -> 1000
B7: Telecomunicações
AB8: =VLOOKUP($B$7,'Benchmark de Taxas'!$A$4:$D34,2,FALSE) -> 0.057
B9: Preencha a baixo o valor que pretende vender no Mês | M9: Leads | V9: =IF(AB11=0,0,ROUNDDOWN(V12/AB11,0)) -> 155 | Y9: =ROUNDUP(Y6*AB8,0) -> 57
B11: 30000 | AB11: =VLOOKUP($B$7,'Benchmark de Taxas'!$A$4:$D34,3,FALSE) -> 0.436
M12: Oportunidades | V12: =IF(AB14=0,0,ROUNDDOWN(V15/AB14,0)) -> 68 | Y12: =ROUNDUP(Y9*AB11,0) -> 25
B14: Qual é o seu Ticket médio? Valor medio de cada venda | AB14: =VLOOKUP($B$7,'Benchmark de Taxas'!$A$4:$D34,4,FALSE) -> 0.147
M15: Vendas | V15: =V23 -> 10 | Y15: =ROUNDUP(Y12*AB14,0) -> 4
B16: 3000
B19: Quantos leads seu MELHOR vendedor atende em média por mês? | M19: Sua taxa de Conversão
V20: =IFERROR(IF(V15=0,0,V15/V6),0) -> 0.0036778227 | Y20: =IF(AB6=0,"Preencha todos os campos corretamente para visualizar o resultado.",(IF(Y6=AB6,"_______________PARABÉNS 😊_______________ Sua empresa tem o número de visitantes únicos suficiente para atingir seus objetivos comerciais. Para obter resultados ainda melhores, tente otimizar a média de vendas da sua equipe e avalie aumentar seu investime"&"nto em mídia e/ou otimizar suas campanhas. A equipe da TURBO terá prazer em acompanhar sua jornada de sucesso.",IF(AB6>Y6,"_______________PARABÉNS 😊_______________ Sua empresa tem mais visitantes únicos do que a média do seu setor, o que é um bom sinal. No entanto, é importante lembrar que o número de visitantes não é o único fator que determina o sucesso de uma empresa. Se "&"você não estiver atingindo seus resultados, pode ser necessário investir em treinamentos para sua equipe de vendas ou rever seus processos internos. Além disso, é importante avaliar se o investimento em mídia pode ser otimizado para obter resultados ainda"&" melhores. A equipe da TURBO terá prazer em acompanhar sua jornada de sucesso.","_______________ATENÇÃO ⚠️_______________ Sua empresa não tem um número de visitantes únicos suficiente para atingir suas metas comerciais. Para alcançar seus objetivos, é importante reavaliar seu investimento em mídia e procurar um de nossos especialistas"&" para que possamos juntos traçar uma estratégia realista e eficaz. A equipe da TURBO terá prazer em acompanhar sua jornada de sucesso.")))) -> Preencha todos os campos corretamente para visualizar o resultado.
B21: 50
M22: Número de vendas necessárias
V23: =IF(B16=0,0,ROUNDUP(B11/B16,0)) -> 10
B24: Quantos leads seu PIOR vendedor atende em média por mês?
M25: Número de vendedores necessários
B26: 10 | V26: =IFERROR(ROUNDUP(V12/((B21+B26)/2),0),0) -> 3
M28: Número de leads que cada vendedor precisa atender
B29: Quantos Visitantes únicos você tem em média hoje? | V29: =IFERROR(IF($V$26=0,0,ROUNDUP(V12/$V$26,0)),0) -> 23
B31: 1000 | M31: Número de vendas que cada vendedor precisa realizar
V32: =IFERROR(IF($V$26=0,0,ROUNDUP(V15/$V$26,0)),0) -> 4

Sheet Projeção Rápida
D1: PROJEÇÃO RÁPIDA
B3: Investimento | D3: CPS | G3: Canal | H3: Facebook | I3: Google | J3: Outros
B4: 10000 | D4: 0.1 | G4: % | H4: 0.7 | I4: 0.4 | J4: 0
G5: Verba Mês | H5: =H4*$B$4 -> 7000 | I5: =I4*$B$4 -> 4000 | J5: =J4*$B$4 -> 0
B6: Ticket Médio | D6: Taxa de Conversão Visita -> Lead | G6: Verba Dia | H6: =ROUNDUP((B4*H4)/30,0) -> 234 | I6: =ROUNDUP((B4*I4)/30,0) -> 134 | J6: =ROUNDUP((B4*J4)/30,0) -> 0 | K6: =SUM(H6:J6) -> 368
B7: 100 | D7: 0.5
B9: Taxa de Leads Qualificados | D9: Taxa Conversão Lead para Venda
B10: 0.3 | D10: 0.1
B12: LEADS | D12: LEADS QUALIFICADOS
B13: =(B4/D4)*D7 -> 50000 | D13: =B13*B10 -> 15000
B15: CPL | D15: VENDAS
B16: =B4/B13 -> 0.2 | D16: =B13*D10 -> 5000
B18: FATURAMENTO
B19: =D16*B7 -> 500000
B21: ANTES DE ENTRAR NO SITE | D21: DEPOIS DE ENTRAR NO SITE | F21: BENCHMARK DE TAXAS
B22: MELHORIAS PARA CPC | D22: MELHORIAS PARA TX | F22: Segmento | G22: Leads | H22: Oportunidades | I22: Vendas
B23: CRIATIVO | D23: NAVEGABILIDADE | F23: Agência de Marketing e Publicidade | G23: 0.04 | H23: 0.135 | I23: 0.24
B24: COPY | D24: CONTEÚDO | F24: Consultorias e Treinamentos | G24: 0.045 | H24: 0.123 | I24: 0.379
B25: PÚBLICO | D25: OFERTA | F25: E-commerce | G25: 0.03 | H25: 0.211 | I25: 0.614
B26: OFERTA | D26: FRETE | F26: Educação e Ensino | G26: 0.063 | H26: 0.121 | I26: 0.321
B27: CAMPANHAS DE CPC BAIXO | D27: CHECKOUT | F27: Engenharia e Indústria em Geral | G27: 0.038 | H27: 0.176 | I27: 0.373
B28: PRODUTO | D28: CREDIBILIDADE E PROVA SOCIAL | F28: Eventos | G28: 0.043 | H28: 0.102 | I28: 0.572
B29: QUALIDADE DA PÁGINA | F29: Financeiro, Jurídico e Serviços Relacionados | G29: 0.046 | H29: 0.148 | I29: 0.239
F30: Hardware e Eletrônicos | G30: 0.055 | H30: 0.116 | I30: 0.607
F31: Imobiliárias | G31: 0.029 | H31: 0.131 | I31: 0.383
F32: Mídia e Comunicação | G32: 0.038 | H32: 0.108 | I32: 0.268
F33: ONGs | G33: 0.047 | H33: 0.126 | I33: 0.244
F34: Saúde e Estética | G34: 0.051 | H34: 0.224 | I34: 0.363
F35: Serviços em Geral | G35: 0.041 | H35: 0.227 | I35: 0.358
F36: Serviços em RH e Coaching | G36: 0.05 | H36: 0.162 | I36: 0.209
F37: Software e Cloud | G37: 0.057 | H37: 0.122 | I37: 0.148
F38: Telecomunicações | G38: 0.057 | H38: 0.436 | I38: 0.147
F39: Turismo e Lazer | G39: 0.051 | H39: 0.239 | I39: 0.252
F40: Varejo | G40: 0.026 | H40: 0.217 | I40: 0.169

Sheet Planejador
B1: JANEIRO
B3: CENÁRIO ATUAL (ÚLTIMO MÊS) | E3: CENÁRIO DESEJADO | H3: CENÁRIO IDEAL | J3: MÉDIA / ANUAL | K3: % ATUAL | L3: % MÁX
B4: Valor Investimento | E4: Faturamento Desejado | H4: Verba Mensal | K4: =(I4-J4)/J4*1 -> #DIV/0! | L4: 0.4
B5: CPS Geral | E5: CPS Atual | F5: =C5 | H5: CPS Ideal | K5: =(I5-J5)/J5*1 -> #DIV/0! | L5: -0.1
B6: Ticket Médio | E6: Ticket Médio | F6: =C6 | H6: Ticket Médio Ideal | K6: =(I6-J6)/J6*1 -> #DIV/0! | L6: 0.15
B7: TX Conversão Para Lead | E7: TX Conversão Para Lead | F7: =C7 | H7: TX Conversão Para Lead Ideal | K7: =(I7-J7)/J7*1 -> #DIV/0! | L7: 0.15
B8: % Lead Para Venda | E8: % Lead Para Venda | F8: =C8 | H8: % Lead Para Venda Ideal | K8: =(I8-J8)/J8*1 -> #DIV/0! | L8: 0.1
B10: Sessões | C10: =C4/C5 -> #DIV/0! | E10: Sessões Ideais | F10: =(F12/F7)/F8 -> #DIV/0! | H10: Sessões Ideais | I10: =I4/I5 -> #DIV/0! | K10: CANAL DE VENDA | L10: % | M10: FATURAMENTO | N10: PEDIDOS POR CANAL
B11: Leads | C11: =C10*C7 -> #DIV/0! | E11: Leads Ideais | F11: =F10*F7 -> #DIV/0! | H11: Leads Ideais | I11: =I10*I7 -> #DIV/0! | K11: Meta Ads | L11: 0.2 | M11: =I15/100*L11*100 -> #DIV/0! | N11: =M11/I6 -> #DIV/0!
B12: Vendas | C12: =C11*C8 -> #DIV/0! | E12: Vendas | F12: =F4/F6 -> #DIV/0! | H12: Vendas | I12: =I15/I6 -> #DIV/0! | K12: Google Ads | L12: 0.2 | M12: =I15/100*L12*100 -> #DIV/0! | N12: =M12/I6 -> #DIV/0!
B13: CPL | C13: =C4/C11 -> #DIV/0! | E13: CPL Ideal | F13: =F15/F11 -> #DIV/0! | H13: CPL Ideal | I13: =I4/I11 -> #DIV/0! | K13: Social | L13: 0.3 | M13: =I15/100*L13*100 -> #DIV/0! | N13: =M13/I6 -> #DIV/0!
B14: CPA | C14: =C4/C12 -> #DIV/0! | E14: CPA | F14: =F15/F12 -> #DIV/0! | H14: CPA | I14: =I4/I12 -> #DIV/0! | K14: Organico | L14: 0.15 | M14: =I15/100*L14*100 -> #DIV/0! | N14: =M14/I6 -> #DIV/0!
B15: Faturamento Real | C15: =C12*C6 -> #DIV/0! | E15: Investimento Necessário | F15: =F10*F5 -> #DIV/0! | H15: Faturamento Desejado | I15: =(I10*I7*I8)*I6 -> #DIV/0! | K15: E-mail | L15: 0.15 | M15: =I15/100*L15*100 -> #DIV/0! | N15: =M15/I6 -> #DIV/0!
B16: ROAS | C16: =C15/C4 -> #DIV/0! | E16: ROAS | F16: =F4/F15 -> #DIV/0! | H16: ROAS | I16: =I15/I4 -> #DIV/0! | L16: =SUM(L11:L15) -> 1 | N16: =SUM(N11:N15) -> #DIV/0!
B18: CENÁRIO DIÁRIO ATUAL | E18: CENÁRIO DIÁRIO DESEJADO | H18: CENÁRIO DIÁRIO IDEAL | K18: Canal | L18: Facebook | M18: Google | N18: Outros | O18: Total
B19: Investimento Diário | C19: =C4/30 -> 0 | E19: Investimento Diário | F19: =F4/30 -> 0 | H19: Investimento Diário | I19: =I4/'Acompanhamento Geral'!B2 -> 0 | K19: % | L19: 0.1 | M19: 0.9 | N19: 0 | O19: =sum(L19:N19) -> 1
B20: Sessões Diárias | C20: =C10/30 -> #DIV/0! | E20: Sessões Diárias | F20: =F10/30 -> #DIV/0! | H20: Sessões Diárias | I20: =I10/'Acompanhamento Geral'!B2 -> #DIV/0! | K20: Verba Mês | L20: =I4*L19 -> 0 | M20: =I4*M19 -> 0 | N20: =I4*N19 -> 0 | O20: =sum(L20:N20) -> 0
B21: Pedidos Diários | C21: =C12/30 -> #DIV/0! | E21: Pedidos Diários | F21: =F12/30 -> #DIV/0! | H21: Pedidos Diários | I21: =I12/'Acompanhamento Geral'!B2 -> #DIV/0! | K21: Verba Dia | L21: =L20/'Acompanhamento Geral'!B2 -> 0 | M21: =M20/'Acompanhamento Geral'!B2 -> 0 | N21: =iferror(N20/'Acompanhamento Geral'!B2,"") -> 0 | O21: =SUM(L21:N21) -> 0
B22: Faturamento Diário | C22: =C15/30 -> #DIV/0! | E22: Faturamento Diário | F22: =F4/30 -> 0 | H22: Faturamento Diário | I22: =I15/'Acompanhamento Geral'!B2 -> #DIV/0!
B24: FEVEREIRO
B26: CENÁRIO ATUAL (ÚLTIMO MÊS) | E26: CENÁRIO DESEJADO | H26: CENÁRIO IDEAL | J26: MÉDIA / ANUAL | K26: % ATUAL | L26: % MÁX
B27: Valor Investimento | E27: Faturamento Desejado | H27: Verba Mensal | K27: =(I27-J27)/J27*1 -> #DIV/0! | L27: 0.4
B28: CPS Geral | E28: CPS Atual | F28: =C28 | H28: CPS Ideal | K28: =(I28-J28)/J28*1 -> #DIV/0! | L28: -0.1
B29: Ticket Médio | E29: Ticket Médio | F29: =C29 | H29: Ticket Médio Ideal | K29: =(I29-J29)/J29*1 -> #DIV/0! | L29: 0.15
B30: TX Conversão Para Lead | E30: TX Conversão Para Lead | F30: =C30 | H30: TX Conversão Para Lead Ideal | K30: =(I30-J30)/J30*1 -> #DIV/0! | L30: 0.1
B31: % Lead Para Venda | E31: % Lead Para Venda | F31: =C31 | H31: % Lead Para Venda Ideal | K31: =(I31-J31)/J31*1 -> #DIV/0! | L31: 0.1
B33: Sessões | C33: =C27/C28 -> #DIV/0! | E33: Sessões Ideais | F33: =(F35/F30)/F31 -> #DIV/0! | H33: Sessões Ideais | I33: =I27/I28 -> #DIV/0! | K33: CANAL DE VENDA | L33: % | M33: FATURAMENTO | N33: PEDIDOS POR CANAL
B34: Leads | C34: =C33*C30 -> #DIV/0! | E34: Leads Ideais | F34: =F33*F30 -> #DIV/0! | H34: Leads Ideais | I34: =I33*I30 -> #DIV/0! | K34: Meta Ads | L34: 0.2 | M34: =I38/100*L34*100 -> #DIV/0! | N34: =M34/I29 -> #DIV/0!
B35: Vendas | C35: =C34*C31 -> #DIV/0! | E35: Vendas | F35: =F27/F29 -> #DIV/0! | H35: Vendas | I35: =I38/I29 -> #DIV/0! | K35: Google Ads | L35: 0.2 | M35: =I38/100*L35*100 -> #DIV/0! | N35: =M35/I29 -> #DIV/0!
B36: CPL | C36: =C27/C34 -> #DIV/0! | E36: CPL Ideal | F36: =F38/F34 -> #DIV/0! | H36: CPL Ideal | I36: =I27/I34 -> #DIV/0! | K36: Social | L36: 0.3 | M36: =I38/100*L36*100 -> #DIV/0! | N36: =M36/I29 -> #DIV/0!
B37: CPA | C37: =C27/C35 -> #DIV/0! | E37: CPA | F37: =F38/F35 -> #DIV/0! | H37: CPA | I37: =I27/I35 -> #DIV/0! | K37: Organico | L37: 0.15 | M37: =I38/100*L37*100 -> #DIV/0! | N37: =M37/I29 -> #DIV/0!
B38: Faturamento Real | C38: =C35*C29 -> #DIV/0! | E38: Investimento Necessário | F38: =F33*F28 -> #DIV/0! | H38: Faturamento Desejado | I38: =(I33*I30*I31)*I29 -> #DIV/0! | K38: E-mail | L38: 0.15 | M38: =I38/100*L38*100 -> #DIV/0! | N38: =M38/I29 -> #DIV/0!
B39: ROAS | C39: =C38/C27 -> #DIV/0! | E39: ROAS | F39: =F27/F38 -> #DIV/0! | H39: ROAS | I39: =I38/I27 -> #DIV/0! | L39: =SUM(L34:L38) -> 1 | N39: =SUM(N34:N38) -> #DIV/0!
B41: CENÁRIO DIÁRIO ATUAL | E41: CENÁRIO DIÁRIO DESEJADO | H41: CENÁRIO DIÁRIO IDEAL | K41: Canal | L41: Facebook | M41: Google | N41: Outros | O41: Total
B42: Investimento Diário | C42: =C27/30 -> 0 | E42: Investimento Diário | F42: =F27/30 -> 0 | H42: Investimento Diário | I42: =I27/'Acompanhamento Geral'!B25 -> #VALUE! | K42: % | L42: 0.7 | M42: 0.3 | N42: 0 | O42: =sum(L42:N42) -> 1
B43: Sessões Diárias | C43: =C33/30 -> #DIV/0! | E43: Sessões Diárias | F43: =F33/30 -> #DIV/0! | H43: Sessões Diárias | I43: =I33/'Acompanhamento Geral'!B25 -> #DIV/0! | K43: Verba Mês | L43: =I27*L42 -> 0 | M43: =I27*M42 -> 0 | N43: =I27*N42 -> 0 | O43: =sum(L43:N43) -> 0
B44: Pedidos Diários | C44: =C35/30 -> #DIV/0! | E44: Pedidos Diários | F44: =F35/30 -> #DIV/0! | H44: Pedidos Diários | I44: =I35/'Acompanhamento Geral'!B25 -> #DIV/0! | K44: Verba Dia | L44: =L43/'Acompanhamento Geral'!B25 -> #VALUE! | M44: =M43/'Acompanhamento Geral'!B25 -> #VALUE! | N44: =iferror(N43/'Acompanhamento Geral'!B25,"") | O44: =SUM(L44:N44) -> #VALUE!
B45: Faturamento Diário | C45: =C38/30 -> #DIV/0! | E45: Faturamento Diário | F45: =F27/30 -> 0 | H45: Faturamento Diário | I45: =I38/'Acompanhamento Geral'!B25 -> #DIV/0!
B47: MARÇO
B49: CENÁRIO ATUAL (ÚLTIMO MÊS) | E49: CENÁRIO DESEJADO | H49: CENÁRIO IDEAL | J49: MÉDIA / ANUAL | K49: % ATUAL | L49: % MÁX
...

Sheet Dados Históricos
A1: CRESCIMENTO MoM | C1: =IFERROR((C3-B3)/B3*1,"") | D1: =iferror((D3-C3)/C3*1,"") | E1: =iferror((E3-D3)/D3*1,"") | F1: =iferror((F3-E3)/E3*1,"") | G1: =iferror((G3-F3)/F3*1,"") | H1: =iferror((H3-G3)/G3*1,"") | I1: =iferror((I3-H3)/H3*1,"") | J1: =iferror((J3-I3)/I3*1,"") | K1: =iferror((K3-J3)/J3*1,"") | ... M1: =iferror((M3-L3)/L3*1,"") | O1: MÉTRICAS MÉDIAS
A2: MÉTRICAS / MÊS | B2: JAN | C2: FEV | D2: MAR | E2: ABR | F2: MAI | G2: JUN | H2: JUL | I2: AGO | J2: SET | K2: OUT | L2: NOV | M2: DEZ | O2: Crescimento Médio | P2: =AVERAGE(C1:M1) -> #DIV/0!
A3: Leads Captados | O3: Leads Captados | P3: =AVERAGE(B3:M3) -> #DIV/0!
A4: Leads Qualificados | O4: Leads Qualificados | P4: =AVERAGE(B4:M4) -> #DIV/0!
A5: % de Qualificados | B5: =IFERROR(B4/B3,"") | C5: =IFERROR(C4/C3,"") | D5: =IFERROR(D4/D3,"") | E5: =IFERROR(E4/E3,"") | F5: =IFERROR(F4/F3,"") | G5: =IFERROR(G4/G3,"") | H5: =IFERROR(H4/H3,"") | I5: =IFERROR(I4/I3,"") | ... M5: =IFERROR(M4/M3,"") | O5: % de Qualificados | P5: =AVERAGE(B5:M5) -> #DIV/0!
A6: Leads Captados Midia Paga | O6: Leads Captados Midia Paga | P6: =AVERAGE(B6:M6) -> #DIV/0!
A7: % Mídia Paga | B7: =IFERROR((B6/B3)*1,"") | C7: =IFERROR((C6/C3)*1,"") | D7: =IFERROR((D6/D3)*1,"") | E7: =IFERROR((E6/E3)*1,"") | F7: =IFERROR((F6/F3)*1,"") | G7: =IFERROR((G6/G3)*1,"") | H7: =IFERROR((H6/H3)*1,"") | I7: =IFERROR((I6/I3)*1,"") | ... M7: =IFERROR((M6/M3)*1,"") | O7: % Mídia Paga | P7: =AVERAGE(B7:J7) -> #DIV/0!
A8: Leads Outros Canais | B8: =IFERROR(B3-B6,"") -> 0 | C8: =IFERROR(C3-C6,"") -> 0 | D8: =IFERROR(D3-D6,"") -> 0 | E8: =IFERROR(E3-E6,"") -> 0 | F8: =IFERROR(F3-F6,"") -> 0 | G8: =IFERROR(G3-G6,"") -> 0 | H8: =IFERROR(H3-H6,"") -> 0 | I8: =IFERROR(I3-I6,"") -> 0 | ... M8: =IFERROR(M3-M6,"") -> 0 | O8: Leads Outros Canais | P8: =AVERAGE(B8:M8) -> 0
A9: % Outros Canais | B9: =IFERROR((B8/B3)*1,"") | C9: =IFERROR((C8/C3)*1,"") | D9: =IFERROR((D8/D3)*1,"") | E9: =IFERROR((E8/E3)*1,"") | F9: =IFERROR((F8/F3)*1,"") | G9: =IFERROR((G8/G3)*1,"") | H9: =IFERROR((H8/H3)*1,"") | I9: =IFERROR((I8/I3)*1,"") | ... M9: =IFERROR((M8/M3)*1,"") | O9: % Outros Canais | P9: =AVERAGE(B9:M9) -> #DIV/0!
A10: Investimento Ads | O10: Investimento Ads | P10: =AVERAGE(B10:M10) -> #DIV/0!
A11: % Aumento / Redução ADS | O11: % Aumento / Redução ADS | P11: =AVERAGE(B11:M11) -> #DIV/0!
A12: Sessões Totais | O12: Sessões Geral | P12: =AVERAGE(B12:M12) -> #DIV/0!
A13: Sessões Midia | O13: Sessões Mídia | P13: =AVERAGE(B13:M13) -> #DIV/0!
A14: CPS Geral | B14: =IFERROR(B10/B12,"") | C14: =IFERROR(C10/C12,"") | D14: =IFERROR(D10/D12,"") | E14: =IFERROR(E10/E12,"") | F14: =IFERROR(F10/F12,"") | G14: =IFERROR(G10/G12,"") | H14: =IFERROR(H10/H12,"") | I14: =IFERROR(I10/I12,"") | ... M14: =IFERROR(M10/M12,"") | O14: CPS Geral | P14: =AVERAGE(B14:M14) -> #DIV/0!
A15: CPS Midia | B15: =IFERROR(B10/B13,"") | C15: =IFERROR(C10/C13,"") | D15: =IFERROR(D10/D13,"") | E15: =IFERROR(E10/E13,"") | F15: =IFERROR(F10/F13,"") | G15: =IFERROR(G10/G13,"") | H15: =IFERROR(H10/H13,"") | I15: =IFERROR(I10/I13,"") | ... M15: =IFERROR(M10/M13,"") | O15: CPS Mídia | P15: =AVERAGE(B15:M15) -> #DIV/0!
A16: Taxa de Conversão Para Lead (%) | B16: =IFERROR(B3/B12,"") | C16: =IFERROR(C3/C12,"") | D16: =IFERROR(D3/D12,"") | E16: =IFERROR(E3/E12,"") | F16: =IFERROR(F3/F12,"") | G16: =IFERROR(G3/G12,"") | H16: =IFERROR(H3/H12,"") | I16: =IFERROR(I3/I12,"") | ... M16: =IFERROR(M3/M12,"") | O16: Taxa de Conversão Para Lead | P16: =AVERAGE(B16:M16) -> #DIV/0!
A17: Taxa de Conversão Para Qualificado (%) | B17: =IFERROR(B4/B12,"") | C17: =IFERROR(C4/C12,"") | D17: =IFERROR(D4/D12,"") | E17: =IFERROR(E4/E12,"") | F17: =IFERROR(F4/F12,"") | G17: =IFERROR(G4/G12,"") | H17: =IFERROR(H4/H12,"") | I17: =IFERROR(I4/I12,"") | ... M17: =IFERROR(M4/M12,"") | O17: Taxa de Conversão Qualificado | P17: =AVERAGE(B17:M17) -> #DIV/0!
A18: CPL Geral | B18: =IFERROR(B10/B3,"") | C18: =IFERROR(C10/C3,"") | D18: =IFERROR(D10/D3,"") | E18: =IFERROR(E10/E3,"") | F18: =IFERROR(F10/F3,"") | G18: =IFERROR(G10/G3,"") | H18: =IFERROR(H10/H3,"") | I18: =IFERROR(I10/I3,"") | ... M18: =IFERROR(M10/M3,"") | O18: CPL Geral | P18: =AVERAGE(B18:M18) -> #DIV/0!
A19: CPL Qualificado | B19: =IFERROR(B10/B4,"") | C19: =IFERROR(C10/C4,"") | D19: =IFERROR(D10/D4,"") | E19: =IFERROR(E10/E4,"") | F19: =IFERROR(F10/F4,"") | G19: =IFERROR(G10/G4,"") | H19: =IFERROR(H10/H4,"") | I19: =IFERROR(I10/I4,"") | ... M19: =IFERROR(M10/M4,"") | O19: CPL Qualificado | P19: =AVERAGE(B19:M19) -> #DIV/0!
A20: Negocios Fechados | O20: Negocios Fechados | P20: =AVERAGE(B20:M20) -> #DIV/0!
A21: CPA (R$) | B21: =iferror(B10/B20,"") | C21: =iferror(C10/C20,"") | D21: =iferror(D10/D20,"") | E21: =iferror(E10/E20,"") | F21: =iferror(F10/F20,"") | G21: =iferror(G10/G20,"") | H21: =iferror(H10/H20,"") | I21: =iferror(I10/I20,"") | ... M21: =iferror(M10/M20,"") | O21: CPA (R$) | P21: =AVERAGE(B21:M21) -> #DIV/0!
A22: Valor de Negocios Fechados | O22: Valor de Negocios Fechados | P22: =AVERAGE(B22:M22) -> #DIV/0!
A23: Ticket Médio | B23: =iferror(B22/B20,"") | C23: =iferror(C22/C20,"") | D23: =iferror(D22/D20,"") | E23: =iferror(E22/E20,"") | F23: =iferror(F22/F20,"") | G23: =iferror(G22/G20,"") | H23: =iferror(H22/H20,"") | I23: =iferror(I22/I20,"") | ... M23: =iferror(M22/M20,"") | O23: Ticket Médio | P23: =AVERAGE(B23:M23) -> #DIV/0!
A24: % Lead Para Venda | B24: =iferror(B20/B3,"") | C24: =iferror(C20/C3,"") | D24: =iferror(D20/D3,"") | E24: =iferror(E20/E3,"") | F24: =iferror(F20/F3,"") | G24: =iferror(G20/G3,"") | H24: =iferror(H20/H3,"") | I24: =iferror(I20/I3,"") | ... M24: =iferror(M20/M3,"") | O24: % Lead Para Venda | P24: =AVERAGE(B24:M24) -> #DIV/0!
A25: ROAS | B25: =iferror(B22/B10,"") | C25: =iferror(C22/C10,"") | D25: =iferror(D22/D10,"") | E25: =iferror(E22/E10,"") | F25: =iferror(F22/F10,"") | G25: =iferror(G22/G10,"") | H25: =iferror(H22/H10,"") | I25: =iferror(I22/I10,"") | ... M25: =iferror(M22/M10,"") | O25: ROAS | P25: =AVERAGE(B25:M25) -> #DIV/0!
A29: CANAIS | B29: JAN | C29: FEV | D29: MAR | E29: ABR | F29: MAI | G29: JUN | H29: JUL | I29: AGO | J29: SET | K29: OUT | L29: NOV | M29: DEZ | O29: TOTAL
A30: (Other) | O30: =SUM(B30:M30) -> 0 | P30: =iferror(O30/$O$44,"")
A31: Direto / none | O31: =SUM(B31:M31) -> 0 | P31: =iferror(O31/$O$44,"")
A32: Facebook cpc | O32: =SUM(B32:M32) -> 0 | P32: =iferror(O32/$O$44,"")
A33: Google cpc | O33: =SUM(B33:M33) -> 0 | P33: =iferror(O33/$O$44,"")
A34: Orgânico | O34: =SUM(B34:M34) -> 0 | P34: =iferror(O34/$O$44,"")
A35: Instagram Perfil | O35: =SUM(B35:M35) -> 0 | P35: =iferror(O35/$O$44,"")
A36: E-mail | O36: =SUM(B36:M36) -> 0 | P36: =iferror(O36/$O$44,"")
A37: IG Shopping | O37: =SUM(B37:M37) -> 0 | P37: =iferror(O37/$O$44,"")
A38: Instagram / FB Referral | O38: =SUM(B38:M38) -> 0 | P38: =iferror(O38/$O$44,"")
A39: Blog | O39: =SUM(B39:M39) -> 0 | P39: =iferror(O39/$O$44,"")
A40: Pinterest / Referral | O40: =SUM(B40:M40) -> 0 | P40: =iferror(O40/$O$44,"")
A41: TikTok | O41: =SUM(B41:M41) -> 0 | P41: =iferror(O41/$O$44,"")
... A43: Youtube referral | O43: =SUM(B43:M43) -> 0 | P43: =iferror(O43/$O$44,"")
A44: Total de Leads | B44: =IFERROR(SUM(B30:B43),"") -> 0 | C44: =IFERROR(SUM(C30:C43),"") -> 0 | D44: =IFERROR(SUM(D30:D43),"") -> 0 | E44: =IFERROR(SUM(E30:E43),"") -> 0 | F44: =IFERROR(SUM(F30:F43),"") -> 0 | G44: =IFERROR(SUM(G30:G43),"") -> 0 | H44: =IFERROR(SUM(H30:H43),"") -> 0 | I44: =IFERROR(SUM(I30:I43),"") -> 0 | ... M44: =IFERROR(SUM(M30:M43),"") -> 0 | O44: =SUM(B44:M44) -> 0
...

Sheet Calendário 2024
C1: CALENDÁRIO 2025
B3: JANEIRO | J3: FEVEREIRO | R3: MARÇO | Z3: DATAS COMEMORATIVAS
B4: Seg | C4: Ter | D4: Qua | E4: Qui | F4: Sex | G4: Sáb | H4: Dom | J4: Seg | K4: Ter | L4: Qua | M4: Qui | N4: Sex | O4: Sáb | P4: Dom | R4: Seg | S4: Ter | T4: Qua | U4: Qui | V4: Sex | W4: Sáb | X4: Dom | Z4: 45047 | AA4: Dia do Trabalho
B5: 1 | C5: 2 | D5: 3 | E5: 4 | F5: 5 | G5: 6 | H5: 7 | M5: 1 | N5: 2 | O5: 3 | P5: 4 | V5: 1 | W5: 2 | X5: 3 | Z5: 45058 | AA5: Dia das Mães
B6: 8 | C6: 9 | D6: 10 | E6: 11 | F6: 12 | G6: 13 | H6: 14 | J6: 5 | K6: 6 | L6: 7 | M6: 8 | N6: 9 | O6: 10 | P6: 11 | R6: 4 | S6: 5 | T6: 6 | U6: 7 | V6: 8 | W6: 9 | X6: 10 | Z6: 45068 | AA6: Dia do Abraço
B7: 15 | C7: 16 | D7: 17 | E7: 18 | F7: 19 | G7: 20 | H7: 21 | J7: 12 | K7: 13 | L7: 14 | M7: 15 | N7: 16 | O7: 17 | P7: 18 | R7: 11 | S7: 12 | T7: 13 | U7: 14 | V7: 15 | W7: 16 | X7: 17 | Z7: 45071 | AA7: Dia do Orgulho Nerd
B8: 22 | C8: 23 | D8: 24 | E8: 25 | F8: 26 | G8: 27 | H8: 28 | J8: 19 | K8: 20 | L8: 21 | M8: 22 | N8: 23 | O8: 24 | P8: 25 | R8: 18 | S8: 19 | T8: 20 | U8: 21 | V8: 22 | W8: 23 | X8: 24 | Z8: 45089 | AA8: Dia dos Namorados
B9: 29 | C9: 30 | D9: 31 | J9: 26 | K9: 27 | L9: 28 | M9: 29 | R9: 25 | S9: 26 | T9: 27 | U9: 28 | V9: 29 | W9: 30 | X9: 31 | Z9: 45098 | AA9: Inicio do Inverno
Z10: 45105 | AA10: Dia do Orgulho LGBT
B11: ABRIL | J11: MAIO | R11: JUNHO | Z11: 45120 | AA11: Dia do Rock
B12: Seg | C12: Ter | D12: Qua | E12: Qui | F12: Sex | G12: Sáb | H12: Dom | J12: Seg | K12: Ter | L12: Qua | M12: Qui | N12: Sex | O12: Sáb | P12: Dom | R12: Seg | S12: Ter | T12: Qua | U12: Qui | V12: Sex | W12: Sáb | X12: Dom | Z12: 45122 | AA12: Dia do Homem
B13: 1 | C13: 2 | D13: 3 | E13: 4 | F13: 5 | G13: 6 | H13: 7 | L13: 1 | M13: 2 | N13: 3 | O13: 4 | P13: 5 | W13: 1 | X13: 2 | Z13: 45137 | AA13: Dia dos Amigos
B14: 8 | C14: 9 | D14: 10 | E14: 11 | F14: 12 | G14: 13 | H14: 14 | J14: 6 | K14: 7 | L14: 8 | M14: 9 | N14: 10 | O14: 11 | P14: 12 | R14: 3 | S14: 4 | T14: 5 | U14: 6 | V14: 7 | W14: 8 | X14: 9 | Z14: 45149 | AA14: Dia dos Pais
B15: 15 | C15: 16 | D15: 17 | E15: 18 | F15: 19 | G15: 20 | H15: 21 | J15: 13 | K15: 14 | L15: 15 | M15: 16 | N15: 17 | O15: 18 | P15: 19 | R15: 10 | S15: 11 | T15: 12 | U15: 13 | V15: 14 | W15: 15 | X15: 16 | Z15: 45153 | AA15: Dia dos Solteiros
B16: 22 | C16: 23 | D16: 24 | E16: 25 | F16: 26 | G16: 27 | H16: 28 | J16: 20 | K16: 21 | L16: 22 | M16: 23 | N16: 24 | O16: 25 | P16: 26 | R16: 17 | S16: 18 | T16: 19 | U16: 20 | V16: 21 | W16: 22 | X16: 23 | Z16: 45176 | AA16: Independencia do Brasil
B17: 29 | C17: 30 | J17: 27 | K17: 28 | L17: 29 | M17: 30 | N17: 31 | R17: 24 | S17: 25 | T17: 26 | U17: 27 | V17: 28 | W17: 29 | X17: 30 | Z17: 45184 | AA17: Dia do Cliente
Z18: 45211 | AA18: Dia das Crianças
B19: JULHO | J19: AGOSTO | R19: SETEMBRO | Z19: 45230 | AA19: Halloween
B20: Seg | C20: Ter | D20: Qua | E20: Qui | F20: Sex | G20: Sáb | H20: Dom | J20: Seg | K20: Ter | L20: Qua | M20: Qui | N20: Sex | O20: Sáb | P20: Dom | R20: Seg | S20: Ter | T20: Qua | U20: Qui | V20: Sex | W20: Sáb | X20: Dom | Z20: 45245 | AA20: Dia da proclamação da Republica
B21: 1 | C21: 2 | D21: 3 | E21: 4 | F21: 5 | G21: 6 | H21: 7 | M21: 1 | N21: 2 | O21: 3 | P21: 4 | X21: 1 | Z21: 45252 | AA21: Black Friday
B22: 8 | C22: 9 | D22: 10 | E22: 11 | F22: 12 | G22: 13 | H22: 14 | J22: 5 | K22: 6 | L22: 7 | M22: 8 | N22: 9 | O22: 10 | P22: 11 | R22: 2 | S22: 3 | T22: 4 | U22: 5 | V22: 6 | W22: 7 | X22: 8 | Z22: 45255 | AA22: Cyber Monday
B23: 15 | C23: 16 | D23: 17 | E23: 18 | F23: 19 | G23: 20 | H23: 21 | J23: 12 | K23: 13 | L23: 14 | M23: 15 | N23: 16 | O23: 17 | P23: 18 | R23: 9 | S23: 10 | T23: 11 | U23: 12 | V23: 13 | W23: 14 | X23: 15 | Z23: 45285 | AA23: Natal
B24: 22 | C24: 23 | D24: 24 | E24: 25 | F24: 26 | G24: 27 | H24: 28 | J24: 19 | K24: 20 | L24: 21 | M24: 22 | N24: 23 | O24: 24 | P24: 25 | R24: 16 | S24: 17 | T24: 18 | U24: 19 | V24: 20 | W24: 21 | X24: 22 | Z24: 45291 | AA24: Ano novo
B25: 29 | C25: 30 | D25: 31 | J25: 26 | K25: 27 | L25: 28 | M25: 29 | N25: 20 | O25: 31 | R25: 23 | S25: 24 | T25: 25 | U25: 26 | V25: 27 | W25: 28 | X25: 29
R26: 30
B28: OUTUBRO | J28: NOVEMBRO | R28: DEZEMBRO
B29: Seg | C29: Ter | D29: Qua | E29: Qui | F29: Sex | G29: Sáb | H29: Dom | J29: Seg | K29: Ter | L29: Qua | M29: Qui | N29: Sex | O29: Sáb | P29: Dom | R29: Seg | S29: Ter | T29: Qua | U29: Qui | V29: Sex | W29: Sáb | X29: Dom
C30: 1 | D30: 2 | E30: 3 | F30: 4 | G30: 5 | H30: 6 | N30: 1 | O30: 2 | P30: 3 | X30: 1
B31: 7 | C31: 8 | D31: 9 | E31: 10 | F31: 11 | G31: 12 | H31: 13 | J31: 4 | K31: 5 | L31: 6 | M31: 7 | N31: 8 | O31: 9 | P31: 10 | R31: 2 | S31: 3 | T31: 4 | U31: 5 | V31: 6 | W31: 7 | X31: 8
B32: 14 | C32: 15 | D32: 16 | E32: 17 | F32: 18 | G32: 19 | H32: 20 | J32: 11 | K32: 12 | L32: 13 | M32: 14 | N32: 15 | O32: 16 | P32: 17 | R32: 9 | S32: 10 | T32: 11 | U32: 12 | V32: 13 | W32: 14 | X32: 15
B33: 21 | C33: 22 | D33: 23 | E33: 24 | F33: 25 | G33: 26 | H33: 27 | J33: 18 | K33: 19 | L33: 20 | M33: 21 | N33: 22 | O33: 23 | P33: 24 | R33: 16 | S33: 17 | T33: 18 | U33: 19 | V33: 20 | W33: 21 | X33: 22
B34: 28 | C34: 29 | D34: 30 | E34: 31 | J34: 25 | K34: 26 | L34: 27 | M34: 28 | N34: 29 | O34: 30 | R34: 23 | S34: 24 | T34: 25 | U34: 26 | V34: 27 | W34: 28 | X34: 29
R35: 30 | S35: 31

Sheet Calendário Janeiro
B1: JANEIRO 2025
B3: SEGUNDA-FEIRA | C3: TERÇA-FEIRA | D3: QUARTA-FEIRA | E3: QUINTA-FEIRA | F3: SEXTA-FEIRA | G3: SÁBADO | H3: DOMINGO
B4: 1 | C4: 2 | D4: 3 | E4: 4 | F4: 5 | G4: 6 | H4: 7
B6: 8 | C6: 9 | D6: 10 | E6: 11 | F6: 12 | G6: 13 | H6: 14
B8: 15 | C8: 16 | D8: 17 | E8: 18 | F8: 19 | G8: 20 | H8: 21
B10: 22 | C10: 23 | D10: 24 | E10: 25 | F10: 26 | G10: 27 | H10: 28
B12: 29 | C12: 30 | D12: 31
B15: OBSERVAÇÕES:
B21: LEGENDA:
B22: Feriados
B23: Datas de nicho
B24: Datas Importantes
B25: Essenciais no E-commerce

Sheet E-mail Mkt
A1: Campanha Broadcast | B1: Enviados | C1: Aberturas | D1: % Abertura | E1: Cliques | F1: % Cliques
A2: Nome - data - Segmentação | B2: 61927 | C2: 7226 | D2: =C2/B2 -> 0.11668578 | E2: 605 | F2: =E2/B2 -> 0.0097695674

Sheet Resultado Criativos
A1: ID | B1: Nome Drive | C1: ID Copy | D1: Data Postagem | E1: Info Extra | F1: Nome Final | G1: CUSTO | H1: CTR | I1: CPS | J1: LEADS | K1: CPL
A2: TP01 | F2: =CONCATENATE(A2,," ","-"," ","",B2,""," ","-"," ",C2," ","-"," ",D2) -> TP01 - - - | G2: =SUMIF('ADV - FB'!L:L,$A2,'ADV - FB'!E:E) -> 0 | H2: =IFERROR(SUMIF('ADV - FB'!L:L,$A2,'ADV - FB'!H:H)/(SUMIF('ADV - FB'!L:L,$A2,'ADV - FB'!G:G)),"-") -> - | I2: =IFERROR(SUMIF('ADV - FB'!L:L,$A2,'ADV - FB'!E:E)/(SUMIF('ADV - FB'!L:L,$A2,'ADV - FB'!F:F)),"-") -> - | J2: =SUMIF('ADV - FB'!L:L,$A2,'ADV - FB'!I:I)+SUMIF('ADV - FB'!L:L,$A2,'ADV - FB'!J:J)+SUMIF('ADV - FB'!L:L,$A2,'ADV - FB'!K:K) -> 0 | K2: =IFERROR(G2/J2,"-") -> -
A3: TP02 | F3: =CONCATENATE(A3,," ","-"," ","",B3,""," ","-"," ",C3," ","-"," ",D3) -> TP02 - - - | G3: =SUMIF('ADV - FB'!L:L,$A3,'ADV - FB'!E:E) -> 0 | H3: =IFERROR(SUMIF('ADV - FB'!L:L,$A3,'ADV - FB'!H:H)/(SUMIF('ADV - FB'!L:L,$A3,'ADV - FB'!G:G)),"-") -> - | I3: =IFERROR(SUMIF('ADV - FB'!L:L,$A3,'ADV - FB'!E:E)/(SUMIF('ADV - FB'!L:L,$A3,'ADV - FB'!F:F)),"-") -> - | J3: =SUMIF('ADV - FB'!L:L,$A3,'ADV - FB'!I:I)+SUMIF('ADV - FB'!L:L,$A3,'ADV - FB'!J:J)+SUMIF('ADV - FB'!L:L,$A3,'ADV - FB'!K:K) -> 0 | K3: =IFERROR(G3/J3,"-") -> -
A4: TP03 | F4: =CONCATENATE(A4,," ","-"," ","",B4,""," ","-"," ",C4," ","-"," ",D4) -> TP03 - - - | G4: =SUMIF('ADV - FB'!L:L,$A4,'ADV - FB'!E:E) -> 0 | H4: =IFERROR(SUMIF('ADV - FB'!L:L,$A4,'ADV - FB'!H:H)/(SUMIF('ADV - FB'!L:L,$A4,'ADV - FB'!G:G)),"-") -> - | I4: =IFERROR(SUMIF('ADV - FB'!L:L,$A4,'ADV - FB'!E:E)/(SUMIF('ADV - FB'!L:L,$A4,'ADV - FB'!F:F)),"-") -> - | J4: =SUMIF('ADV - FB'!L:L,$A4,'ADV - FB'!I:I)+SUMIF('ADV - FB'!L:L,$A4,'ADV - FB'!J:J)+SUMIF('ADV - FB'!L:L,$A4,'ADV - FB'!K:K) -> 0 | K4: =IFERROR(G4/J4,"-") -> -
A5: TP04 | F5: =CONCATENATE(A5,," ","-"," ","",B5,""," ","-"," ",C5," ","-"," ",D5) -> TP04 - - - | G5: =SUMIF('ADV - FB'!L:L,$A5,'ADV - FB'!E:E) -> 0 | H5: =IFERROR(SUMIF('ADV - FB'!L:L,$A5,'ADV - FB'!H:H)/(SUMIF('ADV - FB'!L:L,$A5,'ADV - FB'!G:G)),"-") -> - | I5: =IFERROR(SUMIF('ADV - FB'!L:L,$A5,'ADV - FB'!E:E)/(SUMIF('ADV - FB'!L:L,$A5,'ADV - FB'!F:F)),"-") -> - | J5: =SUMIF('ADV - FB'!L:L,$A5,'ADV - FB'!I:I)+SUMIF('ADV - FB'!L:L,$A5,'ADV - FB'!J:J)+SUMIF('ADV - FB'!L:L,$A5,'ADV - FB'!K:K) -> 0 | K5: =IFERROR(G5/J5,"-") -> -
A6: TP05 | F6: =CONCATENATE(A6,," ","-"," ","",B6,""," ","-"," ",C6," ","-"," ",D6) -> TP05 - - - | G6: =SUMIF('ADV - FB'!L:L,$A6,'ADV - FB'!E:E) -> 0 | H6: =IFERROR(SUMIF('ADV - FB'!L:L,$A6,'ADV - FB'!H:H)/(SUMIF('ADV - FB'!L:L,$A6,'ADV - FB'!G:G)),"-") -> - | I6: =IFERROR(SUMIF('ADV - FB'!L:L,$A6,'ADV - FB'!E:E)/(SUMIF('ADV - FB'!L:L,$A6,'ADV - FB'!F:F)),"-") -> - | J6: =SUMIF('ADV - FB'!L:L,$A6,'ADV - FB'!I:I)+SUMIF('ADV - FB'!L:L,$A6,'ADV - FB'!J:J)+SUMIF('ADV - FB'!L:L,$A6,'ADV - FB'!K:K) -> 0 | K6: =IFERROR(G6/J6,"-") -> -
A7: TP06 | F7: =CONCATENATE(A7,," ","-"," ","",B7,""," ","-"," ",C7," ","-"," ",D7) -> TP06 - - - | G7: =SUMIF('ADV - FB'!L:L,$A7,'ADV - FB'!E:E) -> 0 | H7: =IFERROR(SUMIF('ADV - FB'!L:L,$A7,'ADV - FB'!H:H)/(SUMIF('ADV - FB'!L:L,$A7,'ADV - FB'!G:G)),"-") -> - | I7: =IFERROR(SUMIF('ADV - FB'!L:L,$A7,'ADV - FB'!E:E)/(SUMIF('ADV - FB'!L:L,$A7,'ADV - FB'!F:F)),"-") -> - | J7: =SUMIF('ADV - FB'!L:L,$A7,'ADV - FB'!I:I)+SUMIF('ADV - FB'!L:L,$A7,'ADV - FB'!J:J)+SUMIF('ADV - FB'!L:L,$A7,'ADV - FB'!K:K) -> 0 | K7: =IFERROR(G7/J7,"-") -> -
A8: TP07 | F8: =CONCATENATE(A8,," ","-"," ","",B8,""," ","-"," ",C8," ","-"," ",D8) -> TP07 - - - | G8: =SUMIF('ADV - FB'!L:L,$A8,'ADV - FB'!E:E) -> 0 | H8: =IFERROR(SUMIF('ADV - FB'!L:L,$A8,'ADV - FB'!H:H)/(SUMIF('ADV - FB'!L:L,$A8,'ADV - FB'!G:G)),"-") -> - | I8: =IFERROR(SUMIF('ADV - FB'!L:L,$A8,'ADV - FB'!E:E)/(SUMIF('ADV - FB'!L:L,$A8,'ADV - FB'!F:F)),"-") -> - | J8: =SUMIF('ADV - FB'!L:L,$A8,'ADV - FB'!I:I)+SUMIF('ADV - FB'!L:L,$A8,'ADV - FB'!J:J)+SUMIF('ADV - FB'!L:L,$A8,'ADV - FB'!K:K) -> 0 | K8: =IFERROR(G8/J8,"-") -> -
A9: TP08 | F9: =CONCATENATE(A9,," ","-"," ","",B9,""," ","-"," ",C9," ","-"," ",D9) -> TP08 - - - | G9: =SUMIF('ADV - FB'!L:L,$A9,'ADV - FB'!E:E) -> 0 | H9: =IFERROR(SUMIF('ADV - FB'!L:L,$A9,'ADV - FB'!H:H)/(SUMIF('ADV - FB'!L:L,$A9,'ADV - FB'!G:G)),"-") -> - | I9: =IFERROR(SUMIF('ADV - FB'!L:L,$A9,'ADV - FB'!E:E)/(SUMIF('ADV - FB'!L:L,$A9,'ADV - FB'!F:F)),"-") -> - | J9: =SUMIF('ADV - FB'!L:L,$A9,'ADV - FB'!I:I)+SUMIF('ADV - FB'!L:L,$A9,'ADV - FB'!J:J)+SUMIF('ADV - FB'!L:L,$A9,'ADV - FB'!K:K) -> 0 | K9: =IFERROR(G9/J9,"-") -> -
A10: TP09 | F10: =CONCATENATE(A10,," ","-"," ","",B10,""," ","-"," ",C10," ","-"," ",D10) -> TP09 - - - | G10: =SUMIF('ADV - FB'!L:L,$A10,'ADV - FB'!E:E) -> 0 | H10: =IFERROR(SUMIF('ADV - FB'!L:L,$A10,'ADV - FB'!H:H)/(SUMIF('ADV - FB'!L:L,$A10,'ADV - FB'!G:G)),"-") -> - | I10: =IFERROR(SUMIF('ADV - FB'!L:L,$A10,'ADV - FB'!E:E)/(SUMIF('ADV - FB'!L:L,$A10,'ADV - FB'!F:F)),"-") -> - | J10: =SUMIF('ADV - FB'!L:L,$A10,'ADV - FB'!I:I)+SUMIF('ADV - FB'!L:L,$A10,'ADV - FB'!J:J)+SUMIF('ADV - FB'!L:L,$A10,'ADV - FB'!K:K) -> 0 | K10: =IFERROR(G10/J10,"-") -> -
A11: TP10 | F11: =CONCATENATE(A11,," ","-"," ","",B11,""," ","-"," ",C11," ","-"," ",D11) -> TP10 - - - | G11: =SUMIF('ADV - FB'!L:L,$A11,'ADV - FB'!E:E) -> 0 | H11: =IFERROR(SUMIF('ADV - FB'!L:L,$A11,'ADV - FB'!H:H)/(SUMIF('ADV - FB'!L:L,$A11,'ADV - FB'!G:G)),"-") -> - | I11: =IFERROR(SUMIF('ADV - FB'!L:L,$A11,'ADV - FB'!E:E)/(SUMIF('ADV - FB'!L:L,$A11,'ADV - FB'!F:F)),"-") -> - | J11: =SUMIF('ADV - FB'!L:L,$A11,'ADV - FB'!I:I)+SUMIF('ADV - FB'!L:L,$A11,'ADV - FB'!J:J)+SUMIF('ADV - FB'!L:L,$A11,'ADV - FB'!K:K) -> 0 | K11: =IFERROR(G11/J11,"-") -> -
A12: TP11 | F12: =CONCATENATE(A12,," ","-"," ","",B12,""," ","-"," ",C12," ","-"," ",D12) -> TP11 - - - | G12: =SUMIF('ADV - FB'!L:L,$A12,'ADV - FB'!E:E) -> 0 | H12: =IFERROR(SUMIF('ADV - FB'!L:L,$A12,'ADV - FB'!H:H)/(SUMIF('ADV - FB'!L:L,$A12,'ADV - FB'!G:G)),"-") -> - | I12: =IFERROR(SUMIF('ADV - FB'!L:L,$A12,'ADV - FB'!E:E)/(SUMIF('ADV - FB'!L:L,$A12,'ADV - FB'!F:F)),"-") -> - | J12: =SUMIF('ADV - FB'!L:L,$A12,'ADV - FB'!I:I)+SUMIF('ADV - FB'!L:L,$A12,'ADV - FB'!J:J)+SUMIF('ADV - FB'!L:L,$A12,'ADV - FB'!K:K) -> 0 | K12: =IFERROR(G12/J12,"-") -> -
A13: TP12 | F13: =CONCATENATE(A13,," ","-"," ","",B13,""," ","-"," ",C13," ","-"," ",D13) -> TP12 - - - | G13: =SUMIF('ADV - FB'!L:L,$A13,'ADV - FB'!E:E) -> 0 | H13: =IFERROR(SUMIF('ADV - FB'!L:L,$A13,'ADV - FB'!H:H)/(SUMIF('ADV - FB'!L:L,$A13,'ADV - FB'!G:G)),"-") -> - | I13: =IFERROR(SUMIF('ADV - FB'!L:L,$A13,'ADV - FB'!E:E)/(SUMIF('ADV - FB'!L:L,$A13,'ADV - FB'!F:F)),"-") -> - | J13: =SUMIF('ADV - FB'!L:L,$A13,'ADV - FB'!I:I)+SUMIF('ADV - FB'!L:L,$A13,'ADV - FB'!J:J)+SUMIF('ADV - FB'!L:L,$A13,'ADV - FB'!K:K) -> 0 | K13: =IFERROR(G13/J13,"-") -> -
... A998: TP997 | F998: =CONCATENATE(A998,," ","-"," ","",B998,""," ","-"," ",C998," ","-"," ",D998) -> TP997 - - - | G998: =SUMIF('ADV - FB'!L:L,$A998,'ADV - FB'!E:E) -> 0 | H998: =IFERROR(SUMIF('ADV - FB'!L:L,$A998,'ADV - FB'!H:H)/(SUMIF('ADV - FB'!L:L,$A998,'ADV - FB'!G:G)),"-") -> - | I998: =IFERROR(SUMIF('ADV - FB'!L:L,$A998,'ADV - FB'!E:E)/(SUMIF('ADV - FB'!L:L,$A998,'ADV - FB'!F:F)),"-") -> - | J998: =SUMIF('ADV - FB'!L:L,$A998,'ADV - FB'!I:I)+SUMIF('ADV - FB'!L:L,$A998,'ADV - FB'!J:J)+SUMIF('ADV - FB'!L:L,$A998,'ADV - FB'!K:K) -> 0 | K998: =IFERROR(G998/J998,"-") -> -
A999: TP998 | F999: =CONCATENATE(A999,," ","-"," ","",B999,""," ","-"," ",C999," ","-"," ",D999) -> TP998 - - - | G999: =SUMIF('ADV - FB'!L:L,$A999,'ADV - FB'!E:E) -> 0 | H999: =IFERROR(SUMIF('ADV - FB'!L:L,$A999,'ADV - FB'!H:H)/(SUMIF('ADV - FB'!L:L,$A999,'ADV - FB'!G:G)),"-") -> - | I999: =IFERROR(SUMIF('ADV - FB'!L:L,$A999,'ADV - FB'!E:E)/(SUMIF('ADV - FB'!L:L,$A999,'ADV - FB'!F:F)),"-") -> - | J999: =SUMIF('ADV - FB'!L:L,$A999,'ADV - FB'!I:I) -> 0 | K999: =IFERROR(G999/J999,"-") -> -
